Workbook

Sheet Executive Summary
B1: Amara Raja Energy & Mobility Limited — Executive Summary
B2: Consolidated financial model (LAB bottom-up + NEB single-line) + Sum-of-the-Parts valuation | All figures Rs. cr | Scenario selector on Assumptions tab drives sections below marked (dynamic)
B4: VALUE PER SHARE — ALL THREE CASES | G4: CMP | H4: 876
C5: Bear | D5: Base | E5: Bull
B6: Value Per Share (Rs.) | C6: ='DCF & SOTP'!C70 -> 862.58462 | D6: ='DCF & SOTP'!C108 -> 987.35181 | E6: ='DCF & SOTP'!C146 -> 1107.2233
B7: Upside/(Downside) vs CMP | C7: =C6/Assumptions!$D$107-1 -> -0.015314357 | D7: =D6/Assumptions!$D$107-1 -> 0.12711394 | E7: =E6/Assumptions!$D$107-1 -> 0.26395359
B8: Current Scenario Selected: | D8: =INDEX(Assumptions!$N$3:$N$5,Assumptions!$C$4) -> Base
B10: KEY FINANCIALS — HISTORICAL ACTUAL (FY24-26) & FORECAST (SELECTED SCENARIO)
B11: Line | C11: FY24A | D11: FY25A | E11: FY26A | F11: FY27E | G11: FY28E | H11: FY29E | I11: FY30E | J11: FY31E | K11: FY32E
B12: Total Revenue | C12: ='P&L'!C16 -> 11708.44 | D12: ='P&L'!D16 -> 12846.32 | E12: ='P&L'!E16 -> 13814 | F12: ='P&L'!F16 -> 15261.257 | G12: ='P&L'!G16 -> 16840.665 | H12: ='P&L'!H16 -> 18641.964 | I12: ='P&L'!I16 -> 20604.911 | J12: ='P&L'!J16 -> 22709.192 | K12: ='P&L'!K16 -> 24928.573
B13: LAB EBITDA | E13: ='P&L'!E24 -> 1497.1 | F13: ='P&L'!F24 -> 1509.3681 | G13: ='P&L'!G24 -> 1714.0912 | H13: ='P&L'!H24 -> 1955.5689 | I13: ='P&L'!I24 -> 2223.1909 | J13: ='P&L'!J24 -> 2508.7734 | K13: ='P&L'!K24 -> 2805.8525
B14: NEB Net Contribution | F14: ='P&L'!F31 -> -79.5764 | G14: ='P&L'!G31 -> 0 | H14: ='P&L'!H31 -> 114.13896 | I14: ='P&L'!I31 -> 167.2627 | J14: ='P&L'!J31 -> 235.19101 | K14: ='P&L'!K31 -> 275.47075
B15: PAT (Combined) | C15: 934.4 | D15: 944.7 | E15: 895.8 | F15: ='P&L'!F39 -> 758.50251 | G15: ='P&L'!G39 -> 932.20644 | H15: ='P&L'!H39 -> 1137.1167 | I15: ='P&L'!I39 -> 1314.4921 | J15: ='P&L'!J39 -> 1515.2892 | K15: ='P&L'!K39 -> 1703.0112
B16: FCFE | C16: 397 | D16: 159 | E16: -220 | F16: ='Cash Flow'!C12 -> 9.6026188 | G16: ='Cash Flow'!D12 -> -81.393111 | H16: ='Cash Flow'!E12 -> 68.102677 | I16: ='Cash Flow'!F12 -> 203.93791 | J16: ='Cash Flow'!G12 -> 368.78841 | K16: ='Cash Flow'!H12 -> 1292.0845
B18: SUM-OF-THE-PARTS VALUATION — SCENARIO COMPARISON
C19: Bear | D19: Base | E19: Bull
B20: Total Equity Value (SOTP, Rs. cr) | C20: ='DCF & SOTP'!C69 -> 15787.486 | D20: ='DCF & SOTP'!C107 -> 18071.043 | E20: ='DCF & SOTP'!C145 -> 20264.996
B22: SOTP BUILD-UP (SELECTED SCENARIO)
B23: Part A — Core Business (DCF) | D23: ='DCF & SOTP'!D14 -> 7938.752
B24: (+) BESS (Book Value x P/B) | D24: ='DCF & SOTP'!D18 -> 491.87527
B25: (+) Giga Cell Corridor (Book Value x P/B) | D25: ='DCF & SOTP'!D19 -> 9640.4153
B26: (-) Giga Corridor Debt (FY31E cumulative, 70%-funded) | D26: =-Assumptions!$H$127 -> -4400 | E26: (Not included)
B27: Total Equity Value | D27: ='DCF & SOTP'!D20 -> 18071.043
B28: Value Per Share (Rs.) | D28: ='DCF & SOTP'!D22 -> 987.35181

Sheet Assumptions
B1: Amara Raja Energy & Mobility — Model Assumptions (Consolidated LAB + Current-Scale NEB)
B2: All figures INR Crores unless stated. Blue = hardcoded input. FY26 = actual (Q4FY26 results). Scenario selector below drives sections marked (dynamic).
B3: SCENARIO SELECTOR | L3: 1 | N3: Bear
B4: Scenario Index (1=Bear, 2=Base, 3=Bull) | C4: 2 | L4: 2 | N4: Base
L5: 3 | N5: Bull
B6: REVENUE BUILD — FY26 ACTUAL BASE (Rs. cr)
B7: Line | C7: FY26A
B8: LAB — Replacement (Aftermarket) | C8: 6463.6
B9: LAB — OEM | C9: 2770.1
B10: LAB — Industrial | C10: 3771.6
B11: NEB — Lithium Battery Packs | C11: 647
B12: NEB — Chargers & Power Systems | C12: 161.7
B14: REPLACEMENT (AFTERMARKET) GROWTH % — BY SCENARIO
B15: Scenario | D15: FY27E | E15: FY28E | F15: FY29E | G15: FY30E | H15: FY31E | I15: FY32E
C16: Bear | D16: 0.09 | E16: 0.085 | F16: 0.09 | G16: 0.085 | H16: 0.08 | I16: 0.08
C17: Base | D17: 0.12 | E17: 0.115 | F17: 0.12 | G17: 0.115 | H17: 0.11 | I17: 0.1
C18: Bull | D18: 0.15 | E18: 0.14 | F18: 0.14 | G18: 0.13 | H18: 0.12 | I18: 0.11
B19: Selected (scenario-driven) | D19: =INDEX(D16:D18,$C$4) -> 0.12 | E19: =INDEX(E16:E18,$C$4) -> 0.115 | F19: =INDEX(F16:F18,$C$4) -> 0.12 | G19: =INDEX(G16:G18,$C$4) -> 0.115 | H19: =INDEX(H16:H18,$C$4) -> 0.11 | I19: =INDEX(I16:I18,$C$4) -> 0.1
B20: Bear reverts to mgmt's own cited industry growth (5-6%). Bull: continued brand-led share gains (IPL/Amaron Assist), rising vehicle parc, Home Energy/PM Surya Ghar tailwind, OEM-to-aftermarket 3yr lag from strong FY24-25 OEM years.
B22: OEM GROWTH % — BY SCENARIO
B23: Scenario | D23: FY27E | E23: FY28E | F23: FY29E | G23: FY30E | H23: FY31E | I23: FY32E
C24: Bear | D24: 0.06 | E24: 0.06 | F24: 0.06 | G24: 0.06 | H24: 0.06 | I24: 0.06
C25: Base | D25: 0.08 | E25: 0.08 | F25: 0.08 | G25: 0.08 | H25: 0.08 | I25: 0.08
C26: Bull | D26: 0.1 | E26: 0.09 | F26: 0.09 | G26: 0.09 | H26: 0.09 | I26: 0.09
B27: Selected (scenario-driven) | D27: =INDEX(D24:D26,$C$4) -> 0.08 | E27: =INDEX(E24:E26,$C$4) -> 0.08 | F27: =INDEX(F24:F26,$C$4) -> 0.08 | G27: =INDEX(G24:G26,$C$4) -> 0.08 | H27: =INDEX(H24:H26,$C$4) -> 0.08 | I27: =INDEX(I24:I26,$C$4) -> 0.08
B28: Bear: FY26's 30%+ surge was explicitly flagged by mgmt as festive/GST timing, not structural. Bull: hybrid/auxiliary-battery thesis + continued platform share gains.
B30: INDUSTRIAL GROWTH % — BY SCENARIO
B31: Scenario | D31: FY27E | E31: FY28E | F31: FY29E | G31: FY30E | H31: FY31E | I31: FY32E
C32: Bear | D32: 0.05 | E32: =D32+0.005 -> 0.055 | F32: =E32+0.005 -> 0.06 | G32: =F32+0.005 -> 0.065 | H32: =G32+0.005 -> 0.07 | I32: =H32+0.005 -> 0.075
C33: Base | D33: 0.07 | E33: =D33+0.005 -> 0.075 | F33: =E33+0.005 -> 0.08 | G33: =F33+0.005 -> 0.085 | H33: 0.08 | I33: 0.08
C34: Bull | D34: 0.09 | E34: =D34+0.005 -> 0.095 | F34: =E34+0.005 -> 0.1 | G34: =F34+0.005 -> 0.105 | H34: =G34+0.005 -> 0.11 | I34: =H34+0.005 -> 0.115
B35: Selected (scenario-driven) | D35: =INDEX(D32:D34,$C$4) -> 0.07 | E35: =INDEX(E32:E34,$C$4) -> 0.075 | F35: =INDEX(F32:F34,$C$4) -> 0.08 | G35: =INDEX(G32:G34,$C$4) -> 0.085 | H35: =INDEX(H32:H34,$C$4) -> 0.08 | I35: =INDEX(I32:I34,$C$4) -> 0.08
B36: Deliberately RISING across the forecast in Base/Bull: Telecom LAB drag shrinks each year (already <5% of LAB revenue) while Data Center/UPS structural growth (AI buildout, data localization) continues.
B38: NEB — LITHIUM PACKS GROWTH % — BY SCENARIO
B39: Scenario | D39: FY27E | E39: FY28E | F39: FY29E | G39: FY30E | H39: FY31E | I39: FY32E
C40: Bear | D40: 0.2 | E40: 0.18 | F40: 0.16 | G40: 0.15 | H40: 0.15 | I40: 0.15
C41: Base | D41: 0.25 | E41: 0.22 | F41: 0.2 | G41: 0.18 | H41: 0.18 | I41: 0.18
C42: Bull | D42: 0.3 | E42: 0.25 | F42: 0.22 | G42: 0.2 | H42: 0.18 | I42: 0.16
B43: Selected (scenario-driven) | D43: =INDEX(D40:D42,$C$4) -> 0.25 | E43: =INDEX(E40:E42,$C$4) -> 0.22 | F43: =INDEX(F40:F42,$C$4) -> 0.2 | G43: =INDEX(G40:G42,$C$4) -> 0.18 | H43: =INDEX(H40:H42,$C$4) -> 0.18 | I43: =INDEX(I40:I42,$C$4) -> 0.18
B44: Normalizes SLOWER than LAB — NEB is earlier in its adoption curve (telecom lithium migration, EV/ESS are multi-year runways, not a GST-style one-off pull-forward).
...

Sheet P&L
B1: Amara Raja Energy & Mobility — Combined P&L (LAB + Current-Scale NEB, Rs. cr)
B2: FY24A-FY26A actual; FY27E-FY31E per scenario selected on Assumptions tab. NEB carried as a single all-in cost-ratio line, added at EBIT level (before Other Income/Interest/Tax).
B4: Line | C4: FY24A | D4: FY25A | E4: FY26A | F4: FY27E | G4: FY28E | H4: FY29E | I4: FY30E | J4: FY31E | K4: FY32E
B6: LAB REVENUE
B7: Replacement (Aftermarket) | E7: 6463.6 | F7: =E7*(1+Assumptions!$D$19) -> 7239.232 | G7: =F7*(1+Assumptions!$E$19) -> 8071.7437 | H7: =G7*(1+Assumptions!$F$19) -> 9040.3529 | I7: =H7*(1+Assumptions!$G$19) -> 10079.994 | J7: =I7*(1+Assumptions!$H$19) -> 11188.793 | K7: =J7*(1+Assumptions!$I$19) -> 12307.672
B8: OEM | E8: 2770.1 | F8: =E8*(1+Assumptions!$D$27) -> 2991.708 | G8: =F8*(1+Assumptions!$E$27) -> 3231.0446 | H8: =G8*(1+Assumptions!$F$27) -> 3489.5282 | I8: =H8*(1+Assumptions!$G$27) -> 3768.6905 | J8: =I8*(1+Assumptions!$H$27) -> 4070.1857 | K8: =J8*(1+Assumptions!$I$27) -> 4395.8006
B9: Industrial | E9: 3771.6 | F9: =E9*(1+Assumptions!$D$35) -> 4035.612 | G9: =F9*(1+Assumptions!$E$35) -> 4338.2829 | H9: =G9*(1+Assumptions!$F$35) -> 4685.3455 | I9: =H9*(1+Assumptions!$G$35) -> 5083.5999 | J9: =I9*(1+Assumptions!$H$35) -> 5490.2879 | K9: =J9*(1+Assumptions!$I$35) -> 5929.5109
B10: LAB Revenue | C10: 11186.17 | D10: 12345.13 | E10: =SUM(E7:E9) -> 13005.3 | F10: =SUM(F7:F9) -> 14266.552 | G10: =SUM(G7:G9) -> 15641.071 | H10: =SUM(H7:H9) -> 17215.227 | I10: =SUM(I7:I9) -> 18932.284 | J10: =SUM(J7:J9) -> 20749.266 | K10: =SUM(K7:K9) -> 22632.984
B12: NEB REVENUE
B13: Lithium Battery Packs | E13: 647 | F13: =E13*(1+Assumptions!$D$43) -> 808.75 | G13: =F13*(1+Assumptions!$E$43) -> 986.675 | H13: =G13*(1+Assumptions!$F$43) -> 1184.01 | I13: =H13*(1+Assumptions!$G$43) -> 1397.1318 | J13: =I13*(1+Assumptions!$H$43) -> 1648.6155 | K13: =J13*(1+Assumptions!$I$43) -> 1945.3663
B14: Chargers & Power Systems | E14: 161.7 | F14: =E14*(1+Assumptions!$D$51) -> 185.955 | G14: =F14*(1+Assumptions!$E$51) -> 212.91847 | H14: =G14*(1+Assumptions!$F$51) -> 242.72706 | I14: =H14*(1+Assumptions!$G$51) -> 275.49521 | J14: =I14*(1+Assumptions!$H$51) -> 311.30959 | K14: =J14*(1+Assumptions!$I$51) -> 350.22329
B15: NEB Revenue | C15: 522.27 | D15: 501.19 | E15: =SUM(E13:E14) -> 808.7 | F15: =SUM(F13:F14) -> 994.705 | G15: =SUM(G13:G14) -> 1199.5935 | H15: =SUM(H13:H14) -> 1426.7371 | I15: =SUM(I13:I14) -> 1672.627 | J15: =SUM(J13:J14) -> 1959.9251 | K15: =SUM(K13:K14) -> 2295.5896
B16: TOTAL REVENUE | C16: =C10+C15 -> 11708.44 | D16: =D10+D15 -> 12846.32 | E16: =E10+E15 -> 13814 | F16: =F10+F15 -> 15261.257 | G16: =G10+G15 -> 16840.665 | H16: =H10+H15 -> 18641.964 | I16: =I10+I15 -> 20604.911 | J16: =J10+J15 -> 22709.192 | K16: =K10+K15 -> 24928.573
B17: NEB Share | E17: =E15/E16 -> 0.058542059 | F17: =F15/F16 -> 0.065178445 | G17: =G15/G16 -> 0.071231955 | H17: =H15/H16 -> 0.076533625 | I17: =I15/I16 -> 0.081176134 | J17: =J15/J16 -> 0.086305367 | K17: =K15/K16 -> 0.092086683
B18: LAB COST STACK | F18: (guided 7-8%)
B19: COGS (Material cost, 70% of LAB Revenue) | F19: =F10*Assumptions!$D$63 -> 9986.5864 | G19: =G10*Assumptions!$D$63 -> 10948.75 | H19: =H10*Assumptions!$D$63 -> 12050.659 | I19: =I10*Assumptions!$D$63 -> 13252.599 | J19: =J10*Assumptions!$D$63 -> 14524.486 | K19: =K10*Assumptions!$D$63 -> 15843.088
B20: LAB Gross Profit | F20: =F10-F19 -> 4279.9656 | G20: =G10-G19 -> 4692.3214 | H20: =H10-H19 -> 5164.568 | I20: =I10-I19 -> 5679.6852 | J20: =J10-J19 -> 6224.7799 | K20: =K10-K19 -> 6789.8951
B21: Employee Benefit Expense | E21: 839.59 | F21: =E21*(1+Assumptions!$D$65) -> 889.9654 | G21: =F21*(1+Assumptions!$D$65) -> 943.36332 | H21: =G21*(1+Assumptions!$D$65) -> 999.96512 | I21: =H21*(1+Assumptions!$D$65) -> 1059.963 | J21: =I21*(1+Assumptions!$D$65) -> 1123.5608 | K21: =J21*(1+Assumptions!$D$65) -> 1190.9745
B22: Other Expenses — Fixed | E22: 293.69 | F22: =E22*(1+Assumptions!$D$67) -> 311.3114 | G22: =F22*(1+Assumptions!$D$67) -> 329.99008 | H22: =G22*(1+Assumptions!$D$67) -> 349.78949 | I22: =H22*(1+Assumptions!$D$67) -> 370.77686 | J22: =I22*(1+Assumptions!$D$67) -> 393.02347 | K22: =J22*(1+Assumptions!$D$67) -> 416.60488
B23: Other Expenses — Variable (% of LAB Rev) | F23: =F10*Assumptions!D$68 -> 1569.3207 | G23: =G10*Assumptions!E$68 -> 1704.8768 | H23: =H10*Assumptions!F$68 -> 1859.2445 | I23: =I10*Assumptions!G$68 -> 2025.7544 | J23: =J10*Assumptions!H$68 -> 2199.4222 | K23: =K10*Assumptions!I$68 -> 2376.4633
B24: LAB EBITDA | E24: 1497.1 | F24: =F20-F21-F22-F23 -> 1509.3681 | G24: =G20-G21-G22-G23 -> 1714.0912 | H24: =H20-H21-H22-H23 -> 1955.5689 | I24: =I20-I21-I22-I23 -> 2223.1909 | J24: =J20-J21-J22-J23 -> 2508.7734 | K24: =K20-K21-K22-K23 -> 2805.8525
B25: LAB EBITDA Margin % | E25: =E24/E10 -> 0.11511461 | F25: =F24/F10 -> 0.10579768 | G25: =G24/G10 -> 0.10958912 | H25: =H24/H10 -> 0.1135953 | I25: =I24/I10 -> 0.11742856 | J25: =J24/J10 -> 0.12090902 | K25: =K24/K10 -> 0.12397183
B26: LAB Depreciation | F26: =Assumptions!$D$80 -> 480.155 | G26: =Assumptions!$E$80 -> 466.84927 | H26: =Assumptions!$F$80 -> 455.75229 | I26: =Assumptions!$G$80 -> 446.49741 | J26: =Assumptions!$H$80 -> 438.77884 | K26: =Assumptions!$I$80 -> 432.34155
B27: LAB EBIT | F27: =F24-F26 -> 1029.2131 | G27: =G24-G26 -> 1247.2419 | H27: =H24-H26 -> 1499.8166 | I27: =I24-I26 -> 1776.6935 | J27: =J24-J26 -> 2069.9946 | K27: =K24-K26 -> 2373.5109
B29: NEB — ALL-IN COST RATIO & CONTRIBUTION
B30: NEB cost ratio (% of NEB revenue) | E30: 1.167 | F30: =Assumptions!$D$59 -> 1.08 | G30: =Assumptions!$E$59 -> 1 | H30: =Assumptions!$F$59 -> 0.92 | I30: =Assumptions!$G$59 -> 0.9 | J30: =Assumptions!$H$59 -> 0.88 | K30: =Assumptions!$I$59 -> 0.88
B31: NEB Net Contribution (Rev x (1 - cost ratio)) | E31: =E15*(1-E30) -> -135.0529 | F31: =F15*(1-F30) -> -79.5764 | G31: =G15*(1-G30) -> 0 | H31: =H15*(1-H30) -> 114.13896 | I31: =I15*(1-I30) -> 167.2627 | J31: =J15*(1-J30) -> 235.19101 | K31: =K15*(1-K30) -> 275.47075
B32: NEB has no separate D&A/capex/interest/tax line — all costs embedded in the single ratio, added at EBIT level before Other Income/Interest/Tax below (per agreed treatment).
B34: COMBINED EBIT (LAB EBIT + NEB Net Contribution) | F34: =F27+F31 -> 949.63668 | G34: =G27+G31 -> 1247.2419 | H34: =H27+H31 -> 1613.9556 | I34: =I27+I31 -> 1943.9562 | J34: =J27+J31 -> 2305.1856 | K34: =K27+K31 -> 2648.9817
B35: Other Income | F35: =Assumptions!$D$91 -> 106.2 | G35: =Assumptions!$D$91 -> 106.2 | H35: =Assumptions!$D$91 -> 106.2 | I35: =Assumptions!$D$91 -> 106.2 | J35: =Assumptions!$D$91 -> 106.2 | K35: =Assumptions!$D$91 -> 106.2
B36: Finance Cost (LAB flat + Interest on Giga Corridor Debt) | F36: =Assumptions!$D$92+Assumptions!$D$126 -> 44.5 | G36: =Assumptions!$D$92+Assumptions!$E$126 -> 110.5 | H36: =Assumptions!$D$92+Assumptions!$F$126 -> 204 | I36: =Assumptions!$D$92+Assumptions!$G$126 -> 297.5 | J36: =Assumptions!$D$92+Assumptions!$H$126 -> 391 | K36: =Assumptions!$D$92+Assumptions!$I$126 -> 484.5
B37: PBT | C37: 1250.2 | D37: 1273.2 | E37: 1206.9 | F37: =F34+F35-F36 -> 1011.3367 | G37: =G34+G35-G36 -> 1242.9419 | H37: =H34+H35-H36 -> 1516.1556 | I37: =I34+I35-I36 -> 1752.6562 | J37: =J34+J35-J36 -> 2020.3856 | K37: =K34+K35-K36 -> 2270.6817
B38: Tax | F38: =F37*Assumptions!$D$89 -> 252.83417 | G38: =G37*Assumptions!$D$89 -> 310.73548 | H38: =H37*Assumptions!$D$89 -> 379.0389 | I38: =I37*Assumptions!$D$89 -> 438.16405 | J38: =J37*Assumptions!$D$89 -> 505.09639 | K38: =K37*Assumptions!$D$89 -> 567.67041
B39: PAT (Combined) | C39: 934.4 | D39: 944.7 | E39: 895.8 | F39: =F37-F38 -> 758.50251 | G39: =G37-G38 -> 932.20644 | H39: =H37-H38 -> 1137.1167 | I39: =I37-I38 -> 1314.4921 | J39: =J37-J38 -> 1515.2892 | K39: =K37-K38 -> 1703.0112 | L39: =G39*20 -> 18644.129
B42: REFERENCE ONLY — Other Expenses, Note-to-Accounts Line-Item Trend (Standalone, Rs. cr)
B43: Not forecast. Sourced from AR24/AR25/AR26 Note 28 (FY26)/28(FY25)/29(FY24) 'Other Expenses'. Fixed/Variable classification is a judgment call, consistent with the split used to build LAB Other Expenses above.
B45: Line | C45: FY24A | D45: FY25A | E45: FY26A
B46: VARIABLE (revenue/volume-linked)
B47: Consumption of stores & spares | C47: 148.86 | D47: 163.13 | E47: 177.74
B48: Tools consumed | C48: 1.05 | D48: 1.54 | E48: 1.81
...

Sheet Cash Flow
B1: Amara Raja Energy & Mobility — Cash Flow, FCFE (Rs. cr)
B2: LAB Capex/Depreciation only — NEB has no separate capex/D&A (embedded in its single cost-ratio line). Giga Corridor capex entirely excluded — valued in SOTP Part B.
B4: Line | C4: FY27E | D4: FY28E | E4: FY29E | F4: FY30E | G4: FY31E | H4: FY32E
B5: PAT (Combined) | C5: ='P&L'!F39 -> 758.50251 | D5: ='P&L'!G39 -> 932.20644 | E5: ='P&L'!H39 -> 1137.1167 | F5: ='P&L'!I39 -> 1314.4921 | G5: ='P&L'!J39 -> 1515.2892 | H5: ='P&L'!K39 -> 1703.0112
B6: (+) LAB Depreciation | C6: ='P&L'!F26 -> 480.155 | D6: ='P&L'!G26 -> 466.84927 | E6: ='P&L'!H26 -> 455.75229 | F6: ='P&L'!I26 -> 446.49741 | G6: ='P&L'!J26 -> 438.77884 | H6: ='P&L'!K26 -> 432.34155
B7: (-) LAB Capex | C7: =-Assumptions!$D$74 -> -400 | D7: =-Assumptions!$E$74 -> -400 | E7: =-Assumptions!$F$74 -> -400 | F7: =-Assumptions!$G$74 -> -400 | G7: =-Assumptions!$H$74 -> -400 | H7: =-Assumptions!$I$74 -> -400
B8: Total Revenue (for NWC calc) | C8: ='P&L'!F16 -> 15261.257 | D8: ='P&L'!G16 -> 16840.665 | E8: ='P&L'!H16 -> 18641.964 | F8: ='P&L'!I16 -> 20604.911 | G8: ='P&L'!J16 -> 22709.192 | H8: ='P&L'!K16 -> 24928.573
B9: Net Working Capital ((Inv+Recv-Pay)/365 x Revenue) | C9: =(Assumptions!$D$84+Assumptions!$D$85-Assumptions!$D$86)/365*C8 -> 3048.0702 | D9: =(Assumptions!$D$84+Assumptions!$D$85-Assumptions!$D$86)/365*D8 -> 3363.5191 | E9: =(Assumptions!$D$84+Assumptions!$D$85-Assumptions!$D$86)/365*E8 -> 3723.2854 | F9: =(Assumptions!$D$84+Assumptions!$D$85-Assumptions!$D$86)/365*F8 -> 4115.337 | G9: =(Assumptions!$D$84+Assumptions!$D$85-Assumptions!$D$86)/365*G8 -> 4535.6166 | H9: =(Assumptions!$D$84+Assumptions!$D$85-Assumptions!$D$86)/365*H8 -> 4978.8849
B10: (-)/(+) Change in NWC | C10: =-(C9-13814*(Assumptions!$D$84+Assumptions!$D$85-Assumptions!$D$86)/365) -> -289.05489 | D10: =-(D9-C9) -> -315.44882 | E10: =-(E9-D9) -> -359.7663 | F10: =-(F9-E9) -> -392.05164 | G10: =-(G9-F9) -> -420.27961 | H10: =-(H9-G9) -> -443.26828
B11: Operating Cash Flow | C11: =C5+C6+C10 -> 949.60262 | D11: =D5+D6+D10 -> 1083.6069 | E11: =E5+E6+E10 -> 1233.1027 | F11: =F5+F6+F10 -> 1368.9379 | G11: =G5+G6+G10 -> 1533.7884 | H11: =H5+H6+H10 -> 1692.0845
B12: FCFE (PAT + Dep - LAB Capex - NEB Equity Investment +/- dWC) | C12: =C5+C6+C7+C10+C16 -> 9.6026188 | D12: =D5+D6+D7+D10+D16 -> -81.393111 | E12: =E5+E6+E7+E10+E16 -> 68.102677 | F12: =F5+F6+F7+F10+F16 -> 203.93791 | G12: =G5+G6+G7+G10+G16 -> 368.78841 | H12: =H5+H6+H7+H10+H16 -> 1292.0845
B14: Memo: Dividend (for cash/equity rollforward on Balance Sheet, not FCFE) | C14: =-Assumptions!$D$90 -> -194 | D14: =-Assumptions!$D$90 -> -194 | E14: =-Assumptions!$D$90 -> -194 | F14: =-Assumptions!$D$90 -> -194 | G14: =-Assumptions!$D$90 -> -194 | H14: =-Assumptions!$D$90 -> -194
B16: (-) NEB Giga/BESS Equity Investment (30% of capex, per 70:30 debt:equity funding) | C16: =-Assumptions!$D$124 -> -540 | D16: =-Assumptions!$E$124 -> -765 | E16: =-Assumptions!$F$124 -> -765 | F16: =-Assumptions!$G$124 -> -765 | G16: =-Assumptions!$H$124 -> -765 | H16: =-Assumptions!$I$124 -> 0

Sheet DCF & SOTP
B1: Amara Raja Energy & Mobility — DCF & Sum-of-the-Parts Valuation
B2: Scenario shown below (linked to Assumptions!C4). Explicit forecast now FY27E-FY32E (6 yrs) — FY32E is a 'clean' terminal-anchor year: Giga/BESS capex program complete (zero equity draw), but full steady-state debt interest persists. | F2: =INDEX(Assumptions!$N$3:$N$5,Assumptions!$C$4) -> Base
B4: PART A DCF — SELECTED SCENARIO (Rs. cr)
B5: Line | C5: FY27E | D5: FY28E | E5: FY29E | F5: FY30E | G5: FY31E | H5: FY32E
B6: FCFE | C6: ='Cash Flow'!C12 -> 9.6026188 | D6: ='Cash Flow'!D12 -> -81.393111 | E6: ='Cash Flow'!E12 -> 68.102677 | F6: ='Cash Flow'!F12 -> 203.93791 | G6: ='Cash Flow'!G12 -> 368.78841 | H6: ='Cash Flow'!H12 -> 1292.0845
B7: Discount Period | C7: 1 | D7: 2 | E7: 3 | F7: 4 | G7: 5 | H7: 6
B8: Discount Factor @ Ke | C8: =1/(1+Assumptions!$D$103)^C7 -> 0.8783487 | D8: =1/(1+Assumptions!$D$103)^D7 -> 0.77149645 | E8: =1/(1+Assumptions!$D$103)^E7 -> 0.6776429 | F8: =1/(1+Assumptions!$D$103)^F7 -> 0.59520677 | G8: =1/(1+Assumptions!$D$103)^G7 -> 0.52279909 | H8: =1/(1+Assumptions!$D$103)^H7 -> 0.45919991
B9: PV of FCFE | C9: =C6*C8 -> 8.4344478 | D9: =D6*D8 -> -62.794496 | E9: =E6*E8 -> 46.149296 | F9: =F6*F8 -> 121.38523 | G9: =G6*G8 -> 192.80225 | H9: =H6*H8 -> 593.32509
B11: Sum of PV (Explicit Period, FY27E-FY32E) | D11: =SUM(C9:H9) -> 899.30181 | E11: =D11/$D$14 -> 0.11328
B12: Terminal Value (Gordon Growth, at FY32E) | D12: =H6*(1+Assumptions!$D$104)/(Assumptions!$D$103-Assumptions!$D$104) -> 15329.816
B13: PV of Terminal Value | D13: =D12*H8 -> 7039.4502 | E13: =D13/$D$14 -> 0.88672
B14: Part A Equity Value (DCF) | D14: =D11+D13 -> 7938.752
B16: SUM-OF-THE-PARTS (SELECTED SCENARIO)
B17: Part A — Core Business (DCF) | D17: =D14 -> 7938.752
B18: (+) BESS — Book Value x P/B, 1yr discount | D18: =(Assumptions!$D$95*Assumptions!$D$96)/(1+Assumptions!$D$103)^Assumptions!$D$97 -> 491.87527
B19: (+) Giga Cell Corridor — Book Value x P/B, 5yr discount | D19: =(Assumptions!$D$98*Assumptions!$D$99)/(1+Assumptions!$D$103)^Assumptions!$D$100 -> 9640.4153
B20: Total Equity Value | D20: =D17+D18+D19 -> 18071.043
B21: Shares Outstanding (cr) | D21: =Assumptions!$D$106 -> 18.302536
B22: Value Per Share (Rs.) | D22: =D20/D21 -> 987.35181
B23: CMP (31-Mar-26, Rs.) | D23: =Assumptions!$D$107 -> 876
B24: Implied Upside/(Downside) | D24: =D22/D23-1 -> 0.12711394
B25: Memo: (-) Giga Corridor Debt deducted above (FY31E cumulative, 70%-funded) | D25: =-Assumptions!$H$127 -> -4400
B26: Sensitivity: Terminal growth 3-4%
B27: Terminal growth = 4% | D27: =D11+(H6*1.04/(Assumptions!$D$103-0.04))*H8+D18+D19 -> 17296.141 | E27: =(D27/$D$21)/$D$23-1 -> 0.078782378
B28: Terminal growth = 6% | D28: =D11+(H6*1.06/(Assumptions!$D$103-0.06))*H8+D18+D19 -> 19043.371 | E28: =(D28/$D$21)/$D$23-1 -> 0.18775928
B31: SCENARIO COMPARISON (STATIC — ALL THREE CASES, INDEPENDENT OF TOGGLE ABOVE)
B32: Built by re-running Revenue -> LAB EBITDA -> NEB Contribution -> PAT -> FCFE -> Value for scenario index fixed at 1/2/3 (Bear/Base/Bull). Cost ratios, capex, WC days, tax, and SOTP inputs are scenario-invariant and reused as-is.
B34: SCENARIO: Bear
B35: Line | C35: FY26A | D35: FY27E | E35: FY28E | F35: FY29E | G35: FY30E | H35: FY31E | I35: FY32E
B36: LAB - Replacement | C36: =Assumptions!$C$8 -> 6463.6 | D36: =C36*(1+Assumptions!$D$16) -> 7045.324 | E36: =D36*(1+Assumptions!$E$16) -> 7644.1765 | F36: =E36*(1+Assumptions!$F$16) -> 8332.1524 | G36: =F36*(1+Assumptions!$G$16) -> 9040.3854 | H36: =G36*(1+Assumptions!$H$16) -> 9763.6162 | I36: =H36*(1+Assumptions!$I$16) -> 10544.706
B37: LAB - Oem | C37: =Assumptions!$C$9 -> 2770.1 | D37: =C37*(1+Assumptions!$D$24) -> 2936.306 | E37: =D37*(1+Assumptions!$E$24) -> 3112.4844 | F37: =E37*(1+Assumptions!$F$24) -> 3299.2334 | G37: =F37*(1+Assumptions!$G$24) -> 3497.1874 | H37: =G37*(1+Assumptions!$H$24) -> 3707.0187 | I37: =H37*(1+Assumptions!$I$24) -> 3929.4398
B38: LAB - Industrial | C38: =Assumptions!$C$10 -> 3771.6 | D38: =C38*(1+Assumptions!$D$32) -> 3960.18 | E38: =D38*(1+Assumptions!$E$32) -> 4177.9899 | F38: =E38*(1+Assumptions!$F$32) -> 4428.6693 | G38: =F38*(1+Assumptions!$G$32) -> 4716.5328 | H38: =G38*(1+Assumptions!$H$32) -> 5046.6901 | I38: =H38*(1+Assumptions!$I$32) -> 5425.1919
B39: LAB Revenue | C39: =SUM(C36:C38) -> 13005.3 | D39: =SUM(D36:D38) -> 13941.81 | E39: =SUM(E36:E38) -> 14934.651 | F39: =SUM(F36:F38) -> 16060.055 | G39: =SUM(G36:G38) -> 17254.106 | H39: =SUM(H36:H38) -> 18517.325 | I39: =SUM(I36:I38) -> 19899.337
B40: NEB - Packs | C40: =Assumptions!$C$11 -> 647 | D40: =C40*(1+Assumptions!$D$40) -> 776.4 | E40: =D40*(1+Assumptions!$E$40) -> 916.152 | F40: =E40*(1+Assumptions!$F$40) -> 1062.7363 | G40: =F40*(1+Assumptions!$G$40) -> 1222.1468 | H40: =G40*(1+Assumptions!$H$40) -> 1405.4688 | I40: =H40*(1+Assumptions!$I$40) -> 1616.2891
B41: NEB - Chargers | C41: =Assumptions!$C$12 -> 161.7 | D41: =C41*(1+Assumptions!$D$48) -> 177.87 | E41: =D41*(1+Assumptions!$E$48) -> 193.8783 | F41: =E41*(1+Assumptions!$F$48) -> 209.38856 | G41: =F41*(1+Assumptions!$G$48) -> 226.13965 | H41: =G41*(1+Assumptions!$H$48) -> 244.23082 | I41: =H41*(1+Assumptions!$I$48) -> 263.76929
B42: NEB Revenue | C42: =SUM(C40:C41) -> 808.7 | D42: =SUM(D40:D41) -> 954.27 | E42: =SUM(E40:E41) -> 1110.0303 | F42: =SUM(F40:F41) -> 1272.1249 | G42: =SUM(G40:G41) -> 1448.2864 | H42: =SUM(H40:H41) -> 1649.6996 | I42: =SUM(I40:I41) -> 1880.0584
B43: COGS (70% of LAB Rev) | D43: =D39*Assumptions!$D$63 -> 9759.267 | E43: =E39*Assumptions!$D$63 -> 10454.256 | F43: =F39*Assumptions!$D$63 -> 11242.039 | G43: =G39*Assumptions!$D$63 -> 12077.874 | H43: =H39*Assumptions!$D$63 -> 12962.127 | I43: =I39*Assumptions!$D$63 -> 13929.536
B44: LAB Gross Profit | D44: =D39-D43 -> 4182.543 | E44: =E39-E43 -> 4480.3952 | F44: =F39-F43 -> 4818.0165 | G44: =G39-G43 -> 5176.2317 | H44: =H39-H43 -> 5555.1975 | I44: =I39-I43 -> 5969.8011
B45: Employee Cost | C45: 839.59 | D45: =C45*(1+Assumptions!$D$65) -> 889.9654 | E45: =D45*(1+Assumptions!$D$65) -> 943.36332 | F45: =E45*(1+Assumptions!$D$65) -> 999.96512 | G45: =F45*(1+Assumptions!$D$65) -> 1059.963 | H45: =G45*(1+Assumptions!$D$65) -> 1123.5608 | I45: =H45*(1+Assumptions!$D$65) -> 1190.9745
B46: Other Expenses - Fixed | C46: 293.69 | D46: =C46*(1+Assumptions!$D$67) -> 311.3114 | E46: =D46*(1+Assumptions!$D$67) -> 329.99008 | F46: =E46*(1+Assumptions!$D$67) -> 349.78949 | G46: =F46*(1+Assumptions!$D$67) -> 370.77686 | H46: =G46*(1+Assumptions!$D$67) -> 393.02347 | I46: =H46*(1+Assumptions!$D$67) -> 416.60488
...

Sheet Balance Sheet
B1: Amara Raja Energy & Mobility — Balance Sheet (selected line items, Rs. cr)
B2: PARTIAL — selected items only, per scope. Will NOT fully reconcile Assets = Liabilities + Equity. Giga Corridor debt (70%) and equity investment (30%) explicitly shown below. FY32E added as a clean terminal-anchor year (see DCF & SOTP tab) — capex program complete, only steady-state debt interest persists.
B4: Line | C4: FY24A | D4: FY25A | E4: FY26A | F4: FY27E | G4: FY28E | H4: FY29E | I4: FY30E | J4: FY31E | K4: FY32E
B6: Net Fixed Assets (LAB PP&E only) | C6: 2909.5 | D6: 3116.4 | E6: 3769.5 | F6: =Assumptions!$D$81 -> 2612.345 | G6: =Assumptions!$E$81 -> 2545.4957 | H6: =Assumptions!$F$81 -> 2489.7434 | I6: =Assumptions!$G$81 -> 2443.246 | J6: =Assumptions!$H$81 -> 2404.4672 | K6: =Assumptions!$I$81 -> 2372.1256
B7: Inventories | C7: 1948.4 | D7: 2195.4 | E7: 2514.7 | F7: =Assumptions!$D$84/365*'P&L'!F16 -> 3524.7232 | G7: =Assumptions!$D$84/365*'P&L'!G16 -> 3889.5015 | H7: =Assumptions!$D$84/365*'P&L'!H16 -> 4305.5275 | I7: =Assumptions!$D$84/365*'P&L'!I16 -> 4758.8876 | J7: =Assumptions!$D$84/365*'P&L'!J16 -> 5244.89 | K7: =Assumptions!$D$84/365*'P&L'!K16 -> 5757.4759
B8: Trade Receivables | C8: 1135.8 | D8: 1263.1 | E8: 1243.2 | F8: =Assumptions!$D$85/365*'P&L'!F16 -> 1308.7051 | G8: =Assumptions!$D$85/365*'P&L'!G16 -> 1444.1447 | H8: =Assumptions!$D$85/365*'P&L'!H16 -> 1598.6122 | I8: =Assumptions!$D$85/365*'P&L'!I16 -> 1766.9417 | J8: =Assumptions!$D$85/365*'P&L'!J16 -> 1947.3909 | K8: =Assumptions!$D$85/365*'P&L'!K16 -> 2137.7105
B9: Cash & Cash Equivalents (roll-forward) | C9: 98.3 | D9: 157.8 | E9: 226 | F9: =E9+'Cash Flow'!C12+'Cash Flow'!C14 -> 41.602619 | G9: =F9+'Cash Flow'!D12+'Cash Flow'!D14 -> -233.79049 | H9: =G9+'Cash Flow'!E12+'Cash Flow'!E14 -> -359.68781 | I9: =H9+'Cash Flow'!F12+'Cash Flow'!F14 -> -349.7499 | J9: =I9+'Cash Flow'!G12+'Cash Flow'!G14 -> -174.96149 | K9: =J9+'Cash Flow'!H12+'Cash Flow'!H14 -> 923.12302
B10: Trade Payables | C10: 856.5 | D10: 1086.6 | E10: 1183.7 | F10: =Assumptions!$D$86/365*'P&L'!F16 -> 1785.358 | G10: =Assumptions!$D$86/365*'P&L'!G16 -> 1970.1271 | H10: =Assumptions!$D$86/365*'P&L'!H16 -> 2180.8544 | I10: =Assumptions!$D$86/365*'P&L'!I16 -> 2410.4923 | J10: =Assumptions!$D$86/365*'P&L'!J16 -> 2656.6643 | K10: =Assumptions!$D$86/365*'P&L'!K16 -> 2916.3016
B12: Equity Share Capital | C12: 18.3 | D12: 18.3 | E12: 18.3 | F12: =E12 -> 18.3 | G12: =F12 -> 18.3 | H12: =G12 -> 18.3 | I12: =H12 -> 18.3 | J12: =I12 -> 18.3 | K12: =J12 -> 18.3
B13: Reserves (Other Equity, roll-forward) | C13: 6780.4 | D13: 7370.8 | E13: 8080.7 | F13: =E13+'P&L'!F39+'Cash Flow'!C14 -> 8645.2025 | G13: =F13+'P&L'!G39+'Cash Flow'!D14 -> 9383.409 | H13: =G13+'P&L'!H39+'Cash Flow'!E14 -> 10326.526 | I13: =H13+'P&L'!I39+'Cash Flow'!F14 -> 11447.018 | J13: =I13+'P&L'!J39+'Cash Flow'!G14 -> 12768.307 | K13: =J13+'P&L'!K39+'Cash Flow'!H14 -> 14277.318
B15: Borrowings — Giga Corridor Debt (cumulative) | C15: 0 | D15: 0 | E15: 0 | F15: =Assumptions!$D$127 -> 660 | G15: =Assumptions!$E$127 -> 1595 | H15: =Assumptions!$F$127 -> 2530 | I15: =Assumptions!$G$127 -> 3465 | J15: =Assumptions!$H$127 -> 4400 | K15: =Assumptions!$I$127 -> 4400
B16: Investment in NEB — Giga Corridor (at cost, equity-funded) | C16: 0 | D16: 0 | E16: 0 | F16: =Assumptions!$D$128 -> 2040 | G16: =Assumptions!$E$128 -> 2805 | H16: =Assumptions!$F$128 -> 3570 | I16: =Assumptions!$G$128 -> 4335 | J16: =Assumptions!$H$128 -> 5100 | K16: =Assumptions!$I$128 -> 5100

Sheet Ratios
B1: Amara Raja Energy & Mobility — Ratio Analysis
B2: Historical actual (FY24A-26A, consolidated reported figures) and forecast (selected scenario, FY27E-32E). CMP anchor: Rs.876/share (31-Mar-26).
B4: Line | C4: FY24A | D4: FY25A | E4: FY26A | F4: FY27E | G4: FY28E | H4: FY29E | I4: FY30E | J4: FY31E | K4: FY32E
B6: HISTORICAL ACTUALS (CONSOLIDATED, REPORTED, Rs. cr) — REFERENCE BASE FOR RATIOS BELOW
B7: Revenue | C7: ='P&L'!C16 -> 11708.44 | D7: ='P&L'!D16 -> 12846.32 | E7: ='P&L'!E16 -> 13814 | F7: ='P&L'!F16 -> 15261.257 | G7: ='P&L'!G16 -> 16840.665 | H7: ='P&L'!H16 -> 18641.964 | I7: ='P&L'!I16 -> 20604.911 | J7: ='P&L'!J16 -> 22709.192 | K7: ='P&L'!K16 -> 24928.573
B8: EBITDA (reported) | C8: 1658.5 | D8: 1616.5 | E8: 1497.1 | F8: ='P&L'!F24+'P&L'!F31 -> 1429.7917 | G8: ='P&L'!G24+'P&L'!G31 -> 1714.0912 | H8: ='P&L'!H24+'P&L'!H31 -> 2069.7079 | I8: ='P&L'!I24+'P&L'!I31 -> 2390.4536 | J8: ='P&L'!J24+'P&L'!J31 -> 2743.9644 | K8: ='P&L'!K24+'P&L'!K31 -> 3081.3232
B9: Depreciation | C9: 484.3 | D9: 525.7 | E9: 607.2 | F9: ='P&L'!F26 -> 480.155 | G9: ='P&L'!G26 -> 466.84927 | H9: ='P&L'!H26 -> 455.75229 | I9: ='P&L'!I26 -> 446.49741 | J9: ='P&L'!J26 -> 438.77884 | K9: ='P&L'!K26 -> 432.34155
B10: EBIT (EBITDA - Depreciation) | C10: =C8-C9 -> 1174.2 | D10: =D8-D9 -> 1090.8 | E10: =E8-E9 -> 889.9 | F10: ='P&L'!F34 -> 949.63668 | G10: ='P&L'!G34 -> 1247.2419 | H10: ='P&L'!H34 -> 1613.9556 | I10: ='P&L'!I34 -> 1943.9562 | J10: ='P&L'!J34 -> 2305.1856 | K10: ='P&L'!K34 -> 2648.9817
B11: Finance Cost | C11: 34.4 | D11: 44.3 | E11: 44.5 | F11: ='P&L'!F36 -> 44.5 | G11: ='P&L'!G36 -> 110.5 | H11: ='P&L'!H36 -> 204 | I11: ='P&L'!I36 -> 297.5 | J11: ='P&L'!J36 -> 391 | K11: ='P&L'!K36 -> 484.5
B12: Other Income | C12: 110.4 | D12: 115.6 | E12: 106.2 | F12: ='P&L'!F35 -> 106.2 | G12: ='P&L'!G35 -> 106.2 | H12: ='P&L'!H35 -> 106.2 | I12: ='P&L'!I35 -> 106.2 | J12: ='P&L'!J35 -> 106.2 | K12: ='P&L'!K35 -> 106.2
B13: PBT (reported, incl. exceptional items) | C13: 1250.2 | D13: 1273.2 | E13: 1206.9 | F13: ='P&L'!F37 -> 1011.3367 | G13: ='P&L'!G37 -> 1242.9419 | H13: ='P&L'!H37 -> 1516.1556 | I13: ='P&L'!I37 -> 1752.6562 | J13: ='P&L'!J37 -> 2020.3856 | K13: ='P&L'!K37 -> 2270.6817
B14: PAT (reported) | C14: 934.4 | D14: 944.7 | E14: 895.8 | F14: ='P&L'!F39 -> 758.50251 | G14: ='P&L'!G39 -> 932.20644 | H14: ='P&L'!H39 -> 1137.1167 | I14: ='P&L'!I39 -> 1314.4921 | J14: ='P&L'!J39 -> 1515.2892 | K14: ='P&L'!K39 -> 1703.0112
B15: Historical EBITDA/Dep/Finance Cost/PBT/PAT hardcoded from reported consolidated results (Q4FY26 presentation); P&L tab's detailed LAB/NEB cost-stack split was only built for forecast years FY27E onward.
B16: GROWTH RATIOS
B17: Revenue Growth % | D17: =D7/C7-1 -> 0.097184595 | E17: =E7/D7-1 -> 0.075327409 | F17: =F7/E7-1 -> 0.10476741 | G17: =G7/F7-1 -> 0.10349132 | H17: =H7/G7-1 -> 0.10696128 | I17: =I7/H7-1 -> 0.10529723 | J17: =J7/I7-1 -> 0.1021252 | K17: =K7/J7-1 -> 0.097730545
B18: EBITDA Growth % | D18: =D8/C8-1 -> -0.025324088 | E18: =E8/D8-1 -> -0.073863285 | F18: =F8/E8-1 -> -0.044959134 | G18: =G8/F8-1 -> 0.19883982 | H18: =H8/G8-1 -> 0.2074666 | I18: =I8/H8-1 -> 0.1549715 | J18: =J8/I8-1 -> 0.14788441 | K18: =K8/J8-1 -> 0.12294576
B19: PAT Growth % | D19: =D14/C14-1 -> 0.011023116 | E19: =E14/D14-1 -> -0.051762464 | F19: =F14/E14-1 -> -0.15326802 | G19: =G14/F14-1 -> 0.22900904 | H19: =H14/G14-1 -> 0.21981208 | I19: =I14/H14-1 -> 0.15598703 | J19: =J14/I14-1 -> 0.15275636 | K19: =K14/J14-1 -> 0.12388531
B21: MARGIN RATIOS
B22: LAB Gross Margin % (LAB Gross Profit / LAB Revenue) | F22: ='P&L'!F20/'P&L'!F10 -> 0.3 | G22: ='P&L'!G20/'P&L'!G10 -> 0.3 | H22: ='P&L'!H20/'P&L'!H10 -> 0.3 | I22: ='P&L'!I20/'P&L'!I10 -> 0.3 | J22: ='P&L'!J20/'P&L'!J10 -> 0.3 | K22: ='P&L'!K20/'P&L'!K10 -> 0.3
B23: Only computable for forecast years — historical LAB gross profit not disclosed at this granularity (COGS/Gross Profit split only exists below EBITDA in the forecast build).
B24: EBITDA Margin % (consolidated) | C24: =C8/C7 -> 0.14164996 | D24: =D8/D7 -> 0.1258337 | E24: =E8/E7 -> 0.10837556 | F24: =F8/F7 -> 0.093687675 | G24: =G8/G7 -> 0.10178287 | H24: =H8/H7 -> 0.11102413 | I24: =I8/I7 -> 0.11601378 | J24: =J8/J7 -> 0.12083056 | K24: =K8/K7 -> 0.12360608
B25: PAT Margin % | C25: =C14/C7 -> 0.079805679 | D25: =D14/D7 -> 0.07353857 | E25: =E14/E7 -> 0.064847256 | F25: =F14/F7 -> 0.049701182 | G25: =G14/G7 -> 0.055354492 | H25: =H14/H7 -> 0.060997688 | I25: =I14/I7 -> 0.06379509 | J25: =J14/J7 -> 0.066725809 | K25: =K14/K7 -> 0.068315632
B27: CASH CONVERSION RATIOS
B28: CFO / PAT (Operating Cash Flow, before any capex) | F28: ='Cash Flow'!C11/'P&L'!F39 -> 1.2519439 | G28: ='Cash Flow'!D11/'P&L'!G39 -> 1.1624109 | H28: ='Cash Flow'!E11/'P&L'!H39 -> 1.0844117 | I28: ='Cash Flow'!F11/'P&L'!I39 -> 1.0414196 | J28: ='Cash Flow'!G11/'P&L'!J39 -> 1.0122084 | K28: ='Cash Flow'!H11/'P&L'!K39 -> 0.99358388
B29: CFO (excl. NEB capex) / PAT (net of LAB capex, before NEB equity investment) | F29: =('Cash Flow'!C11+'Cash Flow'!C7)/'P&L'!F39 -> 0.72458906 | G29: =('Cash Flow'!D11+'Cash Flow'!D7)/'P&L'!G39 -> 0.73332135 | H29: =('Cash Flow'!E11+'Cash Flow'!E7)/'P&L'!H39 -> 0.73264484 | I29: =('Cash Flow'!F11+'Cash Flow'!F7)/'P&L'!I39 -> 0.73711959 | J29: =('Cash Flow'!G11+'Cash Flow'!G7)/'P&L'!J39 -> 0.74823237 | K29: =('Cash Flow'!H11+'Cash Flow'!H7)/'P&L'!K39 -> 0.7587058
B30: FCFE / PAT (net of ALL capex incl. NEB equity investment) | F30: ='Cash Flow'!C12/'P&L'!F39 -> 0.01265997 | G30: ='Cash Flow'!D12/'P&L'!G39 -> -0.087312324 | H30: ='Cash Flow'!E12/'P&L'!H39 -> 0.059890667 | I30: ='Cash Flow'!F12/'P&L'!I39 -> 0.15514578 | J30: ='Cash Flow'!G12/'P&L'!J39 -> 0.24337824 | K30: ='Cash Flow'!H12/'P&L'!K39 -> 0.7587058
B31: FCFE Yield (FCFE / Market Cap) | F31: ='Cash Flow'!C12/Assumptions!$D$108 -> 0.00059892757 | G31: ='Cash Flow'!D12/Assumptions!$D$108 -> -0.005076592 | H31: ='Cash Flow'!E12/Assumptions!$D$108 -> 0.0042476507 | I31: ='Cash Flow'!F12/Assumptions!$D$108 -> 0.012719867 | J31: ='Cash Flow'!G12/Assumptions!$D$108 -> 0.023001803 | K31: ='Cash Flow'!H12/Assumptions!$D$108 -> 0.080588957
B32: Dividend Payout Ratio (Dividend / PAT) | F32: =Assumptions!$D$90/'P&L'!F39 -> 0.25576712 | G32: =Assumptions!$D$90/'P&L'!G39 -> 0.20810841 | H32: =Assumptions!$D$90/'P&L'!H39 -> 0.17060694 | I32: =Assumptions!$D$90/'P&L'!I39 -> 0.14758552 | J32: =Assumptions!$D$90/'P&L'!J39 -> 0.12802837 | K32: =Assumptions!$D$90/'P&L'!K39 -> 0.11391587
B34: RETURN RATIOS
B35: ROE (PAT / Closing Equity) | C35: =C14/('Balance Sheet'!C13+'Balance Sheet'!C12) -> 0.13743804 | D35: =D14/('Balance Sheet'!D13+'Balance Sheet'!D12) -> 0.12785048 | E35: =E14/('Balance Sheet'!E13+'Balance Sheet'!E12) -> 0.11060625 | F35: ='P&L'!F39/('Balance Sheet'!F13+'Balance Sheet'!F12) -> 0.087551485 | G35: ='P&L'!G39/('Balance Sheet'!G13+'Balance Sheet'!G12) -> 0.099152872 | H35: ='P&L'!H39/('Balance Sheet'!H13+'Balance Sheet'!H12) -> 0.1099213 | I35: ='P&L'!I39/('Balance Sheet'!I13+'Balance Sheet'!I12) -> 0.11464943 | J35: ='P&L'!J39/('Balance Sheet'!J13+'Balance Sheet'!J12) -> 0.11850596 | K35: ='P&L'!K39/('Balance Sheet'!K13+'Balance Sheet'!K12) -> 0.1191282
B36: ROCE (EBIT / Average Capital Employed [Equity+Debt]) | C36: =C10/(('Balance Sheet'!C13+'Balance Sheet'!C12+'Balance Sheet'!C15)) -> 0.17270949 | D36: =D10/((('Balance Sheet'!C13+'Balance Sheet'!C12+'Balance Sheet'!C15)+('Balance Sheet'!D13+'Balance Sheet'!D12+'Balance Sheet'!D15))/2) -> 0.15376591 | E36: =E10/((('Balance Sheet'!D13+'Balance Sheet'!D12+'Balance Sheet'!D15)+('Balance Sheet'!E13+'Balance Sheet'!E12+'Balance Sheet'!E15))/2) -> 0.11491403 | F36: ='P&L'!F34/((('Balance Sheet'!E13+'Balance Sheet'!E12+'Balance Sheet'!E15)+('Balance Sheet'!F13+'Balance Sheet'!F12+'Balance Sheet'!F15))/2) -> 0.10901266 | G36: ='P&L'!G34/((('Balance Sheet'!F13+'Balance Sheet'!F12+'Balance Sheet'!F15)+('Balance Sheet'!G13+'Balance Sheet'!G12+'Balance Sheet'!G15))/2) -> 0.12275875 | H36: ='P&L'!H34/((('Balance Sheet'!G13+'Balance Sheet'!G12+'Balance Sheet'!G15)+('Balance Sheet'!H13+'Balance Sheet'!H12+'Balance Sheet'!H15))/2) -> 0.13522009 | I36: ='P&L'!I34/((('Balance Sheet'!H13+'Balance Sheet'!H12+'Balance Sheet'!H15)+('Balance Sheet'!I13+'Balance Sheet'!I12+'Balance Sheet'!I15))/2) -> 0.13982709 | J36: ='P&L'!J34/((('Balance Sheet'!I13+'Balance Sheet'!I12+'Balance Sheet'!I15)+('Balance Sheet'!J13+'Balance Sheet'!J12+'Balance Sheet'!J15))/2) -> 0.14354958 | K36: ='P&L'!K34/((('Balance Sheet'!J13+'Balance Sheet'!J12+'Balance Sheet'!J15)+('Balance Sheet'!K13+'Balance Sheet'!K12+'Balance Sheet'!K15))/2) -> 0.14764868
B37: ROCE now computable given the Giga Corridor debt is explicitly on the Balance Sheet. Uses Combined EBIT (LAB EBIT + NEB Net Contribution) over average (Equity + Debt). Not directly comparable to management's disclosed consolidated ROCE (~12.0% FY26) since this Balance Sheet remains partial (excludes most non-core assets).
B39: LEVERAGE & COVERAGE
B40: Debt / Equity (x) [Giga Corridor Debt / (Reserves+Capital)] | C40: ='Balance Sheet'!C15/('Balance Sheet'!C13+'Balance Sheet'!C12) -> 0 | D40: ='Balance Sheet'!D15/('Balance Sheet'!D13+'Balance Sheet'!D12) -> 0 | E40: ='Balance Sheet'!E15/('Balance Sheet'!E13+'Balance Sheet'!E12) -> 0 | F40: ='Balance Sheet'!F15/('Balance Sheet'!F13+'Balance Sheet'!F12) -> 0.07618166 | G40: ='Balance Sheet'!G15/('Balance Sheet'!G13+'Balance Sheet'!G12) -> 0.16965001 | H40: ='Balance Sheet'!H15/('Balance Sheet'!H13+'Balance Sheet'!H12) -> 0.24456671 | I40: ='Balance Sheet'!I15/('Balance Sheet'!I13+'Balance Sheet'!I12) -> 0.30221578 | J40: ='Balance Sheet'!J15/('Balance Sheet'!J13+'Balance Sheet'!J12) -> 0.34411005 | K40: ='Balance Sheet'!K15/('Balance Sheet'!K13+'Balance Sheet'!K12) -> 0.30778662
B41: Net Debt / EBITDA (x) [(Debt - Cash) / EBITDA] | C41: =('Balance Sheet'!C15-'Balance Sheet'!C9)/C8 -> -0.059270425 | D41: =('Balance Sheet'!D15-'Balance Sheet'!D9)/D8 -> -0.097618311 | E41: =('Balance Sheet'!E15-'Balance Sheet'!E9)/E8 -> -0.15095852 | F41: =('Balance Sheet'!F15-'Balance Sheet'!F9)/F8 -> 0.43250873 | G41: =('Balance Sheet'!G15-'Balance Sheet'!G9)/G8 -> 1.0669155 | H41: =('Balance Sheet'!H15-'Balance Sheet'!H9)/H8 -> 1.3961815 | I41: =('Balance Sheet'!I15-'Balance Sheet'!I9)/I8 -> 1.5958268 | J41: =('Balance Sheet'!J15-'Balance Sheet'!J9)/J8 -> 1.6672816 | K41: =('Balance Sheet'!K15-'Balance Sheet'!K9)/K8 -> 1.1283714
B42: Interest Coverage Ratio (EBIT / Finance Cost) | C42: =C10/C11 -> 34.133721 | D42: =D10/D11 -> 24.623025 | E42: =E10/E11 -> 19.997753 | F42: =F10/F11 -> 21.34015 | G42: =G10/G11 -> 11.287257 | H42: =H10/H11 -> 7.911547 | I42: =I10/I11 -> 6.5343065 | J42: =J10/J11 -> 5.8956153 | K42: =K10/K11 -> 5.4674544
B44: EFFICIENCY
B45: Asset Turnover (x) [Revenue / Total Modeled Assets] | C45: =C7/('Balance Sheet'!C6+'Balance Sheet'!C7+'Balance Sheet'!C8+'Balance Sheet'!C9) -> 1.921937 | D45: =D7/('Balance Sheet'!D6+'Balance Sheet'!D7+'Balance Sheet'!D8+'Balance Sheet'!D9) -> 1.9080488 | E45: =E7/('Balance Sheet'!E6+'Balance Sheet'!E7+'Balance Sheet'!E8+'Balance Sheet'!E9) -> 1.78167 | F45: =F7/('Balance Sheet'!F6+'Balance Sheet'!F7+'Balance Sheet'!F8+'Balance Sheet'!F9+'Balance Sheet'!F16) -> 1.6018322 | G45: =G7/('Balance Sheet'!G6+'Balance Sheet'!G7+'Balance Sheet'!G8+'Balance Sheet'!G9+'Balance Sheet'!G16) -> 1.6114927 | H45: =H7/('Balance Sheet'!H6+'Balance Sheet'!H7+'Balance Sheet'!H8+'Balance Sheet'!H9+'Balance Sheet'!H16) -> 1.6064848 | I45: =I7/('Balance Sheet'!I6+'Balance Sheet'!I7+'Balance Sheet'!I8+'Balance Sheet'!I9+'Balance Sheet'!I16) -> 1.5905815 | J45: =J7/('Balance Sheet'!J6+'Balance Sheet'!J7+'Balance Sheet'!J8+'Balance Sheet'!J9+'Balance Sheet'!J16) -> 1.5638015 | K45: =K7/('Balance Sheet'!K6+'Balance Sheet'!K7+'Balance Sheet'!K8+'Balance Sheet'!K9+'Balance Sheet'!K16) -> 1.5302583
B46: Total Modeled Assets = Net Fixed Assets + Inventories + Receivables + Cash (+ Investment in NEB, forecast years only). Excludes Giga Corridor operating PP&E itself (not consolidated in this partial Balance Sheet) — actual asset turnover will differ once Giga assets go live.
B48: PER-SHARE & MARKET-BASED MULTIPLES (CMP anchor: Rs.876/share, 31-Mar-26)
...
