Workbook

Sheet Executive Summary
A1: Exide Industries Limited — Executive Summary
B2: Standalone financial model + Sum-of-the-Parts valuation | All figures Rs. cr unless stated | Scenario selector on Assumptions tab drives sections below marked (dynamic)
A4: VALUE PER SHARE — ALL THREE CASES
C5: Bear | D5: Base | E5: Bull
B6: Value Per Share (Rs.) | C6: ='DCF & SOTP'!E39 -> 308.93724 | D6: ='DCF & SOTP'!E52 -> 340.61513 | E6: ='DCF & SOTP'!E65 -> 354.44051
B7: Upside/Downside | C7: =C6/Ratios!$D$23-1 -> -0.26303139 | D7: =D6/Ratios!$D$23-1 -> -0.18746391 | E7: =E6/Ratios!$D$23-1 -> -0.15448352
B8: Current Scenario Selected: | D8: =Assumptions!C3 -> 0
A10: KEY FINANCIALS — HISTORICAL ACTUAL (FY24-26) & FORECAST (SELECTED SCENARIO)
B11: Line | C11: FY24A | D11: FY25A | E11: FY26A | F11: FY27E | G11: FY28E | H11: FY29E | I11: FY30E | J11: FY31E
B12: Revenue | C12: ='P&L'!C4 -> 16029.19 | D12: ='P&L'!D4 -> 16588.11 | E12: ='P&L'!E4 -> 17268.92 | F12: ='P&L'!F4 -> 19319.604 | G12: ='P&L'!G4 -> 22473.716 | H12: ='P&L'!H4 -> 24957.728 | I12: ='P&L'!I4 -> 27473.217 | J12: ='P&L'!J4 -> 30005.331
B13: EBITDA | C13: ='P&L'!C9 -> 1871.38 | D13: ='P&L'!D9 -> 1893.14 | E13: ='P&L'!E9 -> 1942.85 | F13: ='P&L'!F9 -> 2174.3032 | G13: ='P&L'!G9 -> 2718.4566 | H13: ='P&L'!H9 -> 3125.0843 | I13: ='P&L'!I9 -> 3533.5914 | J13: ='P&L'!J9 -> 3940.8032
B14: EBITDA Margin % | C14: ='P&L'!C10 -> 0.11674826 | D14: ='P&L'!D10 -> 0.11412632 | E14: ='P&L'!E10 -> 0.11250559 | F14: ='P&L'!F10 -> 0.11254388 | G14: ='P&L'!G10 -> 0.1209616 | H14: ='P&L'!H10 -> 0.1252151 | I14: ='P&L'!I10 -> 0.1286195 | J14: ='P&L'!J10 -> 0.13133677
B15: PAT | C15: ='P&L'!C17 -> 1052.96 | D15: ='P&L'!D17 -> 1076.93 | E15: ='P&L'!E17 -> 1111.33 | F15: ='P&L'!F17 -> 1210.3905 | G15: ='P&L'!G17 -> 1631.0343 | H15: ='P&L'!H17 -> 1998.2461 | I15: ='P&L'!I17 -> 2379.971 | J15: ='P&L'!J17 -> 2772.4775
B17: FCFE | F17: ='Cash Flow'!F11 -> 403.6645 | G17: ='Cash Flow'!G11 -> 1444.4747 | H17: ='Cash Flow'!H11 -> 1853.3021 | I17: ='Cash Flow'!I11 -> 2215.873 | J17: ='Cash Flow'!J11 -> 2593.0325
A19: SUM-OF-THE-PARTS VALUATION — SCENARIO COMPARISON (STATIC, ALL THREE CASES)
B20: Component | D20: Bear | E20: Base | F20: Bull
B21: FY31E Total Standalone Revenue | D21: ='DCF & SOTP'!J32 -> 26346.649 | E21: ='DCF & SOTP'!J45 -> 28882.11 | F21: ='DCF & SOTP'!J58 -> 30005.331
B22: Total Equity Value (SOTP) | D22: ='DCF & SOTP'!E38 -> 26259.666 | E22: ='DCF & SOTP'!E51 -> 28952.286 | F22: ='DCF & SOTP'!E64 -> 30127.443
B23: Value Per Share (Rs.) | D23: ='DCF & SOTP'!E39 -> 308.93724 | E23: ='DCF & SOTP'!E52 -> 340.61513 | F23: ='DCF & SOTP'!E65 -> 354.44051
A25: SOTP BUILD-UP (SELECTED SCENARIO)
B26: Standalone Core Business (DCF) | D26: ='DCF & SOTP'!D18 -> 20926.342
B27: (+) EESL (Book Value x P/B) | D27: ='DCF & SOTP'!D19 -> 5600
B28: (+) HDFC Life Stake (net of holding discount) | D28: ='DCF & SOTP'!D20 -> 3601.101
B29: Total Equity Value | D29: ='DCF & SOTP'!D21 -> 30127.443
B30: Value Per Share (Rs.) | D30: ='DCF & SOTP'!D23 -> 354.44051
B32: KNOWN MODEL LIMITATIONS (see cell comments throughout for sourcing detail):
B33: - Other Expenses split Fixed (Rs.1,591cr @ 9.2% of revenue, grown at 8%/yr) + Variable (10.1% of Revenue, scales with Revenue) via LINE-ITEM CLASSIFICATION of all 27 items in audited Note 32 + Note 29 - not a statistical fit. Cross-checked stable across FY24-FY26 (no trend in the ratios historically) - BUT historical stability occurred during a slow-growth period (Revenue +3.5-4.1%/yr) where Fixed-cost inflation (~5-8%) happened to be similar in magnitude; this says little about whether Fixed costs stay decoupled from Revenue once growth is 8-14%/yr as forecast. 8%/yr growth (up from 5%) partially offsets the operating-leverage/margin-expansion effect vs. Variable's revenue-linked growth.
B34: - Other Income = 5% interest on PRIOR YEAR closing Cash & Cash Equivalents (non-circular by construction - deliberately NOT current-year cash, which would create a Cash->Income->PAT->FCFE->Cash feedback loop; tested and confirmed unstable/runaway if built that way). Cash itself grows substantially over the forecast (debt-free, high-retention, flat Rs.170cr dividend against growing PAT) - worth revisiting whether a rising payout ratio or buyback assumption is more realistic than letting cash accumulate unchecked.
B35: - Discount rate (12%) and select EESL infusion phasing (Rs.500cr/300cr FY27/28) are placeholders/assumptions pending further refinement.
B36: - Balance Sheet forecasts only selected line items (per scope) - will not fully reconcile Assets = Liabilities + Equity.
B37: - Non-Institutional growth ('mid-teens') rests on unverified management commentary - carries ~71% of revenue weight (MEDIUM confidence). NOTE: audited Ind AS 115 disaggregation (Note 25) shows Institutional/Non-institutional at 24.6%/75.4% (FY26) - closely validates the 25%/75% assumption used to build the revenue module.
B38: - Export FY28E share-recovery mechanic implies a >100% single-year increase - aggressive; consider phasing over 2-3 years if desired.
B39: - HDFC Life stake value (Rs.5,144.43cr) is the Mar-26 audited mark; live price has since moved (e.g. Rs.555 vs Rs.591 implied - a further ~6% decline) - update Assumptions!D73 periodically.

Sheet Assumptions
A1: Exide Industries Limited — Model Assumptions (Standalone)
B3: SCENARIO SELECTOR | L3: 1 | N3: Bear
B4: Scenario Index (1=Bear, 2=Base, 3=Bull) | C4: 3 | L4: 2 | N4: Base
L5: 3 | N5: Bull
A6: REVENUE BUILD — FY26 AUDITED BASE
B7: Total Standalone Revenue FY26 (Rs. cr) | C7: 17268.92
B8: Domestic % of Total Revenue | C8: 0.95
B9: Export % of Total Revenue | C9: =1-C8 -> 0.05
B10: Institutional % of Domestic Revenue | C10: 0.25
B11: Non-Institutional % of Domestic Revenue | C11: =1-C10 -> 0.75
B12: FY26 Domestic Institutional Revenue (Rs. cr) | C12: =C7*C8*C10 -> 4101.3685
B13: FY26 Domestic Non-Institutional Revenue (Rs. cr) | C13: =C7*C8*C11 -> 12304.105
B14: FY26 Exports (Rs. cr) | C14: =C7*C9 -> 863.446
A16: GROWTH RATE ASSUMPTIONS BY SCENARIO (FY27E-FY31E)
B17: Scenario | D17: FY27E | E17: FY28E | F17: FY29E | G17: FY30E | H17: FY31E
B18: Institutional Growth %
C19: Bear | D19: 0.06 | E19: 0.055 | F19: 0.05 | G19: 0.05 | H19: 0.05
C20: Base | D20: 0.08 | E20: 0.075 | F20: 0.07 | G20: 0.065 | H20: 0.06
C21: Bull | D21: 0.095 | E21: 0.09 | F21: 0.08 | G21: 0.07 | H21: 0.065
B22: Selected (scenario-driven) | D22: =INDEX(D19:D21,$C$4) -> 0.095 | E22: =INDEX(E19:E21,$C$4) -> 0.09 | F22: =INDEX(F19:F21,$C$4) -> 0.08 | G22: =INDEX(G19:G21,$C$4) -> 0.07 | H22: =INDEX(H19:H21,$C$4) -> 0.065
B24: Non-Institutional Growth %
C25: Bear | D25: 0.1 | E25: 0.095 | F25: 0.09 | G25: 0.085 | H25: 0.08
C26: Base | D26: 0.13 | E26: 0.12 | F26: 0.11 | G26: 0.1 | H26: 0.095
C27: Bull | D27: 0.135 | E27: 0.13 | F27: 0.12 | G27: 0.11 | H27: 0.1
B28: Selected (scenario-driven) | D28: =INDEX(D25:D27,$C$4) -> 0.135 | E28: =INDEX(E25:E27,$C$4) -> 0.13 | F28: =INDEX(F25:F27,$C$4) -> 0.12 | G28: =INDEX(G25:G27,$C$4) -> 0.11 | H28: =INDEX(H25:H27,$C$4) -> 0.1
B30: Export Growth % (FY27E explicit only)
C31: Bear | D31: -0.08
C32: Base | D32: -0.04
C33: Bull | D33: 0
B34: Selected (scenario-driven) - FY27E only | D34: =INDEX(D31:D33,$C$4) -> 0
B35: Export Target Share of Total Revenue (FY28E onward) | D35: 0.08
A37: REVENUE BUILD (SELECTED SCENARIO) — Rs. cr
B38: Line | C38: FY26A | D38: FY27E | E38: FY28E | F38: FY29E | G38: FY30E | H38: FY31E
B39: Domestic Institutional | C39: =C12 -> 4101.3685 | D39: =C39*(1+D22) -> 4490.9985 | E39: =D39*(1+E22) -> 4895.1884 | F39: =E39*(1+F22) -> 5286.8034 | G39: =F39*(1+G22) -> 5656.8797 | H39: =G39*(1+H22) -> 6024.5769
B40: Domestic Non-Institutional | C40: =C13 -> 12304.105 | D40: =C40*(1+D28) -> 13965.16 | E40: =D40*(1+E28) -> 15780.631 | F40: =E40*(1+F28) -> 17674.306 | G40: =F40*(1+G28) -> 19618.48 | H40: =G40*(1+H28) -> 21580.328
B41: Exports | C41: =C14 -> 863.446 | D41: =C41*(1+D34) -> 863.446 | E41: =$D$35/(1-$D$35)*(E39+E40) -> 1797.8973 | F41: =$D$35/(1-$D$35)*(F39+F40) -> 1996.6182 | G41: =$D$35/(1-$D$35)*(G39+G40) -> 2197.8574 | H41: =$D$35/(1-$D$35)*(H39+H40) -> 2400.4265
B42: Total Standalone Revenue | C42: =C39+C40+C41 -> 17268.92 | D42: =D39+D40+D41 -> 19319.604 | E42: =E39+E40+E41 -> 22473.716 | F42: =F39+F40+F41 -> 24957.728 | G42: =G39+G40+G41 -> 27473.217 | H42: =H39+H40+H41 -> 30005.331
A44: COST & MARGIN ASSUMPTIONS
B45: COGS % of Revenue | D45: 0.7
B46: FY26 Operating EBITDA (Rs. cr) - reference anchor | C46: 1942.85
...

Sheet P&L
A1: Exide Industries Limited — Standalone P&L (Rs. cr)
B3: Line | C3: FY24A | D3: FY25A | E3: FY26A | F3: FY27E | G3: FY28E | H3: FY29E | I3: FY30E | J3: FY31E
B4: Revenue | C4: 16029.19 | D4: 16588.11 | E4: 17268.92 | F4: =Assumptions!D42 -> 19319.604 | G4: =Assumptions!E42 -> 22473.716 | H4: =Assumptions!F42 -> 24957.728 | I4: =Assumptions!G42 -> 27473.217 | J4: =Assumptions!H42 -> 30005.331
B5: COGS (% of Revenue) | F5: =Assumptions!$D$45 -> 0.7 | G5: =Assumptions!$D$45 -> 0.7 | H5: =Assumptions!$D$45 -> 0.7 | I5: =Assumptions!$D$45 -> 0.7 | J5: =Assumptions!$D$45 -> 0.7
B6: COGS | F6: =F4*F5 -> 13523.723 | G6: =G4*G5 -> 15731.601 | H6: =H4*H5 -> 17470.409 | I6: =I4*I5 -> 19231.252 | J6: =J4*J5 -> 21003.732
B7: Gross Profit | F7: =F4-F6 -> 5795.8813 | G7: =G4-G6 -> 6742.1149 | H7: =H4-H6 -> 7487.3184 | I7: =I4-I6 -> 8241.9651 | J7: =J4-J6 -> 9001.5994
B8: Other Expenses (Fixed + inflation, plus Variable % of Revenue) | F8: =Assumptions!$C$47*(1+Assumptions!$D$48)^1+Assumptions!$D$47*F4 -> 3621.578 | G8: =Assumptions!$C$47*(1+Assumptions!$D$48)^2+Assumptions!$D$47*G4 -> 4023.6582 | H8: =Assumptions!$C$47*(1+Assumptions!$D$48)^3+Assumptions!$D$47*H4 -> 4362.2341 | I8: =Assumptions!$C$47*(1+Assumptions!$D$48)^4+Assumptions!$D$47*I4 -> 4708.3736 | J8: =Assumptions!$C$47*(1+Assumptions!$D$48)^5+Assumptions!$D$47*J4 -> 5060.7961
B9: EBITDA (Operating, excl. Other Income) | C9: 1871.38 | D9: 1893.14 | E9: 1942.85 | F9: =F7-F8 -> 2174.3032 | G9: =G7-G8 -> 2718.4566 | H9: =H7-H8 -> 3125.0843 | I9: =I7-I8 -> 3533.5914 | J9: =J7-J8 -> 3940.8032
B10: EBITDA Margin % | C10: =C9/C4 -> 0.11674826 | D10: =D9/D4 -> 0.11412632 | E10: =E9/E4 -> 0.11250559 | F10: =F9/F4 -> 0.11254388 | G10: =G9/G4 -> 0.1209616 | H10: =H9/H4 -> 0.1252151 | I10: =I9/I4 -> 0.1286195 | J10: =J9/J4 -> 0.13133677
B11: Depreciation & Amortisation | C11: 497.45 | D11: 503.93 | E11: 500.95 | F11: =Assumptions!D86 -> 534.6943 | G11: =Assumptions!E86 -> 530.59505 | H11: =Assumptions!F86 -> 512.23627 | I11: =Assumptions!G86 -> 496.92505 | J11: =Assumptions!H86 -> 484.15549
B12: EBIT | C12: =C9-C11 -> 1373.93 | D12: =D9-D11 -> 1389.21 | E12: =E9-E11 -> 1441.9 | F12: =F9-F11 -> 1639.6089 | G12: =G9-G11 -> 2187.8616 | H12: =H9-H11 -> 2612.848 | I12: =I9-I11 -> 3036.6664 | J12: =J9-J11 -> 3456.6478
B13: Interest (Lease schedule + flat non-lease) | C13: 48.59 | D13: 43.89 | E13: 34.86 | F13: =Assumptions!D93+1.92 -> 33.985447 | G13: =Assumptions!E93+1.92 -> 33.062944 | H13: =Assumptions!F93+1.92 -> 32.15732 | I13: =Assumptions!G93+1.92 -> 31.174301 | J13: =Assumptions!H93+1.92 -> 30.107273
B14: Other Income (5% interest on prior-year cash) | C14: 84.54 | D14: 96.16 | E14: 93.07 | F14: ='Balance Sheet'!E9*Assumptions!$D$49 -> 8.2305 | G14: ='Balance Sheet'!F9*Assumptions!$D$49 -> 19.913725 | H14: ='Balance Sheet'!G9*Assumptions!$D$49 -> 83.63746 | I14: ='Balance Sheet'!H9*Assumptions!$D$49 -> 167.80257 | J14: ='Balance Sheet'!I9*Assumptions!$D$49 -> 270.09622
B15: PBT | C15: =C12-C13+C14 -> 1409.88 | D15: =D12-D13+D14 -> 1441.48 | E15: =E12-E13+E14 -> 1500.11 | F15: =F12-F13+F14 -> 1613.854 | G15: =G12-G13+G14 -> 2174.7124 | H15: =H12-H13+H14 -> 2664.3282 | I15: =I12-I13+I14 -> 3173.2947 | J15: =J12-J13+J14 -> 3696.6367
B16: Tax | C16: 356.92 | D16: 364.55 | E16: 379.74 | F16: =F15*Assumptions!$D$62 -> 403.4635 | G16: =G15*Assumptions!$D$62 -> 543.67809 | H16: =H15*Assumptions!$D$62 -> 666.08204 | I16: =I15*Assumptions!$D$62 -> 793.32366 | J16: =J15*Assumptions!$D$62 -> 924.15918
B17: PAT | C17: 1052.96 | D17: 1076.93 | E17: 1111.33 | F17: =F15-F16 -> 1210.3905 | G17: =G15-G16 -> 1631.0343 | H17: =H15-H16 -> 1998.2461 | I17: =I15-I16 -> 2379.971 | J17: =J15-J16 -> 2772.4775
B21: Line | C21: FY24A | D21: FY25A | E21: FY26A
B22: VARIABLE (revenue/volume-linked)
B23: Power and fuel | C23: 447.68 | D23: 466.78 | E23: 472.88
B24: Warranty expenses | C24: 375.11 | D24: 480.32 | E24: 420.34
B25: Freight & Forwarding (net) | C25: 433.58 | D25: 432.72 | E25: 439.54
B26: Stores and spare parts consumed | C26: 113.67 | D26: 118.18 | E26: 119.48
B27: Battery Charging/assembly expenses | C27: 81.36 | D27: 84.02 | E27: 97.34
B28: After Sales Services | C28: 71.1 | D28: 76.89 | E28: 80.29
B29: Royalty and Technical Aid Fees | C29: 43.76 | D29: 53.86 | E29: 57.28
B30: Clearing and forwarding Expenses | C30: 49.82 | D30: 53.26 | E30: 53.36
B31: Commission | C31: 4.47 | D31: 5.55 | E31: 3.74
B32: Total Variable | C32: 1620.55 | D32: 1771.58 | E32: 1744.25
B34: FIXED (admin/infrastructure-linked)
B35: Salaries, wages and bonus | C35: 858.41 | D35: 928.55 | E35: 953.12
B36: Contribution to PF and other funds | C36: 43.72 | D36: 45.4 | E36: 48.97
B37: Staff welfare expenses | C37: 80.55 | D37: 81.85 | E37: 78.97
B38: Miscellaneous expenses | C38: 198.23 | D38: 195.05 | E38: 175.62
B39: Publicity and Sales Promotion | C39: 55.01 | D39: 30.72 | E39: 71.82
B40: Software expenses | C40: 58.49 | D40: 64.21 | E40: 66.02
B41: Rent & Hire Charges | C41: 49.22 | D41: 55.95 | E41: 63.5
B42: Travelling & Conveyance | C42: 51.56 | D42: 56.34 | E42: 57.01
B43: Repairs & maintenance (Buildings+P&M+Others) | C43: 47.32 | D43: 52.11 | E43: 46.36
B44: Insurance | C44: 12.36 | D44: 12.49 | E44: 14.79
B45: Auditors' Remuneration | C45: 1.93 | D45: 2.1 | E45: 1.99
...

Sheet Balance Sheet
A1: Exide Industries Limited — Standalone Balance Sheet (Rs. cr)
B3: Line | C3: FY24A | D3: FY25A | E3: FY26A | F3: FY27E | G3: FY28E | H3: FY29E | I3: FY30E | J3: FY31E
B4: Net Fixed Assets (PP&E + CWIP) | C4: 3047.22 | D4: 2998.34 | E4: 2921.05 | F4: =Assumptions!D87 -> 2986.3557 | G4: =Assumptions!E87 -> 2875.7607 | H4: =Assumptions!F87 -> 2783.5244 | I4: =Assumptions!G87 -> 2706.5993 | J4: =Assumptions!H87 -> 2642.4438
B5: Investment in EESL (at cost) | C5: 2302.24 | D5: 3302.23 | E5: 4802.23 | F5: =Assumptions!D68 -> 5602.23 | G5: =Assumptions!E68 -> 5602.23 | H5: =Assumptions!F68 -> 5602.23 | I5: =Assumptions!G68 -> 5602.23 | J5: =Assumptions!H68 -> 5602.23
B6: Investment in HDFC Life (fair value) | C6: 5511.55 | D6: 5978.47 | E6: 5144.43 | F6: =$E$6 -> 5144.43 | G6: =$E$6 -> 5144.43 | H6: =$E$6 -> 5144.43 | I6: =$E$6 -> 5144.43 | J6: =$E$6 -> 5144.43
B7: Inventories | C7: 3249.34 | D7: 3827.43 | E7: 3492.14 | F7: ='P&L'!F6*Assumptions!$D$57/365 -> 3485.4154 | G7: ='P&L'!G6*Assumptions!$D$57/365 -> 4054.4431 | H7: ='P&L'!H6*Assumptions!$D$57/365 -> 4502.5792 | I7: ='P&L'!I6*Assumptions!$D$57/365 -> 4956.3941 | J7: ='P&L'!J6*Assumptions!$D$57/365 -> 5413.2084
B8: Trade Receivables | C8: 1264.41 | D8: 1576.59 | E8: 1460.28 | F8: ='P&L'!F4*Assumptions!$D$58/365 -> 1702.2424 | G8: ='P&L'!G4*Assumptions!$D$58/365 -> 1980.1499 | H8: ='P&L'!H4*Assumptions!$D$58/365 -> 2199.0151 | I8: ='P&L'!I4*Assumptions!$D$58/365 -> 2420.6538 | J8: ='P&L'!J4*Assumptions!$D$58/365 -> 2643.7574
B9: Cash & Cash Equivalents | C9: 217.44 | D9: 111.26 | E9: 164.61 | F9: =E9+'Cash Flow'!F11-Assumptions!$D$63 -> 398.2745 | G9: =F9+'Cash Flow'!G11-Assumptions!$D$63 -> 1672.7492 | H9: =G9+'Cash Flow'!H11-Assumptions!$D$63 -> 3356.0514 | I9: =H9+'Cash Flow'!I11-Assumptions!$D$63 -> 5401.9244 | J9: =I9+'Cash Flow'!J11-Assumptions!$D$63 -> 7824.9569
B10: Trade Payables | C10: 2309.64 | D10: 2831.19 | E10: 3127.82 | F10: ='P&L'!F6*Assumptions!$D$59/365 -> 3432.432 | G10: ='P&L'!G6*Assumptions!$D$59/365 -> 3992.8097 | H10: ='P&L'!H6*Assumptions!$D$59/365 -> 4434.1335 | I10: ='P&L'!I6*Assumptions!$D$59/365 -> 4881.0498 | J10: ='P&L'!J6*Assumptions!$D$59/365 -> 5330.9198
B11: Equity Share Capital | C11: 85 | D11: 85 | E11: 85 | F11: =$E$11 -> 85 | G11: =$E$11 -> 85 | H11: =$E$11 -> 85 | I11: =$E$11 -> 85 | J11: =$E$11 -> 85
B12: Reserves (Other Equity) | C12: 13052.24 | D12: 14357.34 | E12: 14588.58 | F12: =E12+'P&L'!F17-Assumptions!$D$63 -> 15628.97 | G12: =F12+'P&L'!G17-Assumptions!$D$63 -> 17090.005 | H12: =G12+'P&L'!H17-Assumptions!$D$63 -> 18918.251 | I12: =H12+'P&L'!I17-Assumptions!$D$63 -> 21128.222 | J12: =I12+'P&L'!J17-Assumptions!$D$63 -> 23730.699
B13: Lease Liabilities (Total) | C13: 395.55 | D13: 385.59 | E13: 375.21 | F13: =Assumptions!D95 -> 364.41545 | G13: =Assumptions!E95 -> 353.81839 | H13: =Assumptions!F95 -> 342.31571 | I13: =Assumptions!G95 -> 329.83001 | J13: =Assumptions!H95 -> 316.27728

Sheet Cash Flow
A1: Exide Industries Limited — Standalone Cash Flow, FCFF/FCFE (Rs. cr)
B3: Line | F3: FY27E | G3: FY28E | H3: FY29E | I3: FY30E | J3: FY31E
B4: PAT | F4: ='P&L'!F17 -> 1210.3905 | G4: ='P&L'!G17 -> 1631.0343 | H4: ='P&L'!H17 -> 1998.2461 | I4: ='P&L'!I17 -> 2379.971 | J4: ='P&L'!J17 -> 2772.4775
B5: (+) Depreciation & Amortisation | F5: ='P&L'!F11 -> 534.6943 | G5: ='P&L'!G11 -> 530.59505 | H5: ='P&L'!H11 -> 512.23627 | I5: ='P&L'!I11 -> 496.92505 | J5: ='P&L'!J11 -> 484.15549
B6: (+) After-tax Interest (FCFF add-back only) | F6: ='P&L'!F13*(1-Assumptions!$D$62) -> 25.489085 | G6: ='P&L'!G13*(1-Assumptions!$D$62) -> 24.797208 | H6: ='P&L'!H13*(1-Assumptions!$D$62) -> 24.11799 | I6: ='P&L'!I13*(1-Assumptions!$D$62) -> 23.380725 | J6: ='P&L'!J13*(1-Assumptions!$D$62) -> 22.580455
B7: (-) Capex | F7: =-Assumptions!D54 -> -600 | G7: =-Assumptions!E54 -> -420 | H7: =-Assumptions!F54 -> -420 | I7: =-Assumptions!G54 -> -420 | J7: =-Assumptions!H54 -> -420
B8: (-) EESL Equity Infusion | F8: =-Assumptions!D67 -> -800 | G8: =-Assumptions!E67 -> 0 | H8: =-Assumptions!F67 -> 0 | I8: =-Assumptions!G67 -> 0 | J8: =-Assumptions!H67 -> 0
B9: (-) Lease Principal Repayment | F9: =-Assumptions!D94 -> -10.794553 | G9: =-Assumptions!E94 -> -10.597056 | H9: =-Assumptions!F94 -> -11.50268 | I9: =-Assumptions!G94 -> -12.485699 | J9: =-Assumptions!H94 -> -13.552727
B10: (-)/(+) Change in Working Capital | F10: =-((('Balance Sheet'!F7-'Balance Sheet'!E7)+('Balance Sheet'!F8-'Balance Sheet'!E8))-('Balance Sheet'!F10-'Balance Sheet'!E10)) -> 69.374256 | G10: =-((('Balance Sheet'!G7-'Balance Sheet'!F7)+('Balance Sheet'!G8-'Balance Sheet'!F8))-('Balance Sheet'!G10-'Balance Sheet'!F10)) -> -286.55755 | H10: =-((('Balance Sheet'!H7-'Balance Sheet'!G7)+('Balance Sheet'!H8-'Balance Sheet'!G8))-('Balance Sheet'!H10-'Balance Sheet'!G10)) -> -225.67756 | I10: =-((('Balance Sheet'!I7-'Balance Sheet'!H7)+('Balance Sheet'!I8-'Balance Sheet'!H8))-('Balance Sheet'!I10-'Balance Sheet'!H10)) -> -228.53735 | J10: =-((('Balance Sheet'!J7-'Balance Sheet'!I7)+('Balance Sheet'!J8-'Balance Sheet'!I8))-('Balance Sheet'!J10-'Balance Sheet'!I10)) -> -230.04779
B11: FCFE (Free Cash Flow to Equity) | F11: =F4+F5+F7+F8+F9+F10 -> 403.6645 | G11: =G4+G5+G7+G8+G9+G10 -> 1444.4747 | H11: =H4+H5+H7+H8+H9+H10 -> 1853.3021 | I11: =I4+I5+I7+I8+I9+I10 -> 2215.873 | J11: =J4+J5+J7+J8+J9+J10 -> 2593.0325
B12: FCFF (Free Cash Flow to Firm, unlevered) | F12: =F11+F6 -> 429.15359 | G12: =G11+G6 -> 1469.2719 | H12: =H11+H6 -> 1877.4201 | I12: =I11+I6 -> 2239.2537 | J12: =J11+J6 -> 2615.613

Sheet DCF & SOTP
A1: Exide Industries Limited — Standalone DCF & Sum-of-the-Parts Valuation
B3: Scenario shown below (linked to Assumptions!C3): | E3: =VLOOKUP(Assumptions!C4,Assumptions!L3:N5,3) -> Bull
A5: STANDALONE DCF — SELECTED SCENARIO (Rs. cr)
B6: Line | F6: FY27E | G6: FY28E | H6: FY29E | I6: FY30E | J6: FY31E
B7: FCFE | F7: ='Cash Flow'!F11 -> 403.6645 | G7: ='Cash Flow'!G11 -> 1444.4747 | H7: ='Cash Flow'!H11 -> 1853.3021 | I7: ='Cash Flow'!I11 -> 2215.873 | J7: ='Cash Flow'!J11 -> 2593.0325
B8: Discount Period | F8: 1 | G8: 2 | H8: 3 | I8: 4 | J8: 5
B9: Discount Factor | F9: =1/(1+Assumptions!$D$78)^F8 -> 0.8767131 | G9: =1/(1+Assumptions!$D$78)^G8 -> 0.76862586 | H9: =1/(1+Assumptions!$D$78)^H8 -> 0.67386435 | I9: =1/(1+Assumptions!$D$78)^I8 -> 0.59078571 | J9: =1/(1+Assumptions!$D$78)^J8 -> 0.51794957
B10: PV of FCFE | F10: =F7*F9 -> 353.89796 | G10: =G7*G9 -> 1110.2606 | H10: =H7*H9 -> 1248.8743 | I10: =I7*I9 -> 1309.1061 | J10: =J7*J9 -> 1343.0601
B12: Sum of PV (Explicit Period, FY27E-FY31E) | D12: =SUM(F10:J10) -> 5365.199
B13: Terminal Value (Gordon Growth, at FY31E) | D13: =J7*(1+Assumptions!$D$79)/(Assumptions!$D$78-Assumptions!$D$79) -> 30043.743
B14: PV of Terminal Value | D14: =D13*J9 -> 15561.143
B15: Standalone Equity Value (DCF) | D15: =D12+D14 -> 20926.342
A17: SUM-OF-THE-PARTS
B18: Standalone Core Business (DCF) | D18: =D15 -> 20926.342
B19: (+) EESL — Book Value x P/B Multiple | D19: =Assumptions!$D$71*Assumptions!$D$72 -> 5600
B20: (+) HDFC Life Stake (CMP x (1-Holding Discount)) | D20: =Assumptions!$D$73*(1-Assumptions!$D$74) -> 3601.101
B21: Total Equity Value | D21: =D18+D19+D20 -> 30127.443
B22: Shares Outstanding (cr) | D22: =Assumptions!$D$75 -> 85
B23: Value Per Share (Rs.) | D23: =D21/D22 -> 354.44051
A25: SCENARIO COMPARISON (STATIC — ALL THREE CASES, INDEPENDENT OF TOGGLE ABOVE)
B26: Built by re-running the Revenue->FCFE->Value chain with scenario index fixed at 1/2/3 (Bear/Base/Bull), reusing scenario-invariant cost/capex/WC/tax assumptions.
B28: SCENARIO: Bear | F28: FY27E | G28: FY28E | H28: FY29E | I28: FY30E | J28: FY31E
B29: Domestic Institutional | E29: =Assumptions!$C$12 -> 4101.3685 | F29: =E29*(1+INDEX(Assumptions!D19:D21,1)) -> 4347.4506 | G29: =F29*(1+INDEX(Assumptions!E19:E21,1)) -> 4586.5604 | H29: =G29*(1+INDEX(Assumptions!F19:F21,1)) -> 4815.8884 | I29: =H29*(1+INDEX(Assumptions!G19:G21,1)) -> 5056.6828 | J29: =I29*(1+INDEX(Assumptions!H19:H21,1)) -> 5309.517
B30: Domestic Non-Institutional | E30: =Assumptions!$C$13 -> 12304.105 | F30: =E30*(1+INDEX(Assumptions!D25:D27,1)) -> 13534.516 | G30: =F30*(1+INDEX(Assumptions!E25:E27,1)) -> 14820.295 | H30: =G30*(1+INDEX(Assumptions!F25:F27,1)) -> 16154.122 | I30: =H30*(1+INDEX(Assumptions!G25:G27,1)) -> 17527.222 | J30: =I30*(1+INDEX(Assumptions!H25:H27,1)) -> 18929.4
B31: Exports | E31: =Assumptions!$C$14 -> 863.446 | F31: =E31*(1+INDEX(Assumptions!D31:D33,1)) -> 794.37032 | G31: =Assumptions!$D$35/(1-Assumptions!$D$35)*(G29+G30) -> 1687.5526 | H31: =Assumptions!$D$35/(1-Assumptions!$D$35)*(H29+H30) -> 1823.4791 | I31: =Assumptions!$D$35/(1-Assumptions!$D$35)*(I29+I30) -> 1963.8178 | J31: =Assumptions!$D$35/(1-Assumptions!$D$35)*(J29+J30) -> 2107.7319
B32: Total Revenue | F32: =F29+F30+F31 -> 18676.337 | G32: =G29+G30+G31 -> 21094.408 | H32: =H29+H30+H31 -> 22793.489 | I32: =I29+I30+I31 -> 24547.723 | J32: =J29+J30+J31 -> 26346.649
B33: EBITDA (Revenue - COGS - Other Exp., own scenario revenue) | F33: =F32*(1-Assumptions!$D$45)-(Assumptions!$C$47*(1+Assumptions!$D$48)^1+Assumptions!$D$47*F32) -> 2046.2931 | G33: =G32*(1-Assumptions!$D$45)-(Assumptions!$C$47*(1+Assumptions!$D$48)^2+Assumptions!$D$47*G32) -> 2443.9743 | H33: =H32*(1-Assumptions!$D$45)-(Assumptions!$C$47*(1+Assumptions!$D$48)^3+Assumptions!$D$47*H32) -> 2694.4008 | I33: =I32*(1-Assumptions!$D$45)-(Assumptions!$C$47*(1+Assumptions!$D$48)^4+Assumptions!$D$47*I32) -> 2951.4181 | J33: =J32*(1-Assumptions!$D$45)-(Assumptions!$C$47*(1+Assumptions!$D$48)^5+Assumptions!$D$47*J32) -> 3212.7254
B34: (-)/(+) Change in Working Capital (own scenario revenue) | F34: 127.81641 | G34: =-(((G32-F32)*Assumptions!$D$45)*(Assumptions!$D$57-Assumptions!$D$59)/365+(G32-F32)*Assumptions!$D$58/365) -> -219.68673 | H34: =-(((H32-G32)*Assumptions!$D$45)*(Assumptions!$D$57-Assumptions!$D$59)/365+(H32-G32)*Assumptions!$D$58/365) -> -154.36501 | I34: =-(((I32-H32)*Assumptions!$D$45)*(Assumptions!$D$57-Assumptions!$D$59)/365+(I32-H32)*Assumptions!$D$58/365) -> -159.37571 | J34: =-(((J32-I32)*Assumptions!$D$45)*(Assumptions!$D$57-Assumptions!$D$59)/365+(J32-I32)*Assumptions!$D$58/365) -> -163.43612
B35: Cash & Cash Equivalents (own scenario roll-forward) | E35: 164.61 | F35: =E35+F36-Assumptions!$D$63 -> 360.70902 | G35: =F35+G36-Assumptions!$D$63 -> 1494.7841 | H35: =G35+H36-Assumptions!$D$63 -> 2919.7125 | I35: =H35+I36-Assumptions!$D$63 -> 4581.7544 | J35: =I35+J36-Assumptions!$D$63 -> 6494.5838
B36: FCFE (PAT + D&A - Capex - EESL - Lease Principal - dWC) | F36: =(F33-'P&L'!F11-'P&L'!F13+E35*Assumptions!$D$49)*(1-Assumptions!$D$62)+'P&L'!F11+'Cash Flow'!F7+'Cash Flow'!F8+'Cash Flow'!F9+F34 -> 366.09902 | G36: =(G33-'P&L'!G11-'P&L'!G13+F35*Assumptions!$D$49)*(1-Assumptions!$D$62)+'P&L'!G11+'Cash Flow'!G7+'Cash Flow'!G8+'Cash Flow'!G9+G34 -> 1304.0751 | H36: =(H33-'P&L'!H11-'P&L'!H13+G35*Assumptions!$D$49)*(1-Assumptions!$D$62)+'P&L'!H11+'Cash Flow'!H7+'Cash Flow'!H8+'Cash Flow'!H9+H34 -> 1594.9284 | I36: =(I33-'P&L'!I11-'P&L'!I13+H35*Assumptions!$D$49)*(1-Assumptions!$D$62)+'P&L'!I11+'Cash Flow'!I7+'Cash Flow'!I8+'Cash Flow'!I9+I34 -> 1832.0419 | J36: =(J33-'P&L'!J11-'P&L'!J13+I35*Assumptions!$D$49)*(1-Assumptions!$D$62)+'P&L'!J11+'Cash Flow'!J7+'Cash Flow'!J8+'Cash Flow'!J9+J34 -> 2082.8294 | M36: 395.36714
B37: PV of FCFE (at placeholder WACC) | F37: =F36/(1+Assumptions!$D$78)^1 -> 320.9638 | G37: =G36/(1+Assumptions!$D$78)^2 -> 1002.3458 | H37: =H36/(1+Assumptions!$D$78)^3 -> 1074.7654 | I37: =I36/(1+Assumptions!$D$78)^4 -> 1082.3442 | J37: =J36/(1+Assumptions!$D$78)^5 -> 1078.8006 | M37: 366.09902
B38: Standalone DCF + EESL + HDFC Life = Total Equity Value | E38: =SUM(F37:J37)+J36*(1+Assumptions!$D$79)/(Assumptions!$D$78-Assumptions!$D$79)/(1+Assumptions!$D$78)^5+Assumptions!$D$71*Assumptions!$D$72+Assumptions!$D$73*(1-Assumptions!$D$74) -> 26259.666 | M38: =M36-M37 -> 29.268123
B39: Value Per Share (Rs.) | E39: =E38/Assumptions!$D$75 -> 308.93724
B41: SCENARIO: Base | F41: FY27E | G41: FY28E | H41: FY29E | I41: FY30E | J41: FY31E
B42: Domestic Institutional | E42: =Assumptions!$C$12 -> 4101.3685 | F42: =E42*(1+INDEX(Assumptions!D19:D21,2)) -> 4429.478 | G42: =F42*(1+INDEX(Assumptions!E19:E21,2)) -> 4761.6888 | H42: =G42*(1+INDEX(Assumptions!F19:F21,2)) -> 5095.007 | I42: =H42*(1+INDEX(Assumptions!G19:G21,2)) -> 5426.1825 | J42: =I42*(1+INDEX(Assumptions!H19:H21,2)) -> 5751.7535
B43: Domestic Non-Institutional | E43: =Assumptions!$C$13 -> 12304.105 | F43: =E43*(1+INDEX(Assumptions!D25:D27,2)) -> 13903.639 | G43: =F43*(1+INDEX(Assumptions!E25:E27,2)) -> 15572.076 | H43: =G43*(1+INDEX(Assumptions!F25:F27,2)) -> 17285.004 | I43: =H43*(1+INDEX(Assumptions!G25:G27,2)) -> 19013.505 | J43: =I43*(1+INDEX(Assumptions!H25:H27,2)) -> 20819.788
B44: Exports | E44: =Assumptions!$C$14 -> 863.446 | F44: =E44*(1+INDEX(Assumptions!D31:D33,2)) -> 828.90816 | G44: =Assumptions!$D$35/(1-Assumptions!$D$35)*(G42+G43) -> 1768.1535 | H44: =Assumptions!$D$35/(1-Assumptions!$D$35)*(H42+H43) -> 1946.0879 | I44: =Assumptions!$D$35/(1-Assumptions!$D$35)*(I42+I43) -> 2125.1902 | J44: =Assumptions!$D$35/(1-Assumptions!$D$35)*(J42+J43) -> 2310.5688
B45: Total Revenue | F45: =F42+F43+F44 -> 19162.025 | G45: =G42+G43+G44 -> 22101.918 | H45: =H42+H43+H44 -> 24326.099 | I45: =I42+I43+I44 -> 26564.877 | J45: =J42+J43+J44 -> 28882.11
B46: EBITDA (Revenue - COGS - Other Exp., own scenario revenue) | F46: =F45*(1-Assumptions!$D$45)-(Assumptions!$C$47*(1+Assumptions!$D$48)^1+Assumptions!$D$47*F45) -> 2142.945 | G46: =G45*(1-Assumptions!$D$45)-(Assumptions!$C$47*(1+Assumptions!$D$48)^2+Assumptions!$D$47*G45) -> 2644.4688 | H46: =H45*(1-Assumptions!$D$45)-(Assumptions!$C$47*(1+Assumptions!$D$48)^3+Assumptions!$D$47*H45) -> 2999.3902 | I46: =I45*(1-Assumptions!$D$45)-(Assumptions!$C$47*(1+Assumptions!$D$48)^4+Assumptions!$D$47*I45) -> 3352.8319 | J46: =J45*(1-Assumptions!$D$45)-(Assumptions!$C$47*(1+Assumptions!$D$48)^5+Assumptions!$D$47*J45) -> 3717.2822
B47: (-)/(+) Change in Working Capital (own scenario revenue) | F47: 83.690622 | G47: =-(((G45-F45)*Assumptions!$D$45)*(Assumptions!$D$57-Assumptions!$D$59)/365+(G45-F45)*Assumptions!$D$58/365) -> -267.09531 | H47: =-(((H45-G45)*Assumptions!$D$45)*(Assumptions!$D$57-Assumptions!$D$59)/365+(H45-G45)*Assumptions!$D$58/365) -> -202.07142 | I47: =-(((I45-H45)*Assumptions!$D$45)*(Assumptions!$D$57-Assumptions!$D$59)/365+(I45-H45)*Assumptions!$D$58/365) -> -203.39759 | J47: =-(((J45-I45)*Assumptions!$D$45)*(Assumptions!$D$57-Assumptions!$D$59)/365+(J45-I45)*Assumptions!$D$58/365) -> -210.52533
...

Sheet Ratios
A1: Exide Industries Limited — Ratio Analysis (Standalone)
B2: Presentation-style comparison, historical actual (FY24-26) and forecast (selected scenario, FY27E-31E)
B4: Line | C4: FY24A | D4: FY25A | E4: FY26A | F4: FY27E | G4: FY28E | H4: FY29E | I4: FY30E | J4: FY31E
A6: GROWTH & MARGIN RATIOS
B7: Revenue Growth % | C7: n/a | D7: =('P&L'!D4/'P&L'!C4)-1 -> 0.034868886 | E7: =('P&L'!E4/'P&L'!D4)-1 -> 0.041042048 | F7: =('P&L'!F4/'P&L'!E4)-1 -> 0.11875 | G7: =('P&L'!G4/'P&L'!F4)-1 -> 0.16325966 | H7: =('P&L'!H4/'P&L'!G4)-1 -> 0.11052964 | I7: =('P&L'!I4/'P&L'!H4)-1 -> 0.10078999 | J7: =('P&L'!J4/'P&L'!I4)-1 -> 0.092166648
B8: EBITDA Margin % | C8: ='P&L'!C10 -> 0.11674826 | D8: ='P&L'!D10 -> 0.11412632 | E8: ='P&L'!E10 -> 0.11250559 | F8: ='P&L'!F10 -> 0.11254388 | G8: ='P&L'!G10 -> 0.1209616 | H8: ='P&L'!H10 -> 0.1252151 | I8: ='P&L'!I10 -> 0.1286195 | J8: ='P&L'!J10 -> 0.13133677
B9: PAT Margin % | C9: ='P&L'!C17/'P&L'!C4 -> 0.065690157 | D9: ='P&L'!D17/'P&L'!D4 -> 0.064921802 | E9: ='P&L'!E17/'P&L'!E4 -> 0.064354343 | F9: ='P&L'!F17/'P&L'!F4 -> 0.062650895 | G9: ='P&L'!G17/'P&L'!G4 -> 0.072575192 | H9: ='P&L'!H17/'P&L'!H4 -> 0.080065226 | I9: ='P&L'!I17/'P&L'!I4 -> 0.08662877 | J9: ='P&L'!J17/'P&L'!J4 -> 0.092399498
A11: RETURN RATIOS
B12: ROCE — Core Basis (excl. EESL & HDFC Life) | C12: ='P&L'!C12/(('Balance Sheet'!C4)+('Balance Sheet'!C7+'Balance Sheet'!C8+'Balance Sheet'!C9-'Balance Sheet'!C10)) -> 0.251232 | D12: ='P&L'!D12/(('Balance Sheet'!D4)+('Balance Sheet'!D7+'Balance Sheet'!D8+'Balance Sheet'!D9-'Balance Sheet'!D10)) -> 0.24447463 | E12: ='P&L'!E12/(('Balance Sheet'!E4)+('Balance Sheet'!E7+'Balance Sheet'!E8+'Balance Sheet'!E9-'Balance Sheet'!E10)) -> 0.29365044 | F12: ='P&L'!F12/(('Balance Sheet'!F4)+('Balance Sheet'!F7+'Balance Sheet'!F8+'Balance Sheet'!F9-'Balance Sheet'!F10)) -> 0.31899901 | G12: ='P&L'!G12/(('Balance Sheet'!G4)+('Balance Sheet'!G7+'Balance Sheet'!G8+'Balance Sheet'!G9-'Balance Sheet'!G10)) -> 0.33198244 | H12: ='P&L'!H12/(('Balance Sheet'!H4)+('Balance Sheet'!H7+'Balance Sheet'!H8+'Balance Sheet'!H9-'Balance Sheet'!H10)) -> 0.31079299 | I12: ='P&L'!I12/(('Balance Sheet'!I4)+('Balance Sheet'!I7+'Balance Sheet'!I8+'Balance Sheet'!I9-'Balance Sheet'!I10)) -> 0.2863558 | J12: ='P&L'!J12/(('Balance Sheet'!J4)+('Balance Sheet'!J7+'Balance Sheet'!J8+'Balance Sheet'!J9-'Balance Sheet'!J10)) -> 0.26199733
B13: ROCE — Total Basis (incl. EESL & HDFC Life) | C13: ='P&L'!C12/(('Balance Sheet'!C4+'Balance Sheet'!C5+'Balance Sheet'!C6)+('Balance Sheet'!C7+'Balance Sheet'!C8+'Balance Sheet'!C9-'Balance Sheet'!C10)) -> 0.10343864 | D13: ='P&L'!D12/(('Balance Sheet'!D4+'Balance Sheet'!D5+'Balance Sheet'!D6)+('Balance Sheet'!D7+'Balance Sheet'!D8+'Balance Sheet'!D9-'Balance Sheet'!D10)) -> 0.092842206 | E13: ='P&L'!E12/(('Balance Sheet'!E4+'Balance Sheet'!E5+'Balance Sheet'!E6)+('Balance Sheet'!E7+'Balance Sheet'!E8+'Balance Sheet'!E9-'Balance Sheet'!E10)) -> 0.097052417 | F13: ='P&L'!F12/(('Balance Sheet'!F4+'Balance Sheet'!F5+'Balance Sheet'!F6)+('Balance Sheet'!F7+'Balance Sheet'!F8+'Balance Sheet'!F9-'Balance Sheet'!F10)) -> 0.10320759 | G13: ='P&L'!G12/(('Balance Sheet'!G4+'Balance Sheet'!G5+'Balance Sheet'!G6)+('Balance Sheet'!G7+'Balance Sheet'!G8+'Balance Sheet'!G9-'Balance Sheet'!G10)) -> 0.12619643 | H13: ='P&L'!H12/(('Balance Sheet'!H4+'Balance Sheet'!H5+'Balance Sheet'!H6)+('Balance Sheet'!H7+'Balance Sheet'!H8+'Balance Sheet'!H9-'Balance Sheet'!H10)) -> 0.13641482 | I13: ='P&L'!I12/(('Balance Sheet'!I4+'Balance Sheet'!I5+'Balance Sheet'!I6)+('Balance Sheet'!I7+'Balance Sheet'!I8+'Balance Sheet'!I9-'Balance Sheet'!I10)) -> 0.14222474 | J13: ='P&L'!J12/(('Balance Sheet'!J4+'Balance Sheet'!J5+'Balance Sheet'!J6)+('Balance Sheet'!J7+'Balance Sheet'!J8+'Balance Sheet'!J9-'Balance Sheet'!J10)) -> 0.14438732
B14: ROE (PAT / Closing Equity) | C14: ='P&L'!C17/('Balance Sheet'!C11+'Balance Sheet'!C12) -> 0.080150777 | D14: ='P&L'!D17/('Balance Sheet'!D11+'Balance Sheet'!D12) -> 0.074567556 | E14: ='P&L'!E17/('Balance Sheet'!E11+'Balance Sheet'!E12) -> 0.0757368 | F14: ='P&L'!F17/('Balance Sheet'!F11+'Balance Sheet'!F12) -> 0.077026395 | G14: ='P&L'!G17/('Balance Sheet'!G11+'Balance Sheet'!G12) -> 0.094965579 | H14: ='P&L'!H17/('Balance Sheet'!H11+'Balance Sheet'!H12) -> 0.10515286 | I14: ='P&L'!I17/('Balance Sheet'!I11+'Balance Sheet'!I12) -> 0.11219281 | J14: ='P&L'!J17/('Balance Sheet'!J11+'Balance Sheet'!J12) -> 0.11641386
B16: MEMO: As Disclosed in Investor Presentations (unreconciled - see note)
B17: ROCE (Core Business) — Nov'25 IP basis, Mar/Sep'25 | D17: 0.176
B18: ROCE (Core Business) — Q4FY26 IP basis, FY25/FY26 (excl. HDFC+EESL) | D18: 0.26 | E18: 0.288
B19: These two disclosed series do NOT reconcile to each other (10+pp gap, likely different Capital Employed denominators) - flagged as an unresolved primary-source discrepancy since our first pass through these documents. Our own formula-driven ROCE rows above are internally consistent across all years but will not match either disclosed series exactly.
A20: MARKET-BASED MULTIPLES (Rs.360.55/share CMP anchor - Apr'26 Market Cap Rs.30,647cr / 85cr shares, per AR26)
B21: Reference Market Cap (Rs. cr, held constant) | D21: 35632
B22: Shares Outstanding (cr) | D22: =Assumptions!$D$75 -> 85
B23: Reference CMP (Rs./share) | D23: =D21/D22 -> 419.2
B25: EV / EBITDA (x) | C25: =($D$21+'Balance Sheet'!C13-'Balance Sheet'!C9)/'P&L'!C9 -> 19.13567 | D25: =($D$21+'Balance Sheet'!D13-'Balance Sheet'!D9)/'P&L'!D9 -> 18.966548 | E25: =($D$21+'Balance Sheet'!E13-'Balance Sheet'!E9)/'P&L'!E9 -> 18.448465 | F25: =($D$21+'Balance Sheet'!F13-'Balance Sheet'!F9)/'P&L'!F9 -> 16.372206 | G25: =($D$21+'Balance Sheet'!G13-'Balance Sheet'!G9)/'P&L'!G9 -> 12.622261 | H25: =($D$21+'Balance Sheet'!H13-'Balance Sheet'!H9)/'P&L'!H9 -> 10.437563 | I25: =($D$21+'Balance Sheet'!I13-'Balance Sheet'!I9)/'P&L'!I9 -> 8.6483982 | J25: =($D$21+'Balance Sheet'!J13-'Balance Sheet'!J9)/'P&L'!J9 -> 7.1364437
B26: P / E (x) | C26: =$D$21/'P&L'!C17 -> 33.839842 | D26: =$D$21/'P&L'!D17 -> 33.086644 | E26: =$D$21/'P&L'!E17 -> 32.062484 | F26: =$D$21/'P&L'!F17 -> 29.438433 | G26: =$D$21/'P&L'!G17 -> 21.846261 | H26: =$D$21/'P&L'!H17 -> 17.831637 | I26: =$D$21/'P&L'!I17 -> 14.971611 | J26: =$D$21/'P&L'!J17 -> 12.852043
B27: Justified P/E (BASE) | C27: ='DCF & SOTP'!$E$51/'P&L'!C17 -> 27.496093 | D27: ='DCF & SOTP'!$E$51/'P&L'!D17 -> 26.884093 | E27: ='DCF & SOTP'!$E$51/'P&L'!E17 -> 26.051925 | F27: ='DCF & SOTP'!$E$51/'P&L'!F17 -> 23.91979 | G27: ='DCF & SOTP'!$E$51/'P&L'!G17 -> 17.750875 | H27: ='DCF & SOTP'!$E$51/'P&L'!H17 -> 14.488849 | I27: ='DCF & SOTP'!$E$51/'P&L'!I17 -> 12.164974 | J27: ='DCF & SOTP'!$E$51/'P&L'!J17 -> 10.442749
B28: Trailing P/E (FY26A basis) | D28: =E26 -> 32.062484
B29: Forward P/E (FY27E basis) | D29: =F26 -> 29.438433
B31: Historical P/E range (FY24A-FY26A) and Forward range (FY27E-FY31E) both shown in the P/E row above, columns C-J. 'Historical', 'Trailing' and 'Forward' are the same calculation (Ref. CMP / that year's EPS) applied to different columns - not three different methodologies.

Sheet Actuals
B2: Consolidated
C3: FY24 | G3: FY25 | K3: FY26
C4: 45078 | D4: 45170 | E4: 45261 | F4: 45352 | G4: 45444 | H4: 45536 | I4: 45627 | J4: 45717 | K4: 45809 | L4: 45901 | M4: 45992 | N4: 46082
B5: Qtr. Revenue | C5: 4245 | D5: 4372 | E5: 3980 | F5: 4173 | G5: 4436 | H5: 4450 | I5: 4017 | J5: 4335 | K5: 4695 | L5: 4365 | M5: 4201 | N5: 4735
B6: Annual Revenue | C6: 16770 | G6: 17238 | K6: 17995
B7: % of Revenue | C7: =C5/$C$6 -> 0.25313059 | D7: =D5/$C$6 -> 0.26070364 | E7: =E5/$C$6 -> 0.23732856 | F7: =F5/$C$6 -> 0.24883721 | G7: =G5/$G$6 -> 0.25733844 | H7: =H5/$G$6 -> 0.2581506 | I7: =I5/$G$6 -> 0.23303167 | J7: =J5/$G$6 -> 0.25147929 | K7: =K5/$K$6 -> 0.26090581 | L7: =L5/$K$6 -> 0.24256738 | M7: =M5/$K$6 -> 0.23345374 | N7: =N5/$K$6 -> 0.26312865
B10: Standalone
C11: FY24 | G11: FY25 | K11: FY26
C12: 45078 | D12: 45170 | E12: 45261 | F12: 45352 | G12: 45444 | H12: 45536 | I12: 45627 | J12: 45717 | K12: 45809 | L12: 45901 | M12: 45992 | N12: 46082
B13: Qtr. Revenue | C13: 4073 | D13: 4107 | E13: 3841 | F13: 4009 | G13: 4313 | H13: 4267 | I13: 3849 | J13: 4159 | K13: 4510 | L13: 4178 | M13: 4030 | N13: 4551
B14: Annual Revenue | C14: 16029 | G14: 16588 | K14: 17269
B15: % of Revenue | C15: =C13/$C$14 -> 0.25410194 | D15: =D13/$C$14 -> 0.2562231 | E15: =E13/$C$14 -> 0.23962817 | F15: =F13/$C$14 -> 0.25010918 | G15: =G13/$G$14 -> 0.26000723 | H15: =H13/$G$14 -> 0.25723415 | I15: =I13/$G$14 -> 0.23203521 | J15: =J13/$G$14 -> 0.25072341 | K15: =K13/$K$14 -> 0.26116162 | L15: =L13/$K$14 -> 0.24193642 | M15: =M13/$K$14 -> 0.23336615 | N15: =N13/$K$14 -> 0.26353582
G17: Standalone
C18: Consolidated | E18: Standalone | G18: FY27F | H18: FY27A | I18: Difference
B19: Quarter 1 | C19: =AVERAGE($C$7,$G$7,$K$7) -> 0.25712495 | E19: =AVERAGE($C$15,$G$15,$K$15) -> 0.2584236 | G19: =$G$23*E19 -> 4992.6416 | H19: 5319.09 | I19: =H19/G19-1 -> 0.065385899
B20: Quarter 2 | C20: =AVERAGE($D$7,$H$7,$L$7) -> 0.2538072 | E20: =AVERAGE($D$15,$H$15,$L$15) -> 0.25179789 | G20: =$G$23*E20 -> 4864.6355
B21: Quarter 3 | C21: =AVERAGE($E$7,$I$7,$M$7) -> 0.23460466 | E21: =AVERAGE($E$15,$I$15,$M$15) -> 0.23500984 | G21: =$G$23*E21 -> 4540.2972
B22: Quarter 4 | C22: =AVERAGE($F$7,$J$7,$N$7) -> 0.25448172 | E22: =AVERAGE($F$15,$J$15,$N$15) -> 0.25478947 | G22: =$G$23*E22 -> 4922.4317
G23: ='Executive Summary'!F12 -> 19319.604 | H23: =H19/E19 -> 20582.834 | I23: =H23/G23-1 -> 0.065385899
