Workbook

Sheet Executive Summary
A1: JUNIPER GREEN ENERGY LIMITED — EXECUTIVE SUMMARY
G2: Bear | H2: Base | I2: Bull
A3: Active Scenario (drives all detailed tabs): | B3: =Assumptions!$B$4 -> Base | C3: (change on the Assumptions tab, cell B4 — this cell mirrors it) | G3: 186.22403 | H3: 328.63564 | I3: 480.25358
G4: =G3/$B$16-1 -> -0.27256238 | H4: =H3/$B$16-1 -> 0.28373297 | I4: =I3/$B$16-1 -> 0.87599053
A6: FINANCIAL SNAPSHOT (current Active Scenario)
B7: FY26A | C7: FY27E | D7: FY28E | E7: FY29E | F7: FY30E | G7: FY31E
A8: Revenue (Rs cr) | B8: ='P&L'!D5 -> 718.934 | C8: ='P&L'!E5 -> 2437.5935 | D8: ='P&L'!F5 -> 5937.1108 | E8: ='P&L'!G5 -> 8038.7308 | F8: ='P&L'!H5 -> 10353.315 | G8: ='P&L'!I5 -> 11021.703
A9: EBITDA (Rs cr) | B9: ='P&L'!D26 -> 692.184 | C9: ='P&L'!E26 -> 2288.6528 | D9: ='P&L'!F26 -> 5667.7714 | E9: ='P&L'!G26 -> 7636.8088 | F9: ='P&L'!H26 -> 9828.8172 | G9: ='P&L'!I26 -> 10453.645
A10: EBITDA Margin % | B10: ='P&L'!D27 -> 0.85993068 | C10: ='P&L'!E27 -> 0.90536117 | D10: ='P&L'!F27 -> 0.93962953 | E10: ='P&L'!G27 -> 0.93838097 | F10: ='P&L'!H27 -> 0.93985118 | G10: ='P&L'!I27 -> 0.93910827
A11: PAT (Rs cr) | B11: ='P&L'!D38 -> 40.464 | C11: ='P&L'!E38 -> 327.01351 | D11: ='P&L'!F38 -> 1272.207 | E11: ='P&L'!G38 -> 1907.7001 | F11: ='P&L'!H38 -> 3169.1666 | G11: ='P&L'!I38 -> 3621.1844
A12: Net Debt/Equity (x) | B12: =Ratios!D14 -> 2.7930405 | C12: =Ratios!E14 -> 4.5342092 | D12: =Ratios!F14 -> 4.5118083 | E12: =Ratios!G14 -> 3.4990782 | F12: =Ratios!H14 -> 2.1831352 | G12: =Ratios!I14 -> 1.2986758
A14: VALUATION SUMMARY (current Active Scenario)
A15: FCFE-DCF Value per Share (Rs) | B15: =Valuation!$B$17 -> 328.63564
A16: CMP | B16: 256
A17: Implied Upside/(Downside) | B17: =Valuation!$B$19 -> 0.28373297
A18: EV/EBITDA (Forward, FY27E) | B18: =Valuation!E32 -> 10.542958
A19: P/E (Forward, FY27E) | B19: =Valuation!E35 -> 44.542887
A21: SCENARIO COMPARISON — BEAR / BASE / BULL (always live, independent of the switch above)
A22: Simplified portfolio-level approximation, NOT a full re-run of the 48-SPV detail. Isolates the two levers with a clean, quantifiable portfolio-wide effect (WSH/FDRE post-COD CUF; merchant tariff). Holds cost structure, tax rate, and D&A at Base-case levels. UCA timeline lever is excluded here as it washes out by FY31 in the detailed model (affects the ramp path and peak leverage, not the FY31 snapshot) — see Debt Model tab for its full effect.
B25: Bear | C25: Base | D25: Bull
A26: WSH/FDRE post-COD CUF | B26: =Assumptions!B40 -> 0.35 | C26: =Assumptions!C40 -> 0.4 | D26: =Assumptions!D40 -> 0.45
A27: Merchant tariff (Rs/kWh) | B27: =Assumptions!B49 -> 2.3 | C27: =Assumptions!C49 -> 2.83 | D27: =Assumptions!D49 -> 3.4
A29: Base-case FY31E Revenue (Rs cr) | C29: 7442.2887
A30: Adj: WSH/FDRE CUF delta impact (5,875.4 MW x 8760 x 1000 x d(CUF) x Rs3.939/kWh /1e6) | B30: =5875.4*8760*1000*(Assumptions!B40-Assumptions!$C$40)*3.939/10000000 -> -1013.6722 | D30: =5875.4*8760*1000*(Assumptions!D40-Assumptions!$C$40)*3.939/10000000 -> 1013.6722
A31: Adj: Merchant tariff delta impact (170 MW x 8760 x 1000 x 24.48% x d(Tariff) /1e6) | B31: =170*8760*1000*0.2448*(Assumptions!B49-Assumptions!$C$49)/10000000 -> -19.321476 | D31: =170*8760*1000*0.2448*(Assumptions!D49-Assumptions!$C$49)/10000000 -> 20.779701
A32: Scenario FY31E Revenue (Rs cr) | B32: =$C$29+B30+B31 -> 6409.295 | C32: =$C$29 -> 7442.2887 | D32: =$C$29+D30+D31 -> 8476.7405
A34: Scenario FY31E EBITDA (Rs cr, Base margin applied) | B34: =B32*$C$10 -> 5802.7268 | C34: =C32*$C$10 -> 6737.9591 | D34: =D32*$C$10 -> 7674.5117
A35: Scenario FY31E PAT (Rs cr, Base PAT margin applied) | B35: =B32*($C$11/$C$8) -> 859.83412 | C35: =C32*($C$11/$C$8) -> 998.4146 | D35: =D32*($C$11/$C$8) -> 1137.1907
A37: Approx. Value/Share (Rs) — Base DCF value scaled by scenario/Base FY31E PAT ratio | B37: 235.57337 | C37: 386.47239 | D37: 553.07614

Sheet Assumptions
A1: JUNIPER GREEN ENERGY LIMITED — MODEL ASSUMPTIONS
A3: SCENARIO SWITCH | I3: 2 | J3: Bear
A4: Active Scenario | B4: =INDEX(J3:J5,I3) -> Base | J4: Base
A5: (Drives WSH/FDRE post-COD CUF, UCA commissioning timeline, and merchant tariff below — Sections 6-8) | J5: Bull
A7: 1. COST OF EQUITY (CAPM) — user-specified, not independently sourced
A8: Risk-free rate (Rf) | B8: 0.0677
A9: Equity risk premium (ERP) | B9: 0.0708
A10: Beta | B10: 1.45
A11: Cost of Equity (Ke = Rf + Beta x ERP) | B11: =B8+B9*B10 -> 0.17036
A13: 2. TAX — Source: RHP tax notes; parent & Sigma on Sec.115BAA (25.168%); Field & Three on Sec.115BAB (17.16%); FY26 actual eff. rate 26.69%
A14: Blended effective tax rate (forward) | B14: 0.255
A16: 3. OPEX INFLATION & TERMINAL GROWTH — fixed across all scenarios per user instruction
A17: Opex inflation rate p.a. (CRISIL FY27P CPI, RHP Table 2) | B17: 0.05
A18: Terminal fade growth, Yrs 6-8 (FY32-FY34) | B18: 0.08
A19: Terminal growth, Yr 9+ (FY35 onward, Gordon growth) | B19: 0.05
A21: 4. DEBT FINANCING — Source: RHP Financial Indebtedness note, p.654 & management-cited project D:E
A22: New capex financing — Debt % | B22: 0.8
A23: New capex financing — Equity % | B23: =1-B22 -> 0.2
A24: New debt interest rate p.a. (upper-half of disclosed 7.75-9.75% term loan band) | B24: 0.09
A25: Existing debt blended effective rate p.a. | B25: 0.0875
A26: Assumed weighted-avg amortization tenor (years) — simplification, no per-loan maturity ladder disclosed | B26: 15
A28: 5. DEPRECIATION — USEFUL LIVES (Source: RHP Significant Accounting Policies, p.504)
A29: Solar power projects (technical assessment) | B29: 25
A30: Wind / WSH / FDRE / BESS plant & equipment (within 20-25yr band; conservative mid-point) | B30: 22
A31: Leasehold land (ROU) | B31: 29
A33: 6. GENERATION — CAPACITY UTILISATION FACTOR (CUF)
A34: Solar CUF (FY26 actual, RHP KPI table p.192) | B34: 0.2448 | K34: =IF(B34="Solar",Assumptions!$B$34,IF(B34="Wind",Assumptions!$B$35,IF(A34="Operational",Assumptions!$B$36,IF(B34="WSH",Assumptions!$E$40,)))) -> 0
A35: Wind CUF (FY26 actual, RHP KPI table p.192) | B35: 0.3184
A36: WSH/FDRE CUF — Operational bucket (solar-leg only commissioned; footnotes confirm wind-leg not yet built) | B36: =B34 -> 0.2448
A37: WSH/FDRE Operational bucket — effective interim tariff (solar-leg-only billing; weighted avg solar tariff proxy per RHP phased-billing mechanic p.21102) | B37: 2.8
A38: WSH/FDRE CUF post-COD (full hybrid), by scenario:
B39: Bear | C39: Base | D39: Bull | E39: Active
A40: WSH/FDRE CUF post-COD | B40: 0.35 | C40: 0.4 | D40: 0.45 | E40: =IF($B$4="Bear",B40,IF($B$4="Base",C40,D40)) -> 0.4
A41: FDRE CUF post-COD | B41: 0.4 | C41: 0.5 | D41: 0.6 | E41: =IF($B$4="Bear",B41,IF($B$4="Base",C41,D41)) -> 0.5
A42: 7. UNDER CONSTRUCTION AWARDED — MONTHS FROM LOA TO SCOD, by scenario (Source: RHP disclosed 13-24mo / 24-30mo implementation windows)
B43: Bear | C43: Base | D43: Bull | E43: Active
A44: WSH (13-24mo disclosed range) | B44: 54 | C44: 48 | D44: 40 | E44: =IF($B$4="Bear",B44,IF($B$4="Base",C44,D44)) -> 48
A45: FDRE (24-30mo disclosed range) | B45: 60 | C45: 54 | D45: 48 | E45: =IF($B$4="Bear",B45,IF($B$4="Base",C45,D45)) -> 54
A47: 8. MERCHANT POWER TARIFF ₹/kWh, by scenario (Base = FY26 disclosed historical realized average)
B48: Bear | C48: Base | D48: Bull | E48: Active
...

Sheet Revenue Model
A1: REVENUE MODEL — SPV LEVEL (48 PPAs/LOAs)
A2: Generation = AC Capacity(MW) x 1,000 x 8,760hrs x CUF x (Months Operational/12); Revenue = Generation x Tariff. COD-based monthly proration vs FY27 (Apr'26) start. All Rs in crores.
A4: Category | B4: Tech | C4: Entity | D4: Off-taker | E4: AC MW | F4: Base Tariff (Rs/kWh) | G4: Eff. Tariff (Rs/kWh) | H4: Base Date (PPA/LOA) | I4: COD | J4: COD Mth Idx | K4: CUF Applied | L4: FY27 Mths Op | M4: FY27 Rev | N4: FY28 Mths Op | O4: FY28 Rev | P4: FY29 Mths Op | Q4: FY29 Rev | R4: FY30 Mths Op | S4: FY30 Rev | T4: FY31 Mths Op | U4: FY31 Rev
A5: Operational | B5: Solar | C5: Nisagra Renewable Energy Pvt Ltd + Juniper Green Energy Ltd | D5: MSEDCL | E5: 100 | F5: 3.15 | G5: =IF(D5="Merchant",Assumptions!$E$49,IF(AND(A5="Operational",OR(B5="WSH",B5="FDRE")),Assumptions!$B$37,F5)) -> 3.15 | H5: 43461 | I5: 43831 | J5: =MAX(0,(YEAR(I5)-YEAR(Assumptions!$B$74))*12+(MONTH(I5)-MONTH(Assumptions!$B$74))) -> 0 | K5: =IF(B5="Solar",Assumptions!$B$34,IF(B5="Wind",Assumptions!$B$35,IF(B5="WSH",Assumptions!$E$40,Assumptions!$E$41))) -> 0.2448 | L5: =MAX(0,MIN(12,60)-MAX(0,$J5)) -> 12 | M5: =$E5*1000*8760*$K5*$G5*L5/12/10000000 -> 67.550112 | N5: =MAX(0,MIN(24,60)-MAX(12,$J5)) -> 12 | O5: =$E5*1000*8760*$K5*$G5*N5/12/10000000 -> 67.550112 | P5: =MAX(0,MIN(36,60)-MAX(24,$J5)) -> 12 | Q5: =$E5*1000*8760*$K5*$G5*P5/12/10000000 -> 67.550112 | R5: =MAX(0,MIN(48,60)-MAX(36,$J5)) -> 12 | S5: =$E5*1000*8760*$K5*$G5*R5/12/10000000 -> 67.550112 | T5: =MAX(0,MIN(60,60)-MAX(48,$J5)) -> 12 | U5: =$E5*1000*8760*$K5*$G5*T5/12/10000000 -> 67.550112
A6: Operational | B6: Solar | C6: Juniper Green Sigma Pvt Ltd | D6: GUVNL | E6: 120 | F6: 2.67 | G6: =IF(D6="Merchant",Assumptions!$E$49,IF(AND(A6="Operational",OR(B6="WSH",B6="FDRE")),Assumptions!$B$37,F6)) -> 2.67 | H6: 43606 | I6: 43831 | J6: =MAX(0,(YEAR(I6)-YEAR(Assumptions!$B$74))*12+(MONTH(I6)-MONTH(Assumptions!$B$74))) -> 0 | K6: =IF(B6="Solar",Assumptions!$B$34,IF(B6="Wind",Assumptions!$B$35,IF(B6="WSH",Assumptions!$E$40,Assumptions!$E$41))) -> 0.2448 | L6: =MAX(0,MIN(12,60)-MAX(0,$J6)) -> 12 | M6: =$E6*1000*8760*$K6*$G6*L6/12/10000000 -> 68.708114 | N6: =MAX(0,MIN(24,60)-MAX(12,$J6)) -> 12 | O6: =$E6*1000*8760*$K6*$G6*N6/12/10000000 -> 68.708114 | P6: =MAX(0,MIN(36,60)-MAX(24,$J6)) -> 12 | Q6: =$E6*1000*8760*$K6*$G6*P6/12/10000000 -> 68.708114 | R6: =MAX(0,MIN(48,60)-MAX(36,$J6)) -> 12 | S6: =$E6*1000*8760*$K6*$G6*R6/12/10000000 -> 68.708114 | T6: =MAX(0,MIN(60,60)-MAX(48,$J6)) -> 12 | U6: =$E6*1000*8760*$K6*$G6*T6/12/10000000 -> 68.708114
A7: Operational | B7: Solar | C7: Juniper Green Three Pvt Ltd | D7: GUVNL | E7: 190 | F7: 2.63 | G7: =IF(D7="Merchant",Assumptions!$E$49,IF(AND(A7="Operational",OR(B7="WSH",B7="FDRE")),Assumptions!$B$37,F7)) -> 2.63 | H7: 44020 | I7: 43831 | J7: =MAX(0,(YEAR(I7)-YEAR(Assumptions!$B$74))*12+(MONTH(I7)-MONTH(Assumptions!$B$74))) -> 0 | K7: =IF(B7="Solar",Assumptions!$B$34,IF(B7="Wind",Assumptions!$B$35,IF(B7="WSH",Assumptions!$E$40,Assumptions!$E$41))) -> 0.2448 | L7: =MAX(0,MIN(12,60)-MAX(0,$J7)) -> 12 | M7: =$E7*1000*8760*$K7*$G7*L7/12/10000000 -> 107.15807 | N7: =MAX(0,MIN(24,60)-MAX(12,$J7)) -> 12 | O7: =$E7*1000*8760*$K7*$G7*N7/12/10000000 -> 107.15807 | P7: =MAX(0,MIN(36,60)-MAX(24,$J7)) -> 12 | Q7: =$E7*1000*8760*$K7*$G7*P7/12/10000000 -> 107.15807 | R7: =MAX(0,MIN(48,60)-MAX(36,$J7)) -> 12 | S7: =$E7*1000*8760*$K7*$G7*R7/12/10000000 -> 107.15807 | T7: =MAX(0,MIN(60,60)-MAX(48,$J7)) -> 12 | U7: =$E7*1000*8760*$K7*$G7*T7/12/10000000 -> 107.15807
A8: Operational | B8: Solar | C8: Juniper Green Field Pvt Ltd | D8: MSEDCL | E8: 150 | F8: 2.89 | G8: =IF(D8="Merchant",Assumptions!$E$49,IF(AND(A8="Operational",OR(B8="WSH",B8="FDRE")),Assumptions!$B$37,F8)) -> 2.89 | H8: 44092 | I8: 43831 | J8: =MAX(0,(YEAR(I8)-YEAR(Assumptions!$B$74))*12+(MONTH(I8)-MONTH(Assumptions!$B$74))) -> 0 | K8: =IF(B8="Solar",Assumptions!$B$34,IF(B8="Wind",Assumptions!$B$35,IF(B8="WSH",Assumptions!$E$40,Assumptions!$E$41))) -> 0.2448 | L8: =MAX(0,MIN(12,60)-MAX(0,$J8)) -> 12 | M8: =$E8*1000*8760*$K8*$G8*L8/12/10000000 -> 92.961821 | N8: =MAX(0,MIN(24,60)-MAX(12,$J8)) -> 12 | O8: =$E8*1000*8760*$K8*$G8*N8/12/10000000 -> 92.961821 | P8: =MAX(0,MIN(36,60)-MAX(24,$J8)) -> 12 | Q8: =$E8*1000*8760*$K8*$G8*P8/12/10000000 -> 92.961821 | R8: =MAX(0,MIN(48,60)-MAX(36,$J8)) -> 12 | S8: =$E8*1000*8760*$K8*$G8*R8/12/10000000 -> 92.961821 | T8: =MAX(0,MIN(60,60)-MAX(48,$J8)) -> 12 | U8: =$E8*1000*8760*$K8*$G8*T8/12/10000000 -> 92.961821
A9: Operational | B9: Solar | C9: Juniper Green Gamma One Pvt Ltd | D9: MSEDCL | E9: 75 | F9: 2.9 | G9: =IF(D9="Merchant",Assumptions!$E$49,IF(AND(A9="Operational",OR(B9="WSH",B9="FDRE")),Assumptions!$B$37,F9)) -> 2.9 | H9: 45111 | I9: 43831 | J9: =MAX(0,(YEAR(I9)-YEAR(Assumptions!$B$74))*12+(MONTH(I9)-MONTH(Assumptions!$B$74))) -> 0 | K9: =IF(B9="Solar",Assumptions!$B$34,IF(B9="Wind",Assumptions!$B$35,IF(B9="WSH",Assumptions!$E$40,Assumptions!$E$41))) -> 0.2448 | L9: =MAX(0,MIN(12,60)-MAX(0,$J9)) -> 12 | M9: =$E9*1000*8760*$K9*$G9*L9/12/10000000 -> 46.641744 | N9: =MAX(0,MIN(24,60)-MAX(12,$J9)) -> 12 | O9: =$E9*1000*8760*$K9*$G9*N9/12/10000000 -> 46.641744 | P9: =MAX(0,MIN(36,60)-MAX(24,$J9)) -> 12 | Q9: =$E9*1000*8760*$K9*$G9*P9/12/10000000 -> 46.641744 | R9: =MAX(0,MIN(48,60)-MAX(36,$J9)) -> 12 | S9: =$E9*1000*8760*$K9*$G9*R9/12/10000000 -> 46.641744 | T9: =MAX(0,MIN(60,60)-MAX(48,$J9)) -> 12 | U9: =$E9*1000*8760*$K9*$G9*T9/12/10000000 -> 46.641744
A10: Operational | B10: Solar | C10: Juniper Green Cosmic Pvt Ltd | D10: Merchant | E10: 100 | G10: =IF(D10="Merchant",Assumptions!$E$49,IF(AND(A10="Operational",OR(B10="WSH",B10="FDRE")),Assumptions!$B$37,F10)) -> 2.83 | H10: 45575 | I10: 43831 | J10: =MAX(0,(YEAR(I10)-YEAR(Assumptions!$B$74))*12+(MONTH(I10)-MONTH(Assumptions!$B$74))) -> 0 | K10: =IF(B10="Solar",Assumptions!$B$34,IF(B10="Wind",Assumptions!$B$35,IF(B10="WSH",Assumptions!$E$40,Assumptions!$E$41))) -> 0.2448 | L10: =MAX(0,MIN(12,60)-MAX(0,$J10)) -> 12 | M10: =$E10*1000*8760*$K10*$G10*L10/12/10000000 -> 60.687878 | N10: =MAX(0,MIN(24,60)-MAX(12,$J10)) -> 12 | O10: =$E10*1000*8760*$K10*$G10*N10/12/10000000 -> 60.687878 | P10: =MAX(0,MIN(36,60)-MAX(24,$J10)) -> 12 | Q10: =$E10*1000*8760*$K10*$G10*P10/12/10000000 -> 60.687878 | R10: =MAX(0,MIN(48,60)-MAX(36,$J10)) -> 12 | S10: =$E10*1000*8760*$K10*$G10*R10/12/10000000 -> 60.687878 | T10: =MAX(0,MIN(60,60)-MAX(48,$J10)) -> 12 | U10: =$E10*1000*8760*$K10*$G10*T10/12/10000000 -> 60.687878
A11: Operational | B11: Solar | C11: Juniper Nirjara Energy Pvt Ltd | D11: Merchant | E11: 50 | G11: =IF(D11="Merchant",Assumptions!$E$49,IF(AND(A11="Operational",OR(B11="WSH",B11="FDRE")),Assumptions!$B$37,F11)) -> 2.83 | H11: 45739 | I11: 43831 | J11: =MAX(0,(YEAR(I11)-YEAR(Assumptions!$B$74))*12+(MONTH(I11)-MONTH(Assumptions!$B$74))) -> 0 | K11: =IF(B11="Solar",Assumptions!$B$34,IF(B11="Wind",Assumptions!$B$35,IF(B11="WSH",Assumptions!$E$40,Assumptions!$E$41))) -> 0.2448 | L11: =MAX(0,MIN(12,60)-MAX(0,$J11)) -> 12 | M11: =$E11*1000*8760*$K11*$G11*L11/12/10000000 -> 30.343939 | N11: =MAX(0,MIN(24,60)-MAX(12,$J11)) -> 12 | O11: =$E11*1000*8760*$K11*$G11*N11/12/10000000 -> 30.343939 | P11: =MAX(0,MIN(36,60)-MAX(24,$J11)) -> 12 | Q11: =$E11*1000*8760*$K11*$G11*P11/12/10000000 -> 30.343939 | R11: =MAX(0,MIN(48,60)-MAX(36,$J11)) -> 12 | S11: =$E11*1000*8760*$K11*$G11*R11/12/10000000 -> 30.343939 | T11: =MAX(0,MIN(60,60)-MAX(48,$J11)) -> 12 | U11: =$E11*1000*8760*$K11*$G11*T11/12/10000000 -> 30.343939
A12: Operational | B12: Solar | C12: Juniper Green Ray Two Pvt Ltd | D12: MSEDCL | E12: 150 | F12: 2.75 | G12: =IF(D12="Merchant",Assumptions!$E$49,IF(AND(A12="Operational",OR(B12="WSH",B12="FDRE")),Assumptions!$B$37,F12)) -> 2.75 | H12: 45784 | I12: 43831 | J12: =MAX(0,(YEAR(I12)-YEAR(Assumptions!$B$74))*12+(MONTH(I12)-MONTH(Assumptions!$B$74))) -> 0 | K12: =IF(B12="Solar",Assumptions!$B$34,IF(B12="Wind",Assumptions!$B$35,IF(B12="WSH",Assumptions!$E$40,Assumptions!$E$41))) -> 0.2448 | L12: =MAX(0,MIN(12,60)-MAX(0,$J12)) -> 12 | M12: =$E12*1000*8760*$K12*$G12*L12/12/10000000 -> 88.45848 | N12: =MAX(0,MIN(24,60)-MAX(12,$J12)) -> 12 | O12: =$E12*1000*8760*$K12*$G12*N12/12/10000000 -> 88.45848 | P12: =MAX(0,MIN(36,60)-MAX(24,$J12)) -> 12 | Q12: =$E12*1000*8760*$K12*$G12*P12/12/10000000 -> 88.45848 | R12: =MAX(0,MIN(48,60)-MAX(36,$J12)) -> 12 | S12: =$E12*1000*8760*$K12*$G12*R12/12/10000000 -> 88.45848 | T12: =MAX(0,MIN(60,60)-MAX(48,$J12)) -> 12 | U12: =$E12*1000*8760*$K12*$G12*T12/12/10000000 -> 88.45848
A13: Operational | B13: Wind | C13: Juniper Green Beam Pvt Ltd | D13: GUVNL | E13: 69.3 | F13: 2.9 | G13: =IF(D13="Merchant",Assumptions!$E$49,IF(AND(A13="Operational",OR(B13="WSH",B13="FDRE")),Assumptions!$B$37,F13)) -> 2.9 | H13: 44909 | I13: 43831 | J13: =MAX(0,(YEAR(I13)-YEAR(Assumptions!$B$74))*12+(MONTH(I13)-MONTH(Assumptions!$B$74))) -> 0 | K13: =IF(B13="Solar",Assumptions!$B$34,IF(B13="Wind",Assumptions!$B$35,IF(B13="WSH",Assumptions!$E$40,Assumptions!$E$41))) -> 0.3184 | L13: =MAX(0,MIN(12,60)-MAX(0,$J13)) -> 12 | M13: =$E13*1000*8760*$K13*$G13*L13/12/10000000 -> 56.054231 | N13: =MAX(0,MIN(24,60)-MAX(12,$J13)) -> 12 | O13: =$E13*1000*8760*$K13*$G13*N13/12/10000000 -> 56.054231 | P13: =MAX(0,MIN(36,60)-MAX(24,$J13)) -> 12 | Q13: =$E13*1000*8760*$K13*$G13*P13/12/10000000 -> 56.054231 | R13: =MAX(0,MIN(48,60)-MAX(36,$J13)) -> 12 | S13: =$E13*1000*8760*$K13*$G13*R13/12/10000000 -> 56.054231 | T13: =MAX(0,MIN(60,60)-MAX(48,$J13)) -> 12 | U13: =$E13*1000*8760*$K13*$G13*T13/12/10000000 -> 56.054231
A14: Operational | B14: Wind | C14: Juniper Green Beam Pvt Ltd | D14: GUVNL | E14: 50.4 | F14: 2.95 | G14: =IF(D14="Merchant",Assumptions!$E$49,IF(AND(A14="Operational",OR(B14="WSH",B14="FDRE")),Assumptions!$B$37,F14)) -> 2.95 | H14: 45056 | I14: 43831 | J14: =MAX(0,(YEAR(I14)-YEAR(Assumptions!$B$74))*12+(MONTH(I14)-MONTH(Assumptions!$B$74))) -> 0 | K14: =IF(B14="Solar",Assumptions!$B$34,IF(B14="Wind",Assumptions!$B$35,IF(B14="WSH",Assumptions!$E$40,Assumptions!$E$41))) -> 0.3184 | L14: =MAX(0,MIN(12,60)-MAX(0,$J14)) -> 12 | M14: =$E14*1000*8760*$K14*$G14*L14/12/10000000 -> 41.469588 | N14: =MAX(0,MIN(24,60)-MAX(12,$J14)) -> 12 | O14: =$E14*1000*8760*$K14*$G14*N14/12/10000000 -> 41.469588 | P14: =MAX(0,MIN(36,60)-MAX(24,$J14)) -> 12 | Q14: =$E14*1000*8760*$K14*$G14*P14/12/10000000 -> 41.469588 | R14: =MAX(0,MIN(48,60)-MAX(36,$J14)) -> 12 | S14: =$E14*1000*8760*$K14*$G14*R14/12/10000000 -> 41.469588 | T14: =MAX(0,MIN(60,60)-MAX(48,$J14)) -> 12 | U14: =$E14*1000*8760*$K14*$G14*T14/12/10000000 -> 41.469588
A15: Operational | B15: Wind | C15: Juniper Green Kite Pvt Ltd | D15: GUVNL | E15: 72.45 | F15: 3.11 | G15: =IF(D15="Merchant",Assumptions!$E$49,IF(AND(A15="Operational",OR(B15="WSH",B15="FDRE")),Assumptions!$B$37,F15)) -> 3.11 | H15: 45330 | I15: 43831 | J15: =MAX(0,(YEAR(I15)-YEAR(Assumptions!$B$74))*12+(MONTH(I15)-MONTH(Assumptions!$B$74))) -> 0 | K15: =IF(B15="Solar",Assumptions!$B$34,IF(B15="Wind",Assumptions!$B$35,IF(B15="WSH",Assumptions!$E$40,Assumptions!$E$41))) -> 0.3184 | L15: =MAX(0,MIN(12,60)-MAX(0,$J15)) -> 12 | M15: =$E15*1000*8760*$K15*$G15*L15/12/10000000 -> 62.845754 | N15: =MAX(0,MIN(24,60)-MAX(12,$J15)) -> 12 | O15: =$E15*1000*8760*$K15*$G15*N15/12/10000000 -> 62.845754 | P15: =MAX(0,MIN(36,60)-MAX(24,$J15)) -> 12 | Q15: =$E15*1000*8760*$K15*$G15*P15/12/10000000 -> 62.845754 | R15: =MAX(0,MIN(48,60)-MAX(36,$J15)) -> 12 | S15: =$E15*1000*8760*$K15*$G15*R15/12/10000000 -> 62.845754 | T15: =MAX(0,MIN(60,60)-MAX(48,$J15)) -> 12 | U15: =$E15*1000*8760*$K15*$G15*T15/12/10000000 -> 62.845754
A16: Operational | B16: Wind | C16: Juniper Green Kite Pvt Ltd | D16: GUVNL | E16: 20 | F16: 3.44 | G16: =IF(D16="Merchant",Assumptions!$E$49,IF(AND(A16="Operational",OR(B16="WSH",B16="FDRE")),Assumptions!$B$37,F16)) -> 3.44 | H16: 45463 | I16: 43831 | J16: =MAX(0,(YEAR(I16)-YEAR(Assumptions!$B$74))*12+(MONTH(I16)-MONTH(Assumptions!$B$74))) -> 0 | K16: =IF(B16="Solar",Assumptions!$B$34,IF(B16="Wind",Assumptions!$B$35,IF(B16="WSH",Assumptions!$E$40,Assumptions!$E$41))) -> 0.3184 | L16: =MAX(0,MIN(12,60)-MAX(0,$J16)) -> 12 | M16: =$E16*1000*8760*$K16*$G16*L16/12/10000000 -> 19.189586 | N16: =MAX(0,MIN(24,60)-MAX(12,$J16)) -> 12 | O16: =$E16*1000*8760*$K16*$G16*N16/12/10000000 -> 19.189586 | P16: =MAX(0,MIN(36,60)-MAX(24,$J16)) -> 12 | Q16: =$E16*1000*8760*$K16*$G16*P16/12/10000000 -> 19.189586 | R16: =MAX(0,MIN(48,60)-MAX(36,$J16)) -> 12 | S16: =$E16*1000*8760*$K16*$G16*R16/12/10000000 -> 19.189586 | T16: =MAX(0,MIN(60,60)-MAX(48,$J16)) -> 12 | U16: =$E16*1000*8760*$K16*$G16*T16/12/10000000 -> 19.189586
A17: Operational | B17: WSH | C17: Juniper Green Power Five Pvt Ltd | D17: MSEDCL | E17: 75 | F17: 3.6 | G17: =IF(D17="Merchant",Assumptions!$E$49,IF(AND(A17="Operational",OR(B17="WSH",B17="FDRE")),Assumptions!$B$37,F17)) -> 2.8 | H17: 44909 | I17: 43831 | J17: =MAX(0,(YEAR(I17)-YEAR(Assumptions!$B$74))*12+(MONTH(I17)-MONTH(Assumptions!$B$74))) -> 0 | K17: =IF(B17="Solar",Assumptions!$B$34,IF(B17="Wind",Assumptions!$B$35,IF(B17="WSH",Assumptions!$E$40,Assumptions!$E$41))) -> 0.4 | L17: =MAX(0,MIN(12,60)-MAX(0,$J17)) -> 12 | M17: =$E17*1000*8760*$K17*$G17*L17/12/10000000 -> 73.584 | N17: =MAX(0,MIN(24,60)-MAX(12,$J17)) -> 12 | O17: =$E17*1000*8760*$K17*$G17*N17/12/10000000 -> 73.584 | P17: =MAX(0,MIN(36,60)-MAX(24,$J17)) -> 12 | Q17: =$E17*1000*8760*$K17*$G17*P17/12/10000000 -> 73.584 | R17: =MAX(0,MIN(48,60)-MAX(36,$J17)) -> 12 | S17: =$E17*1000*8760*$K17*$G17*R17/12/10000000 -> 73.584 | T17: =MAX(0,MIN(60,60)-MAX(48,$J17)) -> 12 | U17: =$E17*1000*8760*$K17*$G17*T17/12/10000000 -> 73.584
A18: Operational | B18: WSH | C18: Juniper Green Spark Ten Pvt Ltd | D18: MSEDCL | E18: 75 | F18: 3.6 | G18: =IF(D18="Merchant",Assumptions!$E$49,IF(AND(A18="Operational",OR(B18="WSH",B18="FDRE")),Assumptions!$B$37,F18)) -> 2.8 | H18: 44909 | I18: 43831 | J18: =MAX(0,(YEAR(I18)-YEAR(Assumptions!$B$74))*12+(MONTH(I18)-MONTH(Assumptions!$B$74))) -> 0 | K18: =IF(B18="Solar",Assumptions!$B$34,IF(B18="Wind",Assumptions!$B$35,IF(B18="WSH",Assumptions!$E$40,Assumptions!$E$41))) -> 0.4 | L18: =MAX(0,MIN(12,60)-MAX(0,$J18)) -> 12 | M18: =$E18*1000*8760*$K18*$G18*L18/12/10000000 -> 73.584 | N18: =MAX(0,MIN(24,60)-MAX(12,$J18)) -> 12 | O18: =$E18*1000*8760*$K18*$G18*N18/12/10000000 -> 73.584 | P18: =MAX(0,MIN(36,60)-MAX(24,$J18)) -> 12 | Q18: =$E18*1000*8760*$K18*$G18*P18/12/10000000 -> 73.584 | R18: =MAX(0,MIN(48,60)-MAX(36,$J18)) -> 12 | S18: =$E18*1000*8760*$K18*$G18*R18/12/10000000 -> 73.584 | T18: =MAX(0,MIN(60,60)-MAX(48,$J18)) -> 12 | U18: =$E18*1000*8760*$K18*$G18*T18/12/10000000 -> 73.584
A19: Operational | B19: WSH | C19: Juniper Green Energy Ltd | D19: GUVNL | E19: 100.45 | F19: 3.04 | G19: =IF(D19="Merchant",Assumptions!$E$49,IF(AND(A19="Operational",OR(B19="WSH",B19="FDRE")),Assumptions!$B$37,F19)) -> 2.8 | H19: 45477 | I19: 43831 | J19: =MAX(0,(YEAR(I19)-YEAR(Assumptions!$B$74))*12+(MONTH(I19)-MONTH(Assumptions!$B$74))) -> 0 | K19: =IF(B19="Solar",Assumptions!$B$34,IF(B19="Wind",Assumptions!$B$35,IF(B19="WSH",Assumptions!$E$40,Assumptions!$E$41))) -> 0.4 | L19: =MAX(0,MIN(12,60)-MAX(0,$J19)) -> 12 | M19: =$E19*1000*8760*$K19*$G19*L19/12/10000000 -> 98.553504 | N19: =MAX(0,MIN(24,60)-MAX(12,$J19)) -> 12 | O19: =$E19*1000*8760*$K19*$G19*N19/12/10000000 -> 98.553504 | P19: =MAX(0,MIN(36,60)-MAX(24,$J19)) -> 12 | Q19: =$E19*1000*8760*$K19*$G19*P19/12/10000000 -> 98.553504 | R19: =MAX(0,MIN(48,60)-MAX(36,$J19)) -> 12 | S19: =$E19*1000*8760*$K19*$G19*R19/12/10000000 -> 98.553504 | T19: =MAX(0,MIN(60,60)-MAX(48,$J19)) -> 12 | U19: =$E19*1000*8760*$K19*$G19*T19/12/10000000 -> 98.553504
A20: Operational | B20: WSH | C20: Juniper Green Spark Four Pvt Ltd | D20: GUVNL | E20: 30.3 | F20: 3.3 | G20: =IF(D20="Merchant",Assumptions!$E$49,IF(AND(A20="Operational",OR(B20="WSH",B20="FDRE")),Assumptions!$B$37,F20)) -> 2.8 | H20: 45575 | I20: 43831 | J20: =MAX(0,(YEAR(I20)-YEAR(Assumptions!$B$74))*12+(MONTH(I20)-MONTH(Assumptions!$B$74))) -> 0 | K20: =IF(B20="Solar",Assumptions!$B$34,IF(B20="Wind",Assumptions!$B$35,IF(B20="WSH",Assumptions!$E$40,Assumptions!$E$41))) -> 0.4 | L20: =MAX(0,MIN(12,60)-MAX(0,$J20)) -> 12 | M20: =$E20*1000*8760*$K20*$G20*L20/12/10000000 -> 29.727936 | N20: =MAX(0,MIN(24,60)-MAX(12,$J20)) -> 12 | O20: =$E20*1000*8760*$K20*$G20*N20/12/10000000 -> 29.727936 | P20: =MAX(0,MIN(36,60)-MAX(24,$J20)) -> 12 | Q20: =$E20*1000*8760*$K20*$G20*P20/12/10000000 -> 29.727936 | R20: =MAX(0,MIN(48,60)-MAX(36,$J20)) -> 12 | S20: =$E20*1000*8760*$K20*$G20*R20/12/10000000 -> 29.727936 | T20: =MAX(0,MIN(60,60)-MAX(48,$J20)) -> 12 | U20: =$E20*1000*8760*$K20*$G20*T20/12/10000000 -> 29.727936
A21: Operational | B21: FDRE | C21: Juniper Green Stellar Pvt Ltd | D21: SJVN | E21: 266.9 | F21: 4.38 | G21: =IF(D21="Merchant",Assumptions!$E$49,IF(AND(A21="Operational",OR(B21="WSH",B21="FDRE")),Assumptions!$B$37,F21)) -> 2.8 | H21: 45412 | I21: 43831 | J21: =MAX(0,(YEAR(I21)-YEAR(Assumptions!$B$74))*12+(MONTH(I21)-MONTH(Assumptions!$B$74))) -> 0 | K21: =IF(B21="Solar",Assumptions!$B$34,IF(B21="Wind",Assumptions!$B$35,IF(B21="WSH",Assumptions!$E$40,Assumptions!$E$41))) -> 0.5 | L21: =MAX(0,MIN(12,60)-MAX(0,$J21)) -> 12 | M21: =$E21*1000*8760*$K21*$G21*L21/12/10000000 -> 327.32616 | N21: =MAX(0,MIN(24,60)-MAX(12,$J21)) -> 12 | O21: =$E21*1000*8760*$K21*$G21*N21/12/10000000 -> 327.32616 | P21: =MAX(0,MIN(36,60)-MAX(24,$J21)) -> 12 | Q21: =$E21*1000*8760*$K21*$G21*P21/12/10000000 -> 327.32616 | R21: =MAX(0,MIN(48,60)-MAX(36,$J21)) -> 12 | S21: =$E21*1000*8760*$K21*$G21*R21/12/10000000 -> 327.32616 | T21: =MAX(0,MIN(60,60)-MAX(48,$J21)) -> 12 | U21: =$E21*1000*8760*$K21*$G21*T21/12/10000000 -> 327.32616
A22: Operational | B22: FDRE | C22: Juniper Green Stellar Pvt Ltd | D22: SJVN | E22: 100 | F22: 4.38 | G22: =IF(D22="Merchant",Assumptions!$E$49,IF(AND(A22="Operational",OR(B22="WSH",B22="FDRE")),Assumptions!$B$37,F22)) -> 2.8 | H22: 45412 | I22: 43831 | J22: =MAX(0,(YEAR(I22)-YEAR(Assumptions!$B$74))*12+(MONTH(I22)-MONTH(Assumptions!$B$74))) -> 0 | K22: =IF(B22="Solar",Assumptions!$B$34,IF(B22="Wind",Assumptions!$B$35,IF(B22="WSH",Assumptions!$E$40,Assumptions!$E$41))) -> 0.5 | L22: =MAX(0,MIN(12,60)-MAX(0,$J22)) -> 12 | M22: =$E22*1000*8760*$K22*$G22*L22/12/10000000 -> 122.64 | N22: =MAX(0,MIN(24,60)-MAX(12,$J22)) -> 12 | O22: =$E22*1000*8760*$K22*$G22*N22/12/10000000 -> 122.64 | P22: =MAX(0,MIN(36,60)-MAX(24,$J22)) -> 12 | Q22: =$E22*1000*8760*$K22*$G22*P22/12/10000000 -> 122.64 | R22: =MAX(0,MIN(48,60)-MAX(36,$J22)) -> 12 | S22: =$E22*1000*8760*$K22*$G22*R22/12/10000000 -> 122.64 | T22: =MAX(0,MIN(60,60)-MAX(48,$J22)) -> 12 | U22: =$E22*1000*8760*$K22*$G22*T22/12/10000000 -> 122.64
A23: UCC | B23: Solar | C23: Juniper Green Beta Pvt Ltd | D23: Merchant | E23: 20 | G23: =IF(D23="Merchant",Assumptions!$E$49,IF(AND(A23="Operational",OR(B23="WSH",B23="FDRE")),Assumptions!$B$37,F23)) -> 2.83 | H23: 45292 | I23: 46192 | J23: =MAX(0,(YEAR(I23)-YEAR(Assumptions!$B$74))*12+(MONTH(I23)-MONTH(Assumptions!$B$74))) -> 2 | K23: =IF(B23="Solar",Assumptions!$B$34,IF(B23="Wind",Assumptions!$B$35,IF(B23="WSH",Assumptions!$E$40,Assumptions!$E$41))) -> 0.2448 | L23: =MAX(0,MIN(12,60)-MAX(0,$J23)) -> 10 | M23: =$E23*1000*8760*$K23*$G23*L23/12/10000000 -> 10.114646 | N23: =MAX(0,MIN(24,60)-MAX(12,$J23)) -> 12 | O23: =$E23*1000*8760*$K23*$G23*N23/12/10000000 -> 12.137576 | P23: =MAX(0,MIN(36,60)-MAX(24,$J23)) -> 12 | Q23: =$E23*1000*8760*$K23*$G23*P23/12/10000000 -> 12.137576 | R23: =MAX(0,MIN(48,60)-MAX(36,$J23)) -> 12 | S23: =$E23*1000*8760*$K23*$G23*R23/12/10000000 -> 12.137576 | T23: =MAX(0,MIN(60,60)-MAX(48,$J23)) -> 12 | U23: =$E23*1000*8760*$K23*$G23*T23/12/10000000 -> 12.137576
A24: UCC | B24: Wind | C24: Juniper Green Kite Pvt Ltd | D24: GUVNL | E24: 70 | F24: 3.44 | G24: =IF(D24="Merchant",Assumptions!$E$49,IF(AND(A24="Operational",OR(B24="WSH",B24="FDRE")),Assumptions!$B$37,F24)) -> 3.44 | H24: 45463 | I24: 46192 | J24: =MAX(0,(YEAR(I24)-YEAR(Assumptions!$B$74))*12+(MONTH(I24)-MONTH(Assumptions!$B$74))) -> 2 | K24: =IF(B24="Solar",Assumptions!$B$34,IF(B24="Wind",Assumptions!$B$35,IF(B24="WSH",Assumptions!$E$40,Assumptions!$E$41))) -> 0.3184 | L24: =MAX(0,MIN(12,60)-MAX(0,$J24)) -> 10 | M24: =$E24*1000*8760*$K24*$G24*L24/12/10000000 -> 55.969626 | N24: =MAX(0,MIN(24,60)-MAX(12,$J24)) -> 12 | O24: =$E24*1000*8760*$K24*$G24*N24/12/10000000 -> 67.163551 | P24: =MAX(0,MIN(36,60)-MAX(24,$J24)) -> 12 | Q24: =$E24*1000*8760*$K24*$G24*P24/12/10000000 -> 67.163551 | R24: =MAX(0,MIN(48,60)-MAX(36,$J24)) -> 12 | S24: =$E24*1000*8760*$K24*$G24*R24/12/10000000 -> 67.163551 | T24: =MAX(0,MIN(60,60)-MAX(48,$J24)) -> 12 | U24: =$E24*1000*8760*$K24*$G24*T24/12/10000000 -> 67.163551
A25: UCC | B25: Wind | C25: Juniper Green Bess Two Pvt Ltd | D25: GUVNL | E25: 100 | F25: 3.56 | G25: =IF(D25="Merchant",Assumptions!$E$49,IF(AND(A25="Operational",OR(B25="WSH",B25="FDRE")),Assumptions!$B$37,F25)) -> 3.56 | H25: 45856 | I25: 46585 | J25: =MAX(0,(YEAR(I25)-YEAR(Assumptions!$B$74))*12+(MONTH(I25)-MONTH(Assumptions!$B$74))) -> 15 | K25: =IF(B25="Solar",Assumptions!$B$34,IF(B25="Wind",Assumptions!$B$35,IF(B25="WSH",Assumptions!$E$40,Assumptions!$E$41))) -> 0.3184 | L25: =MAX(0,MIN(12,60)-MAX(0,$J25)) -> 0 | M25: =$E25*1000*8760*$K25*$G25*L25/12/10000000 -> 0 | N25: =MAX(0,MIN(24,60)-MAX(12,$J25)) -> 9 | O25: =$E25*1000*8760*$K25*$G25*N25/12/10000000 -> 74.471213 | P25: =MAX(0,MIN(36,60)-MAX(24,$J25)) -> 12 | Q25: =$E25*1000*8760*$K25*$G25*P25/12/10000000 -> 99.29495 | R25: =MAX(0,MIN(48,60)-MAX(36,$J25)) -> 12 | S25: =$E25*1000*8760*$K25*$G25*R25/12/10000000 -> 99.29495 | T25: =MAX(0,MIN(60,60)-MAX(48,$J25)) -> 12 | U25: =$E25*1000*8760*$K25*$G25*T25/12/10000000 -> 99.29495
A26: UCC | B26: Wind | C26: Juniper Green Bess Delta Pvt Ltd | D26: GUVNL | E26: 50 | F26: 3.65 | G26: =IF(D26="Merchant",Assumptions!$E$49,IF(AND(A26="Operational",OR(B26="WSH",B26="FDRE")),Assumptions!$B$37,F26)) -> 3.65 | H26: 45852 | I26: 46697 | J26: =MAX(0,(YEAR(I26)-YEAR(Assumptions!$B$74))*12+(MONTH(I26)-MONTH(Assumptions!$B$74))) -> 19 | K26: =IF(B26="Solar",Assumptions!$B$34,IF(B26="Wind",Assumptions!$B$35,IF(B26="WSH",Assumptions!$E$40,Assumptions!$E$41))) -> 0.3184 | L26: =MAX(0,MIN(12,60)-MAX(0,$J26)) -> 0 | M26: =$E26*1000*8760*$K26*$G26*L26/12/10000000 -> 0 | N26: =MAX(0,MIN(24,60)-MAX(12,$J26)) -> 5 | O26: =$E26*1000*8760*$K26*$G26*N26/12/10000000 -> 21.20942 | P26: =MAX(0,MIN(36,60)-MAX(24,$J26)) -> 12 | Q26: =$E26*1000*8760*$K26*$G26*P26/12/10000000 -> 50.902608 | R26: =MAX(0,MIN(48,60)-MAX(36,$J26)) -> 12 | S26: =$E26*1000*8760*$K26*$G26*R26/12/10000000 -> 50.902608 | T26: =MAX(0,MIN(60,60)-MAX(48,$J26)) -> 12 | U26: =$E26*1000*8760*$K26*$G26*T26/12/10000000 -> 50.902608
A27: UCC | B27: WSH | C27: Juniper Green Beam Eight Pvt Ltd | D27: TPCL | E27: 75 | F27: 3.27 | G27: =IF(D27="Merchant",Assumptions!$E$49,IF(AND(A27="Operational",OR(B27="WSH",B27="FDRE")),Assumptions!$B$37,F27)) -> 3.27 | H27: 45380 | I27: 46134 | J27: =MAX(0,(YEAR(I27)-YEAR(Assumptions!$B$74))*12+(MONTH(I27)-MONTH(Assumptions!$B$74))) -> 0 | K27: =IF(B27="Solar",Assumptions!$B$34,IF(B27="Wind",Assumptions!$B$35,IF(B27="WSH",Assumptions!$E$40,Assumptions!$E$41))) -> 0.4 | L27: =MAX(0,MIN(12,60)-MAX(0,$J27)) -> 12 | M27: =$E27*1000*8760*$K27*$G27*L27/12/10000000 -> 85.9356 | N27: =MAX(0,MIN(24,60)-MAX(12,$J27)) -> 12 | O27: =$E27*1000*8760*$K27*$G27*N27/12/10000000 -> 85.9356 | P27: =MAX(0,MIN(36,60)-MAX(24,$J27)) -> 12 | Q27: =$E27*1000*8760*$K27*$G27*P27/12/10000000 -> 85.9356 | R27: =MAX(0,MIN(48,60)-MAX(36,$J27)) -> 12 | S27: =$E27*1000*8760*$K27*$G27*R27/12/10000000 -> 85.9356 | T27: =MAX(0,MIN(60,60)-MAX(48,$J27)) -> 12 | U27: =$E27*1000*8760*$K27*$G27*T27/12/10000000 -> 85.9356
A28: UCC | B28: WSH | C28: Juniper Green Energy Ltd | D28: GUVNL | E28: 50 | F28: 3.04 | G28: =IF(D28="Merchant",Assumptions!$E$49,IF(AND(A28="Operational",OR(B28="WSH",B28="FDRE")),Assumptions!$B$37,F28)) -> 3.04 | H28: 45477 | I28: 46206 | J28: =MAX(0,(YEAR(I28)-YEAR(Assumptions!$B$74))*12+(MONTH(I28)-MONTH(Assumptions!$B$74))) -> 3 | K28: =IF(B28="Solar",Assumptions!$B$34,IF(B28="Wind",Assumptions!$B$35,IF(B28="WSH",Assumptions!$E$40,Assumptions!$E$41))) -> 0.4 | L28: =MAX(0,MIN(12,60)-MAX(0,$J28)) -> 9 | M28: =$E28*1000*8760*$K28*$G28*L28/12/10000000 -> 39.9456 | N28: =MAX(0,MIN(24,60)-MAX(12,$J28)) -> 12 | O28: =$E28*1000*8760*$K28*$G28*N28/12/10000000 -> 53.2608 | P28: =MAX(0,MIN(36,60)-MAX(24,$J28)) -> 12 | Q28: =$E28*1000*8760*$K28*$G28*P28/12/10000000 -> 53.2608 | R28: =MAX(0,MIN(48,60)-MAX(36,$J28)) -> 12 | S28: =$E28*1000*8760*$K28*$G28*R28/12/10000000 -> 53.2608 | T28: =MAX(0,MIN(60,60)-MAX(48,$J28)) -> 12 | U28: =$E28*1000*8760*$K28*$G28*T28/12/10000000 -> 53.2608
A29: UCC | B29: WSH | C29: Juniper Green Beta Pvt Ltd | D29: SECI | E29: 185 | F29: 3.21 | G29: =IF(D29="Merchant",Assumptions!$E$49,IF(AND(A29="Operational",OR(B29="WSH",B29="FDRE")),Assumptions!$B$37,F29)) -> 3.21 | H29: 45463 | I29: 46396 | J29: =MAX(0,(YEAR(I29)-YEAR(Assumptions!$B$74))*12+(MONTH(I29)-MONTH(Assumptions!$B$74))) -> 9 | K29: =IF(B29="Solar",Assumptions!$B$34,IF(B29="Wind",Assumptions!$B$35,IF(B29="WSH",Assumptions!$E$40,Assumptions!$E$41))) -> 0.4 | L29: =MAX(0,MIN(12,60)-MAX(0,$J29)) -> 3 | M29: =$E29*1000*8760*$K29*$G29*L29/12/10000000 -> 52.02126 | N29: =MAX(0,MIN(24,60)-MAX(12,$J29)) -> 12 | O29: =$E29*1000*8760*$K29*$G29*N29/12/10000000 -> 208.08504 | P29: =MAX(0,MIN(36,60)-MAX(24,$J29)) -> 12 | Q29: =$E29*1000*8760*$K29*$G29*P29/12/10000000 -> 208.08504 | R29: =MAX(0,MIN(48,60)-MAX(36,$J29)) -> 12 | S29: =$E29*1000*8760*$K29*$G29*R29/12/10000000 -> 208.08504 | T29: =MAX(0,MIN(60,60)-MAX(48,$J29)) -> 12 | U29: =$E29*1000*8760*$K29*$G29*T29/12/10000000 -> 208.08504
A30: UCC | B30: WSH | C30: Juniper Green Beta Pvt Ltd | D30: NTPC | E30: 238.1 | F30: 3.36 | G30: =IF(D30="Merchant",Assumptions!$E$49,IF(AND(A30="Operational",OR(B30="WSH",B30="FDRE")),Assumptions!$B$37,F30)) -> 3.36 | H30: 45472 | I30: 46201 | J30: =MAX(0,(YEAR(I30)-YEAR(Assumptions!$B$74))*12+(MONTH(I30)-MONTH(Assumptions!$B$74))) -> 2 | K30: =IF(B30="Solar",Assumptions!$B$34,IF(B30="Wind",Assumptions!$B$35,IF(B30="WSH",Assumptions!$E$40,Assumptions!$E$41))) -> 0.4 | L30: =MAX(0,MIN(12,60)-MAX(0,$J30)) -> 10 | M30: =$E30*1000*8760*$K30*$G30*L30/12/10000000 -> 233.60467 | N30: =MAX(0,MIN(24,60)-MAX(12,$J30)) -> 12 | O30: =$E30*1000*8760*$K30*$G30*N30/12/10000000 -> 280.32561 | P30: =MAX(0,MIN(36,60)-MAX(24,$J30)) -> 12 | Q30: =$E30*1000*8760*$K30*$G30*P30/12/10000000 -> 280.32561 | R30: =MAX(0,MIN(48,60)-MAX(36,$J30)) -> 12 | S30: =$E30*1000*8760*$K30*$G30*R30/12/10000000 -> 280.32561 | T30: =MAX(0,MIN(60,60)-MAX(48,$J30)) -> 12 | U30: =$E30*1000*8760*$K30*$G30*T30/12/10000000 -> 280.32561
A31: UCC | B31: WSH | C31: Juniper Green Power Five Pvt Ltd + Juniper Green ETA Five Pvt Ltd | D31: MSEDCL | E31: 127.8 | F31: 3.6 | G31: =IF(D31="Merchant",Assumptions!$E$49,IF(AND(A31="Operational",OR(B31="WSH",B31="FDRE")),Assumptions!$B$37,F31)) -> 3.6 | H31: 45614 | I31: 46343 | J31: =MAX(0,(YEAR(I31)-YEAR(Assumptions!$B$74))*12+(MONTH(I31)-MONTH(Assumptions!$B$74))) -> 7 | K31: =IF(B31="Solar",Assumptions!$B$34,IF(B31="Wind",Assumptions!$B$35,IF(B31="WSH",Assumptions!$E$40,Assumptions!$E$41))) -> 0.4 | L31: =MAX(0,MIN(12,60)-MAX(0,$J31)) -> 5 | M31: =$E31*1000*8760*$K31*$G31*L31/12/10000000 -> 67.17168 | N31: =MAX(0,MIN(24,60)-MAX(12,$J31)) -> 12 | O31: =$E31*1000*8760*$K31*$G31*N31/12/10000000 -> 161.21203 | P31: =MAX(0,MIN(36,60)-MAX(24,$J31)) -> 12 | Q31: =$E31*1000*8760*$K31*$G31*P31/12/10000000 -> 161.21203 | R31: =MAX(0,MIN(48,60)-MAX(36,$J31)) -> 12 | S31: =$E31*1000*8760*$K31*$G31*R31/12/10000000 -> 161.21203 | T31: =MAX(0,MIN(60,60)-MAX(48,$J31)) -> 12 | U31: =$E31*1000*8760*$K31*$G31*T31/12/10000000 -> 161.21203
A32: UCC | B32: WSH | C32: Juniper Green Spark Ten Pvt Ltd | D32: MSEDCL | E32: 25 | F32: 3.6 | G32: =IF(D32="Merchant",Assumptions!$E$49,IF(AND(A32="Operational",OR(B32="WSH",B32="FDRE")),Assumptions!$B$37,F32)) -> 3.6 | H32: 45614 | I32: 46343 | J32: =MAX(0,(YEAR(I32)-YEAR(Assumptions!$B$74))*12+(MONTH(I32)-MONTH(Assumptions!$B$74))) -> 7 | K32: =IF(B32="Solar",Assumptions!$B$34,IF(B32="Wind",Assumptions!$B$35,IF(B32="WSH",Assumptions!$E$40,Assumptions!$E$41))) -> 0.4 | L32: =MAX(0,MIN(12,60)-MAX(0,$J32)) -> 5 | M32: =$E32*1000*8760*$K32*$G32*L32/12/10000000 -> 13.14 | N32: =MAX(0,MIN(24,60)-MAX(12,$J32)) -> 12 | O32: =$E32*1000*8760*$K32*$G32*N32/12/10000000 -> 31.536 | P32: =MAX(0,MIN(36,60)-MAX(24,$J32)) -> 12 | Q32: =$E32*1000*8760*$K32*$G32*P32/12/10000000 -> 31.536 | R32: =MAX(0,MIN(48,60)-MAX(36,$J32)) -> 12 | S32: =$E32*1000*8760*$K32*$G32*R32/12/10000000 -> 31.536 | T32: =MAX(0,MIN(60,60)-MAX(48,$J32)) -> 12 | U32: =$E32*1000*8760*$K32*$G32*T32/12/10000000 -> 31.536
A33: UCC | B33: WSH | C33: Juniper Green Spark Four Pvt Ltd | D33: GUVNL | E33: 90 | F33: 3.3 | G33: =IF(D33="Merchant",Assumptions!$E$49,IF(AND(A33="Operational",OR(B33="WSH",B33="FDRE")),Assumptions!$B$37,F33)) -> 3.3 | H33: 45575 | I33: 46304 | J33: =MAX(0,(YEAR(I33)-YEAR(Assumptions!$B$74))*12+(MONTH(I33)-MONTH(Assumptions!$B$74))) -> 6 | K33: =IF(B33="Solar",Assumptions!$B$34,IF(B33="Wind",Assumptions!$B$35,IF(B33="WSH",Assumptions!$E$40,Assumptions!$E$41))) -> 0.4 | L33: =MAX(0,MIN(12,60)-MAX(0,$J33)) -> 6 | M33: =$E33*1000*8760*$K33*$G33*L33/12/10000000 -> 52.0344 | N33: =MAX(0,MIN(24,60)-MAX(12,$J33)) -> 12 | O33: =$E33*1000*8760*$K33*$G33*N33/12/10000000 -> 104.0688 | P33: =MAX(0,MIN(36,60)-MAX(24,$J33)) -> 12 | Q33: =$E33*1000*8760*$K33*$G33*P33/12/10000000 -> 104.0688 | R33: =MAX(0,MIN(48,60)-MAX(36,$J33)) -> 12 | S33: =$E33*1000*8760*$K33*$G33*R33/12/10000000 -> 104.0688 | T33: =MAX(0,MIN(60,60)-MAX(48,$J33)) -> 12 | U33: =$E33*1000*8760*$K33*$G33*T33/12/10000000 -> 104.0688
A34: UCC | B34: FDRE | C34: Juniper Green Stellar Pvt Ltd | D34: SJVN | E34: 209.7 | F34: 4.38 | G34: =IF(D34="Merchant",Assumptions!$E$49,IF(AND(A34="Operational",OR(B34="WSH",B34="FDRE")),Assumptions!$B$37,F34)) -> 4.38 | H34: 45412 | I34: 46356 | J34: =MAX(0,(YEAR(I34)-YEAR(Assumptions!$B$74))*12+(MONTH(I34)-MONTH(Assumptions!$B$74))) -> 7 | K34: =IF(B34="Solar",Assumptions!$B$34,IF(B34="Wind",Assumptions!$B$35,IF(B34="WSH",Assumptions!$E$40,Assumptions!$E$41))) -> 0.5 | L34: =MAX(0,MIN(12,60)-MAX(0,$J34)) -> 5 | M34: =$E34*1000*8760*$K34*$G34*L34/12/10000000 -> 167.62369 | N34: =MAX(0,MIN(24,60)-MAX(12,$J34)) -> 12 | O34: =$E34*1000*8760*$K34*$G34*N34/12/10000000 -> 402.29687 | P34: =MAX(0,MIN(36,60)-MAX(24,$J34)) -> 12 | Q34: =$E34*1000*8760*$K34*$G34*P34/12/10000000 -> 402.29687 | R34: =MAX(0,MIN(48,60)-MAX(36,$J34)) -> 12 | S34: =$E34*1000*8760*$K34*$G34*R34/12/10000000 -> 402.29687 | T34: =MAX(0,MIN(60,60)-MAX(48,$J34)) -> 12 | U34: =$E34*1000*8760*$K34*$G34*T34/12/10000000 -> 402.29687
A35: UCC | B35: FDRE | C35: Juniper Green Stellar Pvt Ltd | D35: SJVN | E35: 92.4 | F35: 4.38 | G35: =IF(D35="Merchant",Assumptions!$E$49,IF(AND(A35="Operational",OR(B35="WSH",B35="FDRE")),Assumptions!$B$37,F35)) -> 4.38 | H35: 45412 | I35: 46356 | J35: =MAX(0,(YEAR(I35)-YEAR(Assumptions!$B$74))*12+(MONTH(I35)-MONTH(Assumptions!$B$74))) -> 7 | K35: =IF(B35="Solar",Assumptions!$B$34,IF(B35="Wind",Assumptions!$B$35,IF(B35="WSH",Assumptions!$E$40,Assumptions!$E$41))) -> 0.5 | L35: =MAX(0,MIN(12,60)-MAX(0,$J35)) -> 5 | M35: =$E35*1000*8760*$K35*$G35*L35/12/10000000 -> 73.85994 | N35: =MAX(0,MIN(24,60)-MAX(12,$J35)) -> 12 | O35: =$E35*1000*8760*$K35*$G35*N35/12/10000000 -> 177.26386 | P35: =MAX(0,MIN(36,60)-MAX(24,$J35)) -> 12 | Q35: =$E35*1000*8760*$K35*$G35*P35/12/10000000 -> 177.26386 | R35: =MAX(0,MIN(48,60)-MAX(36,$J35)) -> 12 | S35: =$E35*1000*8760*$K35*$G35*R35/12/10000000 -> 177.26386 | T35: =MAX(0,MIN(60,60)-MAX(48,$J35)) -> 12 | U35: =$E35*1000*8760*$K35*$G35*T35/12/10000000 -> 177.26386
... A40: UCC | B40: FDRE | C40: Juniper Green Sigma Eight Pvt Ltd | D40: TPCL | E40: 140 | F40: 4.76 | G40: =IF(D40="Merchant",Assumptions!$E$49,IF(AND(A40="Operational",OR(B40="WSH",B40="FDRE")),Assumptions!$B$37,F40)) -> 4.76 | H40: 45923 | I40: 46676 | J40: =MAX(0,(YEAR(I40)-YEAR(Assumptions!$B$74))*12+(MONTH(I40)-MONTH(Assumptions!$B$74))) -> 18 | K40: =IF(B40="Solar",Assumptions!$B$34,IF(B40="Wind",Assumptions!$B$35,IF(B40="WSH",Assumptions!$E$40,Assumptions!$E$41))) -> 0.5 | L40: =MAX(0,MIN(12,60)-MAX(0,$J40)) -> 0 | M40: =$E40*1000*8760*$K40*$G40*L40/12/10000000 -> 0 | N40: =MAX(0,MIN(24,60)-MAX(12,$J40)) -> 6 | O40: =$E40*1000*8760*$K40*$G40*N40/12/10000000 -> 145.9416 | P40: =MAX(0,MIN(36,60)-MAX(24,$J40)) -> 12 | Q40: =$E40*1000*8760*$K40*$G40*P40/12/10000000 -> 291.8832 | R40: =MAX(0,MIN(48,60)-MAX(36,$J40)) -> 12 | S40: =$E40*1000*8760*$K40*$G40*R40/12/10000000 -> 291.8832 | T40: =MAX(0,MIN(60,60)-MAX(48,$J40)) -> 12 | U40: =$E40*1000*8760*$K40*$G40*T40/12/10000000 -> 291.8832
A41: UCA | B41: WSH | C41: Juniper Green Beam Six Pvt Ltd | D41: SECI | E41: 180 | F41: 3.25 | G41: =IF(D41="Merchant",Assumptions!$E$49,IF(AND(A41="Operational",OR(B41="WSH",B41="FDRE")),Assumptions!$B$37,F41)) -> 3.25 | H41: 45580 | I41: =EDATE(H41,ROUND(Assumptions!$E$44,0)) -> 47041 | J41: =MAX(0,(YEAR(I41)-YEAR(Assumptions!$B$74))*12+(MONTH(I41)-MONTH(Assumptions!$B$74))) -> 30 | K41: =IF(B41="Solar",Assumptions!$B$34,IF(B41="Wind",Assumptions!$B$35,IF(B41="WSH",Assumptions!$E$40,Assumptions!$E$41))) -> 0.4 | L41: =MAX(0,MIN(12,60)-MAX(0,$J41)) -> 0 | M41: =$E41*1000*8760*$K41*$G41*L41/12/10000000 -> 0 | N41: =MAX(0,MIN(24,60)-MAX(12,$J41)) -> 0 | O41: =$E41*1000*8760*$K41*$G41*N41/12/10000000 -> 0 | P41: =MAX(0,MIN(36,60)-MAX(24,$J41)) -> 6 | Q41: =$E41*1000*8760*$K41*$G41*P41/12/10000000 -> 102.492 | R41: =MAX(0,MIN(48,60)-MAX(36,$J41)) -> 12 | S41: =$E41*1000*8760*$K41*$G41*R41/12/10000000 -> 204.984 | T41: =MAX(0,MIN(60,60)-MAX(48,$J41)) -> 12 | U41: =$E41*1000*8760*$K41*$G41*T41/12/10000000 -> 204.984
A42: UCA | B42: WSH | C42: Juniper Green Light Four Pvt Ltd | D42: SJVN | E42: 180 | F42: 3.43 | G42: =IF(D42="Merchant",Assumptions!$E$49,IF(AND(A42="Operational",OR(B42="WSH",B42="FDRE")),Assumptions!$B$37,F42)) -> 3.43 | H42: 45357 | I42: =EDATE(H42,ROUND(Assumptions!$E$44,0)) -> 46818 | J42: =MAX(0,(YEAR(I42)-YEAR(Assumptions!$B$74))*12+(MONTH(I42)-MONTH(Assumptions!$B$74))) -> 23 | K42: =IF(B42="Solar",Assumptions!$B$34,IF(B42="Wind",Assumptions!$B$35,IF(B42="WSH",Assumptions!$E$40,Assumptions!$E$41))) -> 0.4 | L42: =MAX(0,MIN(12,60)-MAX(0,$J42)) -> 0 | M42: =$E42*1000*8760*$K42*$G42*L42/12/10000000 -> 0 | N42: =MAX(0,MIN(24,60)-MAX(12,$J42)) -> 1 | O42: =$E42*1000*8760*$K42*$G42*N42/12/10000000 -> 18.02808 | P42: =MAX(0,MIN(36,60)-MAX(24,$J42)) -> 12 | Q42: =$E42*1000*8760*$K42*$G42*P42/12/10000000 -> 216.33696 | R42: =MAX(0,MIN(48,60)-MAX(36,$J42)) -> 12 | S42: =$E42*1000*8760*$K42*$G42*R42/12/10000000 -> 216.33696 | T42: =MAX(0,MIN(60,60)-MAX(48,$J42)) -> 12 | U42: =$E42*1000*8760*$K42*$G42*T42/12/10000000 -> 216.33696
A43: UCA | B43: WSH | C43: Juniper Green Alpha Three Pvt Ltd | D43: SJVN | E43: 360 | F43: 3.19 | G43: =IF(D43="Merchant",Assumptions!$E$49,IF(AND(A43="Operational",OR(B43="WSH",B43="FDRE")),Assumptions!$B$37,F43)) -> 3.19 | H43: 45630 | I43: =EDATE(H43,ROUND(Assumptions!$E$44,0)) -> 47091 | J43: =MAX(0,(YEAR(I43)-YEAR(Assumptions!$B$74))*12+(MONTH(I43)-MONTH(Assumptions!$B$74))) -> 32 | K43: =IF(B43="Solar",Assumptions!$B$34,IF(B43="Wind",Assumptions!$B$35,IF(B43="WSH",Assumptions!$E$40,Assumptions!$E$41))) -> 0.4 | L43: =MAX(0,MIN(12,60)-MAX(0,$J43)) -> 0 | M43: =$E43*1000*8760*$K43*$G43*L43/12/10000000 -> 0 | N43: =MAX(0,MIN(24,60)-MAX(12,$J43)) -> 0 | O43: =$E43*1000*8760*$K43*$G43*N43/12/10000000 -> 0 | P43: =MAX(0,MIN(36,60)-MAX(24,$J43)) -> 4 | Q43: =$E43*1000*8760*$K43*$G43*P43/12/10000000 -> 134.13312 | R43: =MAX(0,MIN(48,60)-MAX(36,$J43)) -> 12 | S43: =$E43*1000*8760*$K43*$G43*R43/12/10000000 -> 402.39936 | T43: =MAX(0,MIN(60,60)-MAX(48,$J43)) -> 12 | U43: =$E43*1000*8760*$K43*$G43*T43/12/10000000 -> 402.39936
A44: UCA | B44: WSH | C44: Juniper Green Energy Ltd | D44: NTPC | E44: 360 | F44: 3.29 | G44: =IF(D44="Merchant",Assumptions!$E$49,IF(AND(A44="Operational",OR(B44="WSH",B44="FDRE")),Assumptions!$B$37,F44)) -> 3.29 | H44: 45405 | I44: =EDATE(H44,ROUND(Assumptions!$E$44,0)) -> 46866 | J44: =MAX(0,(YEAR(I44)-YEAR(Assumptions!$B$74))*12+(MONTH(I44)-MONTH(Assumptions!$B$74))) -> 24 | K44: =IF(B44="Solar",Assumptions!$B$34,IF(B44="Wind",Assumptions!$B$35,IF(B44="WSH",Assumptions!$E$40,Assumptions!$E$41))) -> 0.4 | L44: =MAX(0,MIN(12,60)-MAX(0,$J44)) -> 0 | M44: =$E44*1000*8760*$K44*$G44*L44/12/10000000 -> 0 | N44: =MAX(0,MIN(24,60)-MAX(12,$J44)) -> 0 | O44: =$E44*1000*8760*$K44*$G44*N44/12/10000000 -> 0 | P44: =MAX(0,MIN(36,60)-MAX(24,$J44)) -> 12 | Q44: =$E44*1000*8760*$K44*$G44*P44/12/10000000 -> 415.01376 | R44: =MAX(0,MIN(48,60)-MAX(36,$J44)) -> 12 | S44: =$E44*1000*8760*$K44*$G44*R44/12/10000000 -> 415.01376 | T44: =MAX(0,MIN(60,60)-MAX(48,$J44)) -> 12 | U44: =$E44*1000*8760*$K44*$G44*T44/12/10000000 -> 415.01376
A45: UCA | B45: WSH | C45: Juniper Green Gem Pvt Ltd | D45: NHPC | E45: 180 | F45: 3.48 | G45: =IF(D45="Merchant",Assumptions!$E$49,IF(AND(A45="Operational",OR(B45="WSH",B45="FDRE")),Assumptions!$B$37,F45)) -> 3.48 | H45: 45341 | I45: =EDATE(H45,ROUND(Assumptions!$E$44,0)) -> 46802 | J45: =MAX(0,(YEAR(I45)-YEAR(Assumptions!$B$74))*12+(MONTH(I45)-MONTH(Assumptions!$B$74))) -> 22 | K45: =IF(B45="Solar",Assumptions!$B$34,IF(B45="Wind",Assumptions!$B$35,IF(B45="WSH",Assumptions!$E$40,Assumptions!$E$41))) -> 0.4 | L45: =MAX(0,MIN(12,60)-MAX(0,$J45)) -> 0 | M45: =$E45*1000*8760*$K45*$G45*L45/12/10000000 -> 0 | N45: =MAX(0,MIN(24,60)-MAX(12,$J45)) -> 2 | O45: =$E45*1000*8760*$K45*$G45*N45/12/10000000 -> 36.58176 | P45: =MAX(0,MIN(36,60)-MAX(24,$J45)) -> 12 | Q45: =$E45*1000*8760*$K45*$G45*P45/12/10000000 -> 219.49056 | R45: =MAX(0,MIN(48,60)-MAX(36,$J45)) -> 12 | S45: =$E45*1000*8760*$K45*$G45*R45/12/10000000 -> 219.49056 | T45: =MAX(0,MIN(60,60)-MAX(48,$J45)) -> 12 | U45: =$E45*1000*8760*$K45*$G45*T45/12/10000000 -> 219.49056
...

Sheet Capex Model
A1: CAPEX MODEL — SPV LEVEL PHASING (UCC & UCA only; Operational projects require no further capex)
A2: Cash capex spread evenly over construction window (Start->COD). Capitalisation to Gross Block occurs as a lump sum in the FY that COD falls in (CWIP->PPE transfer convention). Rs crore.
A4: Category | B4: Tech | C4: Entity | D4: Planned AC MW | E4: Rs cr/MW | F4: Total Project Cost | G4: Start Date | H4: COD | I4: Start Mth Idx | J4: COD Mth Idx | K4: Constr. Months | L4: FY27 Capex (cash) | M4: FY28 Capex (cash) | N4: FY29 Capex (cash) | O4: FY30 Capex (cash) | P4: FY31 Capex (cash) | Q4: Capitalised in FY | R4: Cash Spend Base (Rs cr)
A5: UCC | B5: Solar | C5: Juniper Green Beta Pvt Ltd | D5: 20 | E5: =Assumptions!$B$52 -> 8.6126981 | F5: =D5*E5 -> 172.25396 | G5: 45292 | H5: ='Revenue Model'!I23 -> 46192 | I5: =MAX(0,(YEAR(G5)-YEAR(Assumptions!$B$74))*12+(MONTH(G5)-MONTH(Assumptions!$B$74))) -> 0 | J5: ='Revenue Model'!J23 -> 2 | K5: =MAX(1,MAX($J5,$I5+1)-$I5) -> 2 | L5: =MAX(0,MIN(12,MAX($J5,$I5+1))-MAX(0,$I5))/$K5*$R5 -> 62.56847 | M5: =MAX(0,MIN(24,MAX($J5,$I5+1))-MAX(12,$I5))/$K5*$R5 -> 0 | N5: =MAX(0,MIN(36,MAX($J5,$I5+1))-MAX(24,$I5))/$K5*$R5 -> 0 | O5: =MAX(0,MIN(48,MAX($J5,$I5+1))-MAX(36,$I5))/$K5*$R5 -> 0 | P5: =MAX(0,MIN(60,MAX($J5,$I5+1))-MAX(48,$I5))/$K5*$R5 -> 0 | Q5: =IF(AND($J5>=0,$J5<12),"FY27",IF($J5<24,"FY28",IF($J5<36,"FY29",IF($J5<48,"FY30",IF($J5<60,"FY31","Beyond"))))) -> FY27 | R5: =IF(A5="UCC",F5*Assumptions!$B$54,F5) -> 62.56847
A6: UCC | B6: Wind | C6: Juniper Green Kite Pvt Ltd | D6: 70 | E6: =Assumptions!$B$52 -> 8.6126981 | F6: =D6*E6 -> 602.88886 | G6: 45463 | H6: ='Revenue Model'!I24 -> 46192 | I6: =MAX(0,(YEAR(G6)-YEAR(Assumptions!$B$74))*12+(MONTH(G6)-MONTH(Assumptions!$B$74))) -> 0 | J6: ='Revenue Model'!J24 -> 2 | K6: =MAX(1,MAX($J6,$I6+1)-$I6) -> 2 | L6: =MAX(0,MIN(12,MAX($J6,$I6+1))-MAX(0,$I6))/$K6*$R6 -> 218.98965 | M6: =MAX(0,MIN(24,MAX($J6,$I6+1))-MAX(12,$I6))/$K6*$R6 -> 0 | N6: =MAX(0,MIN(36,MAX($J6,$I6+1))-MAX(24,$I6))/$K6*$R6 -> 0 | O6: =MAX(0,MIN(48,MAX($J6,$I6+1))-MAX(36,$I6))/$K6*$R6 -> 0 | P6: =MAX(0,MIN(60,MAX($J6,$I6+1))-MAX(48,$I6))/$K6*$R6 -> 0 | Q6: =IF(AND($J6>=0,$J6<12),"FY27",IF($J6<24,"FY28",IF($J6<36,"FY29",IF($J6<48,"FY30",IF($J6<60,"FY31","Beyond"))))) -> FY27 | R6: =IF(A6="UCC",F6*Assumptions!$B$54,F6) -> 218.98965
A7: UCC | B7: Wind | C7: Juniper Green Bess Two Pvt Ltd | D7: 100 | E7: =Assumptions!$B$52 -> 8.6126981 | F7: =D7*E7 -> 861.26981 | G7: 45856 | H7: ='Revenue Model'!I25 -> 46585 | I7: =MAX(0,(YEAR(G7)-YEAR(Assumptions!$B$74))*12+(MONTH(G7)-MONTH(Assumptions!$B$74))) -> 0 | J7: ='Revenue Model'!J25 -> 15 | K7: =MAX(1,MAX($J7,$I7+1)-$I7) -> 15 | L7: =MAX(0,MIN(12,MAX($J7,$I7+1))-MAX(0,$I7))/$K7*$R7 -> 250.27388 | M7: =MAX(0,MIN(24,MAX($J7,$I7+1))-MAX(12,$I7))/$K7*$R7 -> 62.56847 | N7: =MAX(0,MIN(36,MAX($J7,$I7+1))-MAX(24,$I7))/$K7*$R7 -> 0 | O7: =MAX(0,MIN(48,MAX($J7,$I7+1))-MAX(36,$I7))/$K7*$R7 -> 0 | P7: =MAX(0,MIN(60,MAX($J7,$I7+1))-MAX(48,$I7))/$K7*$R7 -> 0 | Q7: =IF(AND($J7>=0,$J7<12),"FY27",IF($J7<24,"FY28",IF($J7<36,"FY29",IF($J7<48,"FY30",IF($J7<60,"FY31","Beyond"))))) -> FY28 | R7: =IF(A7="UCC",F7*Assumptions!$B$54,F7) -> 312.84235
A8: UCC | B8: Wind | C8: Juniper Green Bess Delta Pvt Ltd | D8: 50 | E8: =Assumptions!$B$52 -> 8.6126981 | F8: =D8*E8 -> 430.6349 | G8: 45852 | H8: ='Revenue Model'!I26 -> 46697 | I8: =MAX(0,(YEAR(G8)-YEAR(Assumptions!$B$74))*12+(MONTH(G8)-MONTH(Assumptions!$B$74))) -> 0 | J8: ='Revenue Model'!J26 -> 19 | K8: =MAX(1,MAX($J8,$I8+1)-$I8) -> 19 | L8: =MAX(0,MIN(12,MAX($J8,$I8+1))-MAX(0,$I8))/$K8*$R8 -> 98.792322 | M8: =MAX(0,MIN(24,MAX($J8,$I8+1))-MAX(12,$I8))/$K8*$R8 -> 57.628854 | N8: =MAX(0,MIN(36,MAX($J8,$I8+1))-MAX(24,$I8))/$K8*$R8 -> 0 | O8: =MAX(0,MIN(48,MAX($J8,$I8+1))-MAX(36,$I8))/$K8*$R8 -> 0 | P8: =MAX(0,MIN(60,MAX($J8,$I8+1))-MAX(48,$I8))/$K8*$R8 -> 0 | Q8: =IF(AND($J8>=0,$J8<12),"FY27",IF($J8<24,"FY28",IF($J8<36,"FY29",IF($J8<48,"FY30",IF($J8<60,"FY31","Beyond"))))) -> FY28 | R8: =IF(A8="UCC",F8*Assumptions!$B$54,F8) -> 156.42118
A9: UCC | B9: WSH | C9: Juniper Green Beam Eight Pvt Ltd | D9: 75 | E9: =Assumptions!$B$52 -> 8.6126981 | F9: =D9*E9 -> 645.95235 | G9: 45380 | H9: ='Revenue Model'!I27 -> 46134 | I9: =MAX(0,(YEAR(G9)-YEAR(Assumptions!$B$74))*12+(MONTH(G9)-MONTH(Assumptions!$B$74))) -> 0 | J9: ='Revenue Model'!J27 -> 0 | K9: =MAX(1,MAX($J9,$I9+1)-$I9) -> 1 | L9: =MAX(0,MIN(12,MAX($J9,$I9+1))-MAX(0,$I9))/$K9*$R9 -> 234.63176 | M9: =MAX(0,MIN(24,MAX($J9,$I9+1))-MAX(12,$I9))/$K9*$R9 -> 0 | N9: =MAX(0,MIN(36,MAX($J9,$I9+1))-MAX(24,$I9))/$K9*$R9 -> 0 | O9: =MAX(0,MIN(48,MAX($J9,$I9+1))-MAX(36,$I9))/$K9*$R9 -> 0 | P9: =MAX(0,MIN(60,MAX($J9,$I9+1))-MAX(48,$I9))/$K9*$R9 -> 0 | Q9: =IF(AND($J9>=0,$J9<12),"FY27",IF($J9<24,"FY28",IF($J9<36,"FY29",IF($J9<48,"FY30",IF($J9<60,"FY31","Beyond"))))) -> FY27 | R9: =IF(A9="UCC",F9*Assumptions!$B$54,F9) -> 234.63176
A10: UCC | B10: WSH | C10: Juniper Green Energy Ltd | D10: 50 | E10: =Assumptions!$B$52 -> 8.6126981 | F10: =D10*E10 -> 430.6349 | G10: 45477 | H10: ='Revenue Model'!I28 -> 46206 | I10: =MAX(0,(YEAR(G10)-YEAR(Assumptions!$B$74))*12+(MONTH(G10)-MONTH(Assumptions!$B$74))) -> 0 | J10: ='Revenue Model'!J28 -> 3 | K10: =MAX(1,MAX($J10,$I10+1)-$I10) -> 3 | L10: =MAX(0,MIN(12,MAX($J10,$I10+1))-MAX(0,$I10))/$K10*$R10 -> 156.42118 | M10: =MAX(0,MIN(24,MAX($J10,$I10+1))-MAX(12,$I10))/$K10*$R10 -> 0 | N10: =MAX(0,MIN(36,MAX($J10,$I10+1))-MAX(24,$I10))/$K10*$R10 -> 0 | O10: =MAX(0,MIN(48,MAX($J10,$I10+1))-MAX(36,$I10))/$K10*$R10 -> 0 | P10: =MAX(0,MIN(60,MAX($J10,$I10+1))-MAX(48,$I10))/$K10*$R10 -> 0 | Q10: =IF(AND($J10>=0,$J10<12),"FY27",IF($J10<24,"FY28",IF($J10<36,"FY29",IF($J10<48,"FY30",IF($J10<60,"FY31","Beyond"))))) -> FY27 | R10: =IF(A10="UCC",F10*Assumptions!$B$54,F10) -> 156.42118
A11: UCC | B11: WSH | C11: Juniper Green Beta Pvt Ltd | D11: 185 | E11: =Assumptions!$B$52 -> 8.6126981 | F11: =D11*E11 -> 1593.3491 | G11: 45463 | H11: ='Revenue Model'!I29 -> 46396 | I11: =MAX(0,(YEAR(G11)-YEAR(Assumptions!$B$74))*12+(MONTH(G11)-MONTH(Assumptions!$B$74))) -> 0 | J11: ='Revenue Model'!J29 -> 9 | K11: =MAX(1,MAX($J11,$I11+1)-$I11) -> 9 | L11: =MAX(0,MIN(12,MAX($J11,$I11+1))-MAX(0,$I11))/$K11*$R11 -> 578.75835 | M11: =MAX(0,MIN(24,MAX($J11,$I11+1))-MAX(12,$I11))/$K11*$R11 -> 0 | N11: =MAX(0,MIN(36,MAX($J11,$I11+1))-MAX(24,$I11))/$K11*$R11 -> 0 | O11: =MAX(0,MIN(48,MAX($J11,$I11+1))-MAX(36,$I11))/$K11*$R11 -> 0 | P11: =MAX(0,MIN(60,MAX($J11,$I11+1))-MAX(48,$I11))/$K11*$R11 -> 0 | Q11: =IF(AND($J11>=0,$J11<12),"FY27",IF($J11<24,"FY28",IF($J11<36,"FY29",IF($J11<48,"FY30",IF($J11<60,"FY31","Beyond"))))) -> FY27 | R11: =IF(A11="UCC",F11*Assumptions!$B$54,F11) -> 578.75835
A12: UCC | B12: WSH | C12: Juniper Green Beta Pvt Ltd | D12: 238.1 | E12: =Assumptions!$B$52 -> 8.6126981 | F12: =D12*E12 -> 2050.6834 | G12: 45472 | H12: ='Revenue Model'!I30 -> 46201 | I12: =MAX(0,(YEAR(G12)-YEAR(Assumptions!$B$74))*12+(MONTH(G12)-MONTH(Assumptions!$B$74))) -> 0 | J12: ='Revenue Model'!J30 -> 2 | K12: =MAX(1,MAX($J12,$I12+1)-$I12) -> 2 | L12: =MAX(0,MIN(12,MAX($J12,$I12+1))-MAX(0,$I12))/$K12*$R12 -> 744.87764 | M12: =MAX(0,MIN(24,MAX($J12,$I12+1))-MAX(12,$I12))/$K12*$R12 -> 0 | N12: =MAX(0,MIN(36,MAX($J12,$I12+1))-MAX(24,$I12))/$K12*$R12 -> 0 | O12: =MAX(0,MIN(48,MAX($J12,$I12+1))-MAX(36,$I12))/$K12*$R12 -> 0 | P12: =MAX(0,MIN(60,MAX($J12,$I12+1))-MAX(48,$I12))/$K12*$R12 -> 0 | Q12: =IF(AND($J12>=0,$J12<12),"FY27",IF($J12<24,"FY28",IF($J12<36,"FY29",IF($J12<48,"FY30",IF($J12<60,"FY31","Beyond"))))) -> FY27 | R12: =IF(A12="UCC",F12*Assumptions!$B$54,F12) -> 744.87764
A13: UCC | B13: WSH | C13: Juniper Green Power Five Pvt Ltd + Juniper Green ETA Five Pvt Ltd | D13: 127.8 | E13: =Assumptions!$B$52 -> 8.6126981 | F13: =D13*E13 -> 1100.7028 | G13: 45614 | H13: ='Revenue Model'!I31 -> 46343 | I13: =MAX(0,(YEAR(G13)-YEAR(Assumptions!$B$74))*12+(MONTH(G13)-MONTH(Assumptions!$B$74))) -> 0 | J13: ='Revenue Model'!J31 -> 7 | K13: =MAX(1,MAX($J13,$I13+1)-$I13) -> 7 | L13: =MAX(0,MIN(12,MAX($J13,$I13+1))-MAX(0,$I13))/$K13*$R13 -> 399.81253 | M13: =MAX(0,MIN(24,MAX($J13,$I13+1))-MAX(12,$I13))/$K13*$R13 -> 0 | N13: =MAX(0,MIN(36,MAX($J13,$I13+1))-MAX(24,$I13))/$K13*$R13 -> 0 | O13: =MAX(0,MIN(48,MAX($J13,$I13+1))-MAX(36,$I13))/$K13*$R13 -> 0 | P13: =MAX(0,MIN(60,MAX($J13,$I13+1))-MAX(48,$I13))/$K13*$R13 -> 0 | Q13: =IF(AND($J13>=0,$J13<12),"FY27",IF($J13<24,"FY28",IF($J13<36,"FY29",IF($J13<48,"FY30",IF($J13<60,"FY31","Beyond"))))) -> FY27 | R13: =IF(A13="UCC",F13*Assumptions!$B$54,F13) -> 399.81253
A14: UCC | B14: WSH | C14: Juniper Green Spark Ten Pvt Ltd | D14: 25 | E14: =Assumptions!$B$52 -> 8.6126981 | F14: =D14*E14 -> 215.31745 | G14: 45614 | H14: ='Revenue Model'!I32 -> 46343 | I14: =MAX(0,(YEAR(G14)-YEAR(Assumptions!$B$74))*12+(MONTH(G14)-MONTH(Assumptions!$B$74))) -> 0 | J14: ='Revenue Model'!J32 -> 7 | K14: =MAX(1,MAX($J14,$I14+1)-$I14) -> 7 | L14: =MAX(0,MIN(12,MAX($J14,$I14+1))-MAX(0,$I14))/$K14*$R14 -> 78.210588 | M14: =MAX(0,MIN(24,MAX($J14,$I14+1))-MAX(12,$I14))/$K14*$R14 -> 0 | N14: =MAX(0,MIN(36,MAX($J14,$I14+1))-MAX(24,$I14))/$K14*$R14 -> 0 | O14: =MAX(0,MIN(48,MAX($J14,$I14+1))-MAX(36,$I14))/$K14*$R14 -> 0 | P14: =MAX(0,MIN(60,MAX($J14,$I14+1))-MAX(48,$I14))/$K14*$R14 -> 0 | Q14: =IF(AND($J14>=0,$J14<12),"FY27",IF($J14<24,"FY28",IF($J14<36,"FY29",IF($J14<48,"FY30",IF($J14<60,"FY31","Beyond"))))) -> FY27 | R14: =IF(A14="UCC",F14*Assumptions!$B$54,F14) -> 78.210588
A15: UCC | B15: WSH | C15: Juniper Green Spark Four Pvt Ltd | D15: 90 | E15: =Assumptions!$B$52 -> 8.6126981 | F15: =D15*E15 -> 775.14283 | G15: 45575 | H15: ='Revenue Model'!I33 -> 46304 | I15: =MAX(0,(YEAR(G15)-YEAR(Assumptions!$B$74))*12+(MONTH(G15)-MONTH(Assumptions!$B$74))) -> 0 | J15: ='Revenue Model'!J33 -> 6 | K15: =MAX(1,MAX($J15,$I15+1)-$I15) -> 6 | L15: =MAX(0,MIN(12,MAX($J15,$I15+1))-MAX(0,$I15))/$K15*$R15 -> 281.55812 | M15: =MAX(0,MIN(24,MAX($J15,$I15+1))-MAX(12,$I15))/$K15*$R15 -> 0 | N15: =MAX(0,MIN(36,MAX($J15,$I15+1))-MAX(24,$I15))/$K15*$R15 -> 0 | O15: =MAX(0,MIN(48,MAX($J15,$I15+1))-MAX(36,$I15))/$K15*$R15 -> 0 | P15: =MAX(0,MIN(60,MAX($J15,$I15+1))-MAX(48,$I15))/$K15*$R15 -> 0 | Q15: =IF(AND($J15>=0,$J15<12),"FY27",IF($J15<24,"FY28",IF($J15<36,"FY29",IF($J15<48,"FY30",IF($J15<60,"FY31","Beyond"))))) -> FY27 | R15: =IF(A15="UCC",F15*Assumptions!$B$54,F15) -> 281.55812
A16: UCC | B16: FDRE | C16: Juniper Green Stellar Pvt Ltd | D16: 209.7 | E16: =Assumptions!$B$52 -> 8.6126981 | F16: =D16*E16 -> 1806.0828 | G16: 45412 | H16: ='Revenue Model'!I34 -> 46356 | I16: =MAX(0,(YEAR(G16)-YEAR(Assumptions!$B$74))*12+(MONTH(G16)-MONTH(Assumptions!$B$74))) -> 0 | J16: ='Revenue Model'!J34 -> 7 | K16: =MAX(1,MAX($J16,$I16+1)-$I16) -> 7 | L16: =MAX(0,MIN(12,MAX($J16,$I16+1))-MAX(0,$I16))/$K16*$R16 -> 656.03041 | M16: =MAX(0,MIN(24,MAX($J16,$I16+1))-MAX(12,$I16))/$K16*$R16 -> 0 | N16: =MAX(0,MIN(36,MAX($J16,$I16+1))-MAX(24,$I16))/$K16*$R16 -> 0 | O16: =MAX(0,MIN(48,MAX($J16,$I16+1))-MAX(36,$I16))/$K16*$R16 -> 0 | P16: =MAX(0,MIN(60,MAX($J16,$I16+1))-MAX(48,$I16))/$K16*$R16 -> 0 | Q16: =IF(AND($J16>=0,$J16<12),"FY27",IF($J16<24,"FY28",IF($J16<36,"FY29",IF($J16<48,"FY30",IF($J16<60,"FY31","Beyond"))))) -> FY27 | R16: =IF(A16="UCC",F16*Assumptions!$B$54,F16) -> 656.03041
... A22: UCC | B22: FDRE | C22: Juniper Green Sigma Eight Pvt Ltd | D22: 140 | E22: =Assumptions!$B$52 -> 8.6126981 | F22: =D22*E22 -> 1205.7777 | G22: 45923 | H22: ='Revenue Model'!I40 -> 46676 | I22: =MAX(0,(YEAR(G22)-YEAR(Assumptions!$B$74))*12+(MONTH(G22)-MONTH(Assumptions!$B$74))) -> 0 | J22: ='Revenue Model'!J40 -> 18 | K22: =MAX(1,MAX($J22,$I22+1)-$I22) -> 18 | L22: =MAX(0,MIN(12,MAX($J22,$I22+1))-MAX(0,$I22))/$K22*$R22 -> 291.9862 | M22: =MAX(0,MIN(24,MAX($J22,$I22+1))-MAX(12,$I22))/$K22*$R22 -> 145.9931 | N22: =MAX(0,MIN(36,MAX($J22,$I22+1))-MAX(24,$I22))/$K22*$R22 -> 0 | O22: =MAX(0,MIN(48,MAX($J22,$I22+1))-MAX(36,$I22))/$K22*$R22 -> 0 | P22: =MAX(0,MIN(60,MAX($J22,$I22+1))-MAX(48,$I22))/$K22*$R22 -> 0 | Q22: =IF(AND($J22>=0,$J22<12),"FY27",IF($J22<24,"FY28",IF($J22<36,"FY29",IF($J22<48,"FY30",IF($J22<60,"FY31","Beyond"))))) -> FY28 | R22: =IF(A22="UCC",F22*Assumptions!$B$54,F22) -> 437.97929
A23: UCA | B23: WSH | C23: Juniper Green Beam Six Pvt Ltd | D23: 180 | E23: =Assumptions!$B$53 -> 5.8797426 | F23: =D23*E23 -> 1058.3537 | G23: 45580 | H23: ='Revenue Model'!I41 -> 47041 | I23: =MAX(0,(YEAR(G23)-YEAR(Assumptions!$B$74))*12+(MONTH(G23)-MONTH(Assumptions!$B$74))) -> 0 | J23: ='Revenue Model'!J41 -> 30 | K23: =MAX(1,MAX($J23,$I23+1)-$I23) -> 30 | L23: =MAX(0,MIN(12,MAX($J23,$I23+1))-MAX(0,$I23))/$K23*$R23 -> 423.34147 | M23: =MAX(0,MIN(24,MAX($J23,$I23+1))-MAX(12,$I23))/$K23*$R23 -> 423.34147 | N23: =MAX(0,MIN(36,MAX($J23,$I23+1))-MAX(24,$I23))/$K23*$R23 -> 211.67073 | O23: =MAX(0,MIN(48,MAX($J23,$I23+1))-MAX(36,$I23))/$K23*$R23 -> 0 | P23: =MAX(0,MIN(60,MAX($J23,$I23+1))-MAX(48,$I23))/$K23*$R23 -> 0 | Q23: =IF(AND($J23>=0,$J23<12),"FY27",IF($J23<24,"FY28",IF($J23<36,"FY29",IF($J23<48,"FY30",IF($J23<60,"FY31","Beyond"))))) -> FY29 | R23: =IF(A23="UCC",F23*Assumptions!$B$54,F23) -> 1058.3537
A24: UCA | B24: WSH | C24: Juniper Green Light Four Pvt Ltd | D24: 180 | E24: =Assumptions!$B$53 -> 5.8797426 | F24: =D24*E24 -> 1058.3537 | G24: 45357 | H24: ='Revenue Model'!I42 -> 46818 | I24: =MAX(0,(YEAR(G24)-YEAR(Assumptions!$B$74))*12+(MONTH(G24)-MONTH(Assumptions!$B$74))) -> 0 | J24: ='Revenue Model'!J42 -> 23 | K24: =MAX(1,MAX($J24,$I24+1)-$I24) -> 23 | L24: =MAX(0,MIN(12,MAX($J24,$I24+1))-MAX(0,$I24))/$K24*$R24 -> 552.18452 | M24: =MAX(0,MIN(24,MAX($J24,$I24+1))-MAX(12,$I24))/$K24*$R24 -> 506.16914 | N24: =MAX(0,MIN(36,MAX($J24,$I24+1))-MAX(24,$I24))/$K24*$R24 -> 0 | O24: =MAX(0,MIN(48,MAX($J24,$I24+1))-MAX(36,$I24))/$K24*$R24 -> 0 | P24: =MAX(0,MIN(60,MAX($J24,$I24+1))-MAX(48,$I24))/$K24*$R24 -> 0 | Q24: =IF(AND($J24>=0,$J24<12),"FY27",IF($J24<24,"FY28",IF($J24<36,"FY29",IF($J24<48,"FY30",IF($J24<60,"FY31","Beyond"))))) -> FY28 | R24: =IF(A24="UCC",F24*Assumptions!$B$54,F24) -> 1058.3537
