Workbook

Sheet Working
A1: Equity Shares Data as on March 31, 2026
G2: Manual Workbook Calculation is "On", Press F9 to update the numbers or recalculated the workbook.
A3: Metrics (in Cr) | D3: Retail Investors | P3: Monte Carlo Simulation
A4: Total Equity Capital | B4: 2098 | D4: Investment Amount | E4: =E6*B7 -> 152000 | S4: Acceptance Ratio
A5: Total No of shares | B5: 1048.8412 | D5: Buyback Price | E5: 250 | P5: CMP | Q5: =B7 -> 190 | S5: Acceptance Ratio | T5: Probability | U5: Cumulative | W5: Results
A6: FV | B6: 2 | D6: Quantity | E6: 800 | P6: Daily Standard Deviation | Q6: ='Price Data'!F4 -> 0.014619815 | S6: 0.15 | T6: 0.03 | U6: 0 | W6: Average Return | Z6: =AVERAGE(V17:V5016) -> 0.10997183
A7: CMP (as on May 8, 2026) | B7: 190 | D7: No. of Shares Buyback | E7: =E6*B18 -> 173.64607 | H7: LTCG | I7: STCG | J7: Cess | P7: Holding Period | Q7: =J30 -> 45 | S7: 0.217 | T7: 0.1 | U7: =U6+T6 -> 0.03 | W7: Probability of Loss | Z7: =COUNTIF(V17:V5016,"<0")/Q11 -> 0.0636
A8: Buyback Price (in Rs) | B8: 250 | D8: Inv. Am. Of Buyback shares | E8: =E7*B7 -> 32992.754 | H8: 0.125 | I8: 0.2 | J8: 0.04 | P8: Mean Price | Q8: 190 | S8: 0.3 | T8: 0.25 | U8: =U7+T7 -> 0.13 | W8: Worst Outcome | Z8: =MIN(V17:V5016) -> -0.1820906
P9: Holding Period St. Dev. | Q9: =Q6*SQRT(Q7) -> 0.098072698 | S9: 0.35 | T9: 0.22 | U9: =U8+T8 -> 0.38 | W9: Best Outcome | Z9: =MAX(V17:V5016) -> 0.33154369
A10: Total Buyback Size(in Rs Cr) | B10: 15000 | D10: Buyback Profit | E10: =(B8-B7)*E7 -> 10418.764 | H10: Amount Invested | I10: Acceptance Ratio | J10: Entitled Share | K10: Profit | L10: Absolute Return (Before Tax) | M10: Absolute Return (After tax) | N10: Profit After tax | P10: Price St. Dev. | Q10: =Q5*Q9 -> 18.633813 | S10: 0.4 | T10: 0.2 | U10: =U9+T9 -> 0.6 | W10: 5th Percentile | Z10: =_xlfn.PERCENTILE.INC(V17:V5016,5%) -> -0.011749844
P11: Total Trials | Q11: 5000 | S11: 0.45 | T11: 0.15 | U11: =U10+T10 -> 0.8 | W11: 95th Percentile | Z11: =_xlfn.PERCENTILE.INC(V17:V5016,95%) -> 0.21901449
A12: Buyback no. of shares (in cr.) | B12: 60 | D12: Buyback Profit % | E12: =E10/E8 -> 0.31578947 | H12: =$E$6*$B$7 -> 152000 | I12: 0.217 | J12: =$E$6*I12 -> 173.6 | K12: =J12*($B$8-$B$7) -> 10416 | L12: =K12/H12 -> 0.068526316 | M12: =L12-(L12*$I$8)-(L12*$I$8*$J$8) -> 0.054272842 | N12: =H12*M12 -> 8249.472 | S12: 0.5 | T12: 0.05 | U12: =U11+T11 -> 0.95 | W12: Median | Z12: =MEDIAN(V17:V5016) -> 0.11195042
A13: % of Issued Capital | B13: =B12/B5 -> 0.057205988 | D13: Buyback Profit as % Inv. Am. | E13: =E10/E4 -> 0.068544502 | H13: =$E$6*$B$7 -> 152000 | I13: 0.3 | J13: =$E$6*I13 -> 240 | K13: =J13*($B$8-$B$7) -> 14400 | L13: =K13/H13 -> 0.094736842 | M13: =L13-(L13*$I$8)-(L13*$I$8*$J$8) -> 0.075031579 | N13: =H13*M13 -> 11404.8 | T13: =SUM(T6:T12) -> 1 | U13: =U12+T12 -> 1
A14: Retailers No. of shares | H14: =$E$6*$B$7 -> 152000 | I14: 0.4 | J14: =$E$6*I14 -> 320 | K14: =J14*($B$8-$B$7) -> 19200 | L14: =K14/H14 -> 0.12631579 | M14: =L14-(L14*$I$8)-(L14*$I$8*$J$8) -> 0.10004211 | N14: =H14*M14 -> 15206.4
A15: SHP upto 2 lac | B15: 41.46365 | D15: HNI Investors inc. Promoters | H15: =$E$6*$B$7 -> 152000 | I15: 0.5 | J15: =$E$6*I15 -> 400 | K15: =J15*($B$8-$B$7) -> 24000 | L15: =K15/H15 -> 0.15789474 | M15: =L15-(L15*$I$8)-(L15*$I$8*$J$8) -> 0.12505263 | N15: =H15*M15 -> 19008 | Q15: Simulation Table
A16: Buyback shares for retail | B16: =B12*B17 -> 9 | D16: Investment Amount | E16: 1000000 | H16: =$E$6*$B$7 -> 152000 | I16: 0.6 | J16: =$E$6*I16 -> 480 | K16: =J16*($B$8-$B$7) -> 28800 | L16: =K16/H16 -> 0.18947368 | M16: =L16-(L16*$I$8)-(L16*$I$8*$J$8) -> 0.15006316 | N16: =H16*M16 -> 22809.6 | Q16: Trial | R16: AR | S16: Exit Price | T16: Profit from Buyback Shares | U16: Total Profit | V16: Return Before Tax | W16: Annualised Return
A17: % for retailers** | B17: 0.15 | D17: Buyback Price | E17: 250 | H17: =$E$6*$B$7 -> 152000 | I17: 0.7 | J17: =$E$6*I17 -> 560 | K17: =J17*($B$8-$B$7) -> 33600 | L17: =K17/H17 -> 0.22105263 | M17: =L17-(L17*$I$8)-(L17*$I$8*$J$8) -> 0.17507368 | N17: =H17*M17 -> 26611.2 | Q17: 1 | R17: =LOOKUP(RAND(),$U$6:$U$12,$S$6:$S$12) -> 0.4 | S17: =_xlfn.NORM.INV(RAND(),$Q$5,$Q$10) -> 170.49776 | T17: =($B$8-$B$7)*($E$6*R17) -> 19200 | U17: =T17+((S17-$B$7)*($E$6*(1-R17))) -> 9838.9267 | V17: =U17/$E$4 -> 0.064729781 | W17: =(1+V17)^($J$29/$J$30)-1 -> 0.6631898 | Z17: =MAX(S17:S5016) -> 254.22448 | AA17: Max Exit Price
A18: Acceptance ratio % | B18: =B16/B15 -> 0.21705759 | D18: Quantity | E18: =E16/B7 -> 5263.1579 | H18: =$E$6*$B$7 -> 152000 | I18: 1 | J18: =$E$6*I18 -> 800 | K18: =J18*($B$8-$B$7) -> 48000 | L18: =K18/H18 -> 0.31578947 | M18: =L18-(L18*$I$8)-(L18*$I$8*$J$8) -> 0.25010526 | N18: =H18*M18 -> 38016 | Q18: =Q17+1 -> 2 | R18: =LOOKUP(RAND(),$U$6:$U$12,$S$6:$S$12) -> 0.3 | S18: =_xlfn.NORM.INV(RAND(),$Q$5,$Q$10) -> 170.46048 | T18: =($B$8-$B$7)*($E$6*R18) -> 14400 | U18: =T18+((S18-$B$7)*($E$6*(1-R18))) -> 3457.8674 | V18: =U18/$E$4 -> 0.022749128 | W18: =(1+V18)^($J$29/$J$30)-1 -> 0.20015793 | Z18: =MIN(S17:S5016) -> 119.99181 | AA18: Min Exit Price
D19: No. of Share Buyback | E19: =E18*B24 -> 266.45525 | Q19: =Q18+1 -> 3 | R19: =LOOKUP(RAND(),$U$6:$U$12,$S$6:$S$12) -> 0.4 | S19: =_xlfn.NORM.INV(RAND(),$Q$5,$Q$10) -> 201.31749 | T19: =($B$8-$B$7)*($E$6*R19) -> 19200 | U19: =T19+((S19-$B$7)*($E$6*(1-R19))) -> 24632.395 | V19: =U19/$E$4 -> 0.16205523 | W19: =(1+V19)^($J$29/$J$30)-1 -> 2.3811278 | Z19: =AVERAGE(S17:S5016) -> 189.81565 | AA19: Average Exit Price
A20: Eligible Qty | D20: Inv. Am. Of Buyback shares | E20: =E19*B7 -> 50626.498 | G20: CMP | H20: =B7 -> 190 | Q20: =Q19+1 -> 4 | R20: =LOOKUP(RAND(),$U$6:$U$12,$S$6:$S$12) -> 0.4 | S20: =_xlfn.NORM.INV(RAND(),$Q$5,$Q$10) -> 187.92832 | T20: =($B$8-$B$7)*($E$6*R20) -> 19200 | U20: =T20+((S20-$B$7)*($E$6*(1-R20))) -> 18205.595 | V20: =U20/$E$4 -> 0.11977365 | W20: =(1+V20)^($J$29/$J$30)-1 -> 1.5032307
A21: More than 2lac | B21: 27.806492 | D21: Buyback Profit | E21: =($B$8-$B$7)*E19 -> 15987.315 | G21: Acceptance Ratio | H21: =INDEX(I12:I18,I21) -> 0.217 | I21: 1 | Q21: =Q20+1 -> 5 | R21: =LOOKUP(RAND(),$U$6:$U$12,$S$6:$S$12) -> 0.3 | S21: =_xlfn.NORM.INV(RAND(),$Q$5,$Q$10) -> 191.03101 | T21: =($B$8-$B$7)*($E$6*R21) -> 14400 | U21: =T21+((S21-$B$7)*($E$6*(1-R21))) -> 14977.365 | V21: =U21/$E$4 -> 0.098535295 | W21: =(1+V21)^($J$29/$J$30)-1 -> 1.1431226
A22: Buyback shares whithout retail | B22: =B12*85% -> 51 | D22: Buyback Profit % | E22: =E21/E20 -> 0.31578947 | G22: Profit from Buyback shares | H22: =INDEX(K12:K18,I21) -> 10416 | Q22: =Q21+1 -> 6 | R22: =LOOKUP(RAND(),$U$6:$U$12,$S$6:$S$12) -> 0.35 | S22: =_xlfn.NORM.INV(RAND(),$Q$5,$Q$10) -> 185.14059 | T22: =($B$8-$B$7)*($E$6*R22) -> 16800 | U22: =T22+((S22-$B$7)*($E$6*(1-R22))) -> 14273.107 | V22: =U22/$E$4 -> 0.09390202 | W22: =(1+V22)^($J$29/$J$30)-1 -> 1.0708962
A23: Total HNI (incl promoter*) | B23: =B5-B15 -> 1007.3776 | D23: Buyback Profit as % Inv. Am. | E23: =E21/E16 -> 0.015987315 | M23: Return after tax (Short Term) | N23: Return after tax (Long Term) | Q23: =Q22+1 -> 7 | R23: =LOOKUP(RAND(),$U$6:$U$12,$S$6:$S$12) -> 0.3 | S23: =_xlfn.NORM.INV(RAND(),$Q$5,$Q$10) -> 165.59682 | T23: =($B$8-$B$7)*($E$6*R23) -> 14400 | U23: =T23+((S23-$B$7)*($E$6*(1-R23))) -> 734.22088 | V23: =U23/$E$4 -> 0.0048304005 | W23: =(1+V23)^($J$29/$J$30)-1 -> 0.039859483
A24: Acceptance ratio % | B24: =B22/B23 -> 0.050626498 | H24: MP at sell of shares | I24: No. of shares sold | J24: Profit/Loss | K24: Net Profit/Loss | L24: Return before tax | Q24: =Q23+1 -> 8 | R24: =LOOKUP(RAND(),$U$6:$U$12,$S$6:$S$12) -> 0.3 | S24: =_xlfn.NORM.INV(RAND(),$Q$5,$Q$10) -> 182.63168 | T24: =($B$8-$B$7)*($E$6*R24) -> 14400 | U24: =T24+((S24-$B$7)*($E$6*(1-R24))) -> 10273.743 | V24: =U24/$E$4 -> 0.067590415 | W24: =(1+V24)^($J$29/$J$30)-1 -> 0.69978269
A25: Promoter holding | B25: 761.68409 | D25: HNI Investors exc. Promoters | G25: Worst Case | H25: 170 | I25: =$E$6-($H$21*$E$6) -> 626.4 | J25: =(I25*H25)-(I25*$H$20) -> -12528 | K25: =J25+$H$22 -> -2112 | L25: =K25/$E$4 -> -0.013894737 | M25: =IF($L25>0,$L25-($L25*$I$8)-($L25*$I$8*$J$8),$L25) -> -0.013894737 | N25: =IF($L25>0,$L25-($L25*$H$8)-($L25*$H$8*$J$8),$L25) -> -0.013894737 | Q25: =Q24+1 -> 9 | R25: =LOOKUP(RAND(),$U$6:$U$12,$S$6:$S$12) -> 0.217 | S25: =_xlfn.NORM.INV(RAND(),$Q$5,$Q$10) -> 183.16376 | T25: =($B$8-$B$7)*($E$6*R25) -> 10416 | U25: =T25+((S25-$B$7)*($E$6*(1-R25))) -> 6133.7799 | V25: =U25/$E$4 -> 0.040353815 | W25: =(1+V25)^($J$29/$J$30)-1 -> 0.37834368
A26: Ex promoter | B26: =B23-B25 -> 245.69351 | D26: Investment Amount | E26: 1000000 | G26: Base Case | H26: 200 | I26: =$E$6-($H$21*$E$6) -> 626.4 | J26: =(I26*H26)-(I26*$H$20) -> 6264 | K26: =J26+$H$22 -> 16680 | L26: =K26/$E$4 -> 0.10973684 | M26: =IF($L26>0,$L26-($L26*$I$8)-($L26*$I$8*$J$8),$L26) -> 0.086911579 | N26: =IF($L26>0,$L26-($L26*$H$8)-($L26*$H$8*$J$8),$L26) -> 0.095471053 | Q26: =Q25+1 -> 10 | R26: =LOOKUP(RAND(),$U$6:$U$12,$S$6:$S$12) -> 0.45 | S26: =_xlfn.NORM.INV(RAND(),$Q$5,$Q$10) -> 204.1448 | T26: =($B$8-$B$7)*($E$6*R26) -> 21600 | U26: =T26+((S26-$B$7)*($E$6*(1-R26))) -> 27823.714 | V26: =U26/$E$4 -> 0.18305075 | W26: =(1+V26)^($J$29/$J$30)-1 -> 2.9096555
A27: Acceptance ratio % | B27: =B22/B26 -> 0.20757569 | D27: Buyback Price | E27: 250 | G27: Bull Case | H27: 220 | I27: =$E$6-($H$21*$E$6) -> 626.4 | J27: =(I27*H27)-(I27*$H$20) -> 18792 | K27: =J27+$H$22 -> 29208 | L27: =K27/$E$4 -> 0.19215789 | M27: =IF($L27>0,$L27-($L27*$I$8)-($L27*$I$8*$J$8),$L27) -> 0.15218905 | N27: =IF($L27>0,$L27-($L27*$H$8)-($L27*$H$8*$J$8),$L27) -> 0.16717737 | Q27: =Q26+1 -> 11 | R27: =LOOKUP(RAND(),$U$6:$U$12,$S$6:$S$12) -> 0.45 | S27: =_xlfn.NORM.INV(RAND(),$Q$5,$Q$10) -> 215.0476 | T27: =($B$8-$B$7)*($E$6*R27) -> 21600 | U27: =T27+((S27-$B$7)*($E$6*(1-R27))) -> 32620.944 | V27: =U27/$E$4 -> 0.21461147 | W27: =(1+V27)^($J$29/$J$30)-1 -> 3.8403968
D28: Quantity | E28: =E26/B7 -> 5263.1579 | L28: Annualised Return | Q28: =Q27+1 -> 12 | R28: =LOOKUP(RAND(),$U$6:$U$12,$S$6:$S$12) -> 0.35 | S28: =_xlfn.NORM.INV(RAND(),$Q$5,$Q$10) -> 184.97524 | T28: =($B$8-$B$7)*($E$6*R28) -> 16800 | U28: =T28+((S28-$B$7)*($E$6*(1-R28))) -> 14187.123 | V28: =U28/$E$4 -> 0.093336336 | W28: =(1+V28)^($J$29/$J$30)-1 -> 1.0622259
D29: No. of Share Buyback | E29: =E28*B27 -> 1092.5037 | I29: Total No. of days | J29: 365 | L29: =((1+L25)^($J$29/$J$30))-1 -> -0.10728872 | M29: =IF($L29>0,$L29-($L29*$I$8)-($L29*$I$8*$J$8),$L29) -> -0.10728872 | N29: =IF($L29>0,$L29-($L29*$H$8)-($L29*$H$8*$J$8),$L29) -> -0.10728872 | Q29: =Q28+1 -> 13 | R29: =LOOKUP(RAND(),$U$6:$U$12,$S$6:$S$12) -> 0.35 | S29: =_xlfn.NORM.INV(RAND(),$Q$5,$Q$10) -> 181.21388 | T29: =($B$8-$B$7)*($E$6*R29) -> 16800 | U29: =T29+((S29-$B$7)*($E$6*(1-R29))) -> 12231.219 | V29: =U29/$E$4 -> 0.080468546 | W29: =(1+V29)^($J$29/$J$30)-1 -> 0.87340514
D30: Inv. Am. Of Buyback shares | E30: =E29*B7 -> 207575.69 | I30: Inv. Duration | J30: 45 | L30: =((1+L26)^($J$29/$J$30))-1 -> 1.3269362 | M30: =IF($L30>0,$L30-($L30*$I$8)-($L30*$I$8*$J$8),$L30) -> 1.0509335 | N30: =IF($L30>0,$L30-($L30*$H$8)-($L30*$H$8*$J$8),$L30) -> 1.1544345 | Q30: =Q29+1 -> 14 | R30: =LOOKUP(RAND(),$U$6:$U$12,$S$6:$S$12) -> 0.4 | S30: =_xlfn.NORM.INV(RAND(),$Q$5,$Q$10) -> 173.19105 | T30: =($B$8-$B$7)*($E$6*R30) -> 19200 | U30: =T30+((S30-$B$7)*($E$6*(1-R30))) -> 11131.705 | V30: =U30/$E$4 -> 0.073234904 | W30: =(1+V30)^($J$29/$J$30)-1 -> 0.77406219
D31: Buyback Profit | E31: =($B$8-$B$7)*E29 -> 65550.219 | L31: =((1+L27)^($J$29/$J$30))-1 -> 3.1605598 | M31: =IF($L31>0,$L31-($L31*$I$8)-($L31*$I$8*$J$8),$L31) -> 2.5031633 | N31: =IF($L31>0,$L31-($L31*$H$8)-($L31*$H$8*$J$8),$L31) -> 2.749687 | Q31: =Q30+1 -> 15 | R31: =LOOKUP(RAND(),$U$6:$U$12,$S$6:$S$12) -> 0.35 | S31: =_xlfn.NORM.INV(RAND(),$Q$5,$Q$10) -> 207.69242 | T31: =($B$8-$B$7)*($E$6*R31) -> 16800 | U31: =T31+((S31-$B$7)*($E$6*(1-R31))) -> 26000.059 | V31: =U31/$E$4 -> 0.17105302 | W31: =(1+V31)^($J$29/$J$30)-1 -> 2.5994163
D32: Buyback Profit % | E32: =E31/E30 -> 0.31578947 | Q32: =Q31+1 -> 16 | R32: =LOOKUP(RAND(),$U$6:$U$12,$S$6:$S$12) -> 0.35 | S32: =_xlfn.NORM.INV(RAND(),$Q$5,$Q$10) -> 188.73228 | T32: =($B$8-$B$7)*($E$6*R32) -> 16800 | U32: =T32+((S32-$B$7)*($E$6*(1-R32))) -> 16140.785 | V32: =U32/$E$4 -> 0.10618937 | W32: =(1+V32)^($J$29/$J$30)-1 -> 1.2672833
D33: Buyback Profit as % Inv. Am. | E33: =E31/E26 -> 0.065550219 | G33: Sensitivity Analysis | J33: Return Before Tax | Q33: =Q32+1 -> 17 | R33: =LOOKUP(RAND(),$U$6:$U$12,$S$6:$S$12) -> 0.35 | S33: =_xlfn.NORM.INV(RAND(),$Q$5,$Q$10) -> 178.39515 | T33: =($B$8-$B$7)*($E$6*R33) -> 16800 | U33: =T33+((S33-$B$7)*($E$6*(1-R33))) -> 10765.479 | V33: =U33/$E$4 -> 0.070825519 | W33: =(1+V33)^($J$29/$J$30)-1 -> 0.74201455
I34: =H43 -> 0.10973684 | J34: 0.15 | K34: 0.217 | L34: 0.3 | M34: 0.4 | N34: 0.5 | Q34: =Q33+1 -> 18 | R34: =LOOKUP(RAND(),$U$6:$U$12,$S$6:$S$12) -> 0.35 | S34: =_xlfn.NORM.INV(RAND(),$Q$5,$Q$10) -> 192.85777 | T34: =($B$8-$B$7)*($E$6*R34) -> 16800 | U34: =T34+((S34-$B$7)*($E$6*(1-R34))) -> 18286.042 | V34: =U34/$E$4 -> 0.12030291 | W34: =(1+V34)^($J$29/$J$30)-1 -> 1.5128434
I35: 170 | J35: -0.042105263 | K35: -0.013894737 | L35: 0.021052632 | M35: 0.063157895 | N35: 0.10526316 | Q35: =Q34+1 -> 19 | R35: =LOOKUP(RAND(),$U$6:$U$12,$S$6:$S$12) -> 0.4 | S35: =_xlfn.NORM.INV(RAND(),$Q$5,$Q$10) -> 160.10175 | T35: =($B$8-$B$7)*($E$6*R35) -> 19200 | U35: =T35+((S35-$B$7)*($E$6*(1-R35))) -> 4848.8417 | V35: =U35/$E$4 -> 0.031900274 | W35: =(1+V35)^($J$29/$J$30)-1 -> 0.29008143
I36: 180 | J36: 0.0026315789 | K36: 0.027315789 | L36: 0.057894737 | M36: 0.094736842 | N36: 0.13157895 | Q36: =Q35+1 -> 20 | R36: =LOOKUP(RAND(),$U$6:$U$12,$S$6:$S$12) -> 0.15 | S36: =_xlfn.NORM.INV(RAND(),$Q$5,$Q$10) -> 221.19435 | T36: =($B$8-$B$7)*($E$6*R36) -> 7200 | U36: =T36+((S36-$B$7)*($E$6*(1-R36))) -> 28412.156 | V36: =U36/$E$4 -> 0.18692208 | W36: =(1+V36)^($J$29/$J$30)-1 -> 3.0146418
G37: Sensitivity Analysis Input | I37: 190 | J37: 0.047368421 | K37: 0.068526316 | L37: 0.094736842 | M37: 0.12631579 | N37: 0.15789474 | Q37: =Q36+1 -> 21 | R37: =LOOKUP(RAND(),$U$6:$U$12,$S$6:$S$12) -> 0.217 | S37: =_xlfn.NORM.INV(RAND(),$Q$5,$Q$10) -> 204.5939 | T37: =($B$8-$B$7)*($E$6*R37) -> 10416 | U37: =T37+((S37-$B$7)*($E$6*(1-R37))) -> 19557.621 | V37: =U37/$E$4 -> 0.12866856 | W37: =(1+V37)^($J$29/$J$30)-1 -> 1.6691448
G38: CMP | H38: =B7 -> 190 | I38: 200 | J38: 0.092105263 | K38: 0.10973684 | L38: 0.13157895 | M38: 0.15789474 | N38: 0.18421053 | Q38: =Q37+1 -> 22 | R38: =LOOKUP(RAND(),$U$6:$U$12,$S$6:$S$12) -> 0.35 | S38: =_xlfn.NORM.INV(RAND(),$Q$5,$Q$10) -> 195.15503 | T38: =($B$8-$B$7)*($E$6*R38) -> 16800 | U38: =T38+((S38-$B$7)*($E$6*(1-R38))) -> 19480.613 | V38: =U38/$E$4 -> 0.12816193 | W38: =(1+V38)^($J$29/$J$30)-1 -> 1.6594423
G39: Acceptance Ratio | H39: 0.217 | I39: 210 | J39: 0.13684211 | K39: 0.15094737 | L39: 0.16842105 | M39: 0.18947368 | N39: 0.21052632 | Q39: =Q38+1 -> 23 | R39: =LOOKUP(RAND(),$U$6:$U$12,$S$6:$S$12) -> 0.3 | S39: =_xlfn.NORM.INV(RAND(),$Q$5,$Q$10) -> 198.40031 | T39: =($B$8-$B$7)*($E$6*R39) -> 14400 | U39: =T39+((S39-$B$7)*($E$6*(1-R39))) -> 19104.173 | V39: =U39/$E$4 -> 0.12568535 | W39: =(1+V39)^($J$29/$J$30)-1 -> 1.6124568
G40: Profit from Buyback shares | H40: =(B8-B7)*(E6*H39) -> 10416 | I40: 220 | J40: 0.18157895 | K40: 0.19215789 | L40: 0.20526316 | M40: 0.22105263 | N40: 0.23684211 | Q40: =Q39+1 -> 24 | R40: =LOOKUP(RAND(),$U$6:$U$12,$S$6:$S$12) -> 0.35 | S40: =_xlfn.NORM.INV(RAND(),$Q$5,$Q$10) -> 180.17848 | T40: =($B$8-$B$7)*($E$6*R40) -> 16800 | U40: =T40+((S40-$B$7)*($E$6*(1-R40))) -> 11692.808 | V40: =U40/$E$4 -> 0.076926369 | W40: =(1+V40)^($J$29/$J$30)-1 -> 0.82416581
...

Sheet Price Data
A1: DATE | B1: CLOSE | C1: Daily Returns
A2: 46154 | B2: 189.57 | C2: =B2/B3-1 -> -0.036150092
A3: 46153 | B3: 196.68 | C3: =B3/B4-1 -> -0.0062149462
A4: 46150 | B4: 197.91 | C4: =B4/B5-1 -> 0.0027867856 | E4: Standard Deviation | F4: =_xlfn.STDEV.S(C2:C248) -> 0.014619815
A5: 46149 | B5: 197.36 | C5: =B5/B6-1 -> -0.0088388911
A6: 46148 | B6: 199.12 | C6: =B6/B7-1 -> -0.003303634
A7: 46147 | B7: 199.78 | C7: =B7/B8-1 -> -0.0048318804
A8: 46146 | B8: 200.75 | C8: =B8/B9-1 -> 0.00049838026
A9: 46142 | B9: 200.65 | C9: =B9/B10-1 -> -0.00014949173
A10: 46141 | B10: 200.68 | C10: =B10/B11-1 -> -0.0044647286
A11: 46140 | B11: 201.58 | C11: =B11/B12-1 -> -0.016922702
A12: 46139 | B12: 205.05 | C12: =B12/B13-1 -> 0.028541332
A13: 46136 | B13: 199.36 | C13: =B13/B14-1 -> -0.016768593
A14: 46135 | B14: 202.76 | C14: =B14/B15-1 -> -0.0060784314
A15: 46134 | B15: 204 | C15: =B15/B16-1 -> -0.0049265889
A16: 46133 | B16: 205.01 | C16: =B16/B17-1 -> 0.012495061
... A248: 45791 | B248: 252.94 | C248: =B248/B249-1 -> 0.0054458004
A249: 45790 | B249: 251.57

Sheet Advanced Analysis
A1: Inputs
B2: CMP | C2: =Working!B7 -> 190
B3: Market Cap | C3: =C2*Working!B5 -> 199279.84
B4: Buyback Price | C4: =Working!B8 -> 250
B5: Buyback Premium | C5: =C4-C2 -> 60
B6: Qty | C6: =Working!E6 -> 800
B7: Investment | C7: =Working!E4 -> 152000
B8: Holding days | C8: =Working!J30 -> 45
B9: Daily SD | C9: =Working!Q6 -> 0.014619815
B10: Mean MC Return | C10: =Working!Z6 -> 0.10997183
B11: SD MC Return | C11: =_xlfn.STDEV.S(Working!V17:V5016) -> 0.069527809
B12: Loss Probability | C12: =Working!Z7 -> 0.0636
B13: Risk Free Rate | C13: 0.053398
A15: Break-even Exit Price
B17: Accetance Ratio | C17: Buyback Shares | D17: Remaining Shares | E17: Break-even Exit Price | F17: Buffer from CMP | G17: Price Change%
B18: 0.15 | C18: =B18*$C$6 -> 120 | D18: =$C$6-C18 -> 680 | E18: =$C$2-((B18*$C$5)/(1-B18)) -> 179.41176 | F18: =E18-$C$2 -> -10.588235 | G18: =F18/$C$2 -> -0.055727554
B19: =Working!$B$18 -> 0.21705759 | C19: =B19*$C$6 -> 173.64607 | D19: =$C$6-C19 -> 626.35393 | E19: =$C$2-((B19*$C$5)/(1-B19)) -> 173.36601 | F19: =E19-$C$2 -> -16.633989 | G19: =F19/$C$2 -> -0.087547311
B20: 0.3 | C20: =B20*$C$6 -> 240 | D20: =$C$6-C20 -> 560 | E20: =$C$2-((B20*$C$5)/(1-B20)) -> 164.28571 | F20: =E20-$C$2 -> -25.714286 | G20: =F20/$C$2 -> -0.13533835
B21: 0.35 | C21: =B21*$C$6 -> 280 | D21: =$C$6-C21 -> 520 | E21: =$C$2-((B21*$C$5)/(1-B21)) -> 157.69231 | F21: =E21-$C$2 -> -32.307692 | G21: =F21/$C$2 -> -0.17004049
B22: 0.4 | C22: =B22*$C$6 -> 320 | D22: =$C$6-C22 -> 480 | E22: =$C$2-((B22*$C$5)/(1-B22)) -> 150 | F22: =E22-$C$2 -> -40 | G22: =F22/$C$2 -> -0.21052632
B23: 0.45 | C23: =B23*$C$6 -> 360 | D23: =$C$6-C23 -> 440 | E23: =$C$2-((B23*$C$5)/(1-B23)) -> 140.90909 | F23: =E23-$C$2 -> -49.090909 | G23: =F23/$C$2 -> -0.25837321
B24: 0.5 | C24: =B24*$C$6 -> 400 | D24: =$C$6-C24 -> 400 | E24: =$C$2-((B24*$C$5)/(1-B24)) -> 130 | F24: =E24-$C$2 -> -60 | G24: =F24/$C$2 -> -0.31578947
A26: Return Decomposition
E27: Market Exposure | H27: Total
B28: Accetance Ratio | C28: Buyback Gain | D28: B.G. as % of Investment | E28: Worst - Exit Price=170 | F28: Base - Exit Price=190 | G28: Bull - Exit Price=210 | H28: Worst | I28: Base | J28: Bull | K28: Market Exposure Ratio
B29: 0.15 | C29: =B29*$C$6*$C$5 -> 7200 | D29: =C29/$C$7 -> 0.047368421 | E29: =(1-$B29)*$C$6*(170-$C$2) -> -13600 | F29: =(1-$B29)*$C$6*(200-$C$2) -> 6800 | G29: =(1-$B29)*$C$6*(210-$C$2) -> 13600 | H29: =$C$29+E29 -> -6400 | I29: =$C$29+F29 -> 14000 | J29: =$C$29+G29 -> 20800 | K29: =(1-B29)*$C$6*$C$2/$C$7 -> 0.85
B30: =Working!$B$18 -> 0.21705759 | C30: =B30*$C$6*$C$5 -> 10418.764 | D30: =C30/$C$7 -> 0.068544502 | E30: =(1-$B30)*$C$6*(170-$C$2) -> -12527.079 | F30: =(1-$B30)*$C$6*(200-$C$2) -> 6263.5393 | G30: =(1-$B30)*$C$6*(210-$C$2) -> 12527.079 | H30: =$C$29+E30 -> -5327.0785 | I30: =$C$29+F30 -> 13463.539 | J30: =$C$29+G30 -> 19727.079 | K30: =(1-B30)*$C$6*$C$2/$C$7 -> 0.78294241
B31: 0.3 | C31: =B31*$C$6*$C$5 -> 14400 | D31: =C31/$C$7 -> 0.094736842 | E31: =(1-$B31)*$C$6*(170-$C$2) -> -11200 | F31: =(1-$B31)*$C$6*(200-$C$2) -> 5600 | G31: =(1-$B31)*$C$6*(210-$C$2) -> 11200 | H31: =$C$29+E31 -> -4000 | I31: =$C$29+F31 -> 12800 | J31: =$C$29+G31 -> 18400 | K31: =(1-B31)*$C$6*$C$2/$C$7 -> 0.7
B32: 0.35 | C32: =B32*$C$6*$C$5 -> 16800 | D32: =C32/$C$7 -> 0.11052632 | E32: =(1-$B32)*$C$6*(170-$C$2) -> -10400 | F32: =(1-$B32)*$C$6*(200-$C$2) -> 5200 | G32: =(1-$B32)*$C$6*(210-$C$2) -> 10400 | H32: =$C$29+E32 -> -3200 | I32: =$C$29+F32 -> 12400 | J32: =$C$29+G32 -> 17600 | K32: =(1-B32)*$C$6*$C$2/$C$7 -> 0.65
B33: 0.4 | C33: =B33*$C$6*$C$5 -> 19200 | D33: =C33/$C$7 -> 0.12631579 | E33: =(1-$B33)*$C$6*(170-$C$2) -> -9600 | F33: =(1-$B33)*$C$6*(200-$C$2) -> 4800 | G33: =(1-$B33)*$C$6*(210-$C$2) -> 9600 | H33: =$C$29+E33 -> -2400 | I33: =$C$29+F33 -> 12000 | J33: =$C$29+G33 -> 16800 | K33: =(1-B33)*$C$6*$C$2/$C$7 -> 0.6
B34: 0.45 | C34: =B34*$C$6*$C$5 -> 21600 | D34: =C34/$C$7 -> 0.14210526 | E34: =(1-$B34)*$C$6*(170-$C$2) -> -8800 | F34: =(1-$B34)*$C$6*(200-$C$2) -> 4400 | G34: =(1-$B34)*$C$6*(210-$C$2) -> 8800 | H34: =$C$29+E34 -> -1600 | I34: =$C$29+F34 -> 11600 | J34: =$C$29+G34 -> 16000 | K34: =(1-B34)*$C$6*$C$2/$C$7 -> 0.55
B35: 0.5 | C35: =B35*$C$6*$C$5 -> 24000 | D35: =C35/$C$7 -> 0.15789474 | E35: =(1-$B35)*$C$6*(170-$C$2) -> -8000 | F35: =(1-$B35)*$C$6*(200-$C$2) -> 4000 | G35: =(1-$B35)*$C$6*(210-$C$2) -> 8000 | H35: =$C$29+E35 -> -800 | I35: =$C$29+F35 -> 11200 | J35: =$C$29+G35 -> 15200 | K35: =(1-B35)*$C$6*$C$2/$C$7 -> 0.5
A37: Fundamental Value Accretion Model
B39: EPS Accretion
C40: Pre-Buyback | D40: Post-Buyback | E40: Change
B41: Shares Outstanding | C41: =Working!B5 -> 1048.8412 | D41: =C41-Working!B12 -> 988.84125 | E41: =D41-C41 -> -60
B42: PAT (Cr) | C42: 13197.4 | D42: =C42 -> 13197.4 | E42: =D42-C42 -> 0
B43: EPS (Rs) | C43: =C42/C41 -> 12.582838 | D43: =D42/D41 -> 13.346328 | E43: =D43-C43 -> 0.76348991
B44: EPS Accretion | D44: =D43/C43-1 -> 0.060677081
B46: Theoritical Price Impact
...
